Workbook

Sheet CONTROLE FINANCEIRO - 2025 
A1: CONTROLE FINANCEIRO 2025
A3: DESPESAS FIXAS | B3: JANEIRO | C3: FEVEREIRO | D3: MARÇO | E3: ABRIL | F3: MAIO | G3: JUNHO | H3: JULHO | I3: AGOSTO | J3: SETEMBRO | K3: OUTUBRO | L3: NOVEMBRO | M3: DEZEMBRO
A4: Aluguel | B4: 4450.38 | C4: 4450.38 | D4: 4450.38 | E4: 4450.38 | F4: 4450.38 | G4: 4450.38 | H4: 4450.38 | I4: 4450.38
A5: Condomínio
A6: IPTU
A7: Luz | B7: 140.28 | C7: 140.28 | D7: 140.28 | E7: 140.28 | F7: 140.28 | G7: 140.28 | H7: 140.28 | I7: 140.28
A8: Telefone | B8: 379.98 | C8: 379.98 | D8: 379.98 | E8: 379.98 | F8: 379.98 | G8: 379.98 | H8: 379.98 | I8: 379.98
A9: Celular
A10: Internet | B10: 197.53 | C10: 197.53 | D10: 197.53 | E10: 197.53 | F10: 197.53 | G10: 197.53 | H10: 197.53 | I10: 197.53
A11: T.I.
A12: Contador | B12: 1412 | C12: 1518 | D12: 1518 | E12: 1518 | F12: 1518 | G12: 1518 | H12: 1518 | I12: 1518
A13: Faxineira | B13: =90*8 -> 720 | C13: =90*8 -> 720 | D13: =90*8 -> 720 | E13: =90*8 -> 720 | F13: =90*8 -> 720 | G13: =90*8 -> 720 | H13: =90*8 -> 720 | I13: =90*8 -> 720
A14: Sistema | B14: 285.97 | C14: 285.97 | D14: 285.97 | E14: 285.97 | F14: 285.97 | G14: 285.97 | H14: 285.97 | I14: 285.97
A15: Alarme
A16: CRM | B16: 856.9
A17: Seguro de Equipamentos
A18: Mensalidade Conta Corrente
A19: Mensalidade Cartão de Crédito
A20: Mensalidade Maquineta de Cartão
A21: Anuidade Certificado Digital
A22: Outros
A23: TOTAL | B23: =SUM(B4:B22) -> 8443.04 | C23: =SUM(C4:C22) -> 7692.14 | D23: =SUM(D4:D22) -> 7692.14 | E23: =SUM(E4:E22) -> 7692.14 | F23: =SUM(F4:F22) -> 7692.14 | G23: =SUM(G4:G22) -> 7692.14 | H23: =SUM(H4:H22) -> 7692.14 | I23: =SUM(I4:I22) -> 7692.14 | ... M23: =SUM(M4:M22) -> 0
A25: DESPESAS VARIÁVEIS | B25: JANEIRO | C25: FEVEREIRO | D25: MARÇO | E25: ABRIL | F25: MAIO | G25: JUNHO | H25: JULHO | I25: AGOSTO | J25: SETEMBRO | K25: OUTUBRO | L25: NOVEMBRO | M25: DEZEMBRO
A26: Correios
A27: Consultoria
A28: Lanche para o paciente (Coffee Break)
A29: Higienização de Estofaos
A30: Cursos e treinamentos
A31: Manutenção Ar-condicionado
A32: Manutenção Geral
A33: Locação de Equipamentos (MPT Transporte) | B33: 200 | C33: 200 | D33: 200 | E33: 200 | F33: 200 | G33: 200 | H33: 200 | I33: 200 | J33: 200
A34: Serviço de bordado (Rouparia)
A35: Material de Expediente (Itens para escritório)
A36: Material de Limpeza
A37: Insumos para Copa/ Descartáveis
A38: Insumos Clínica
A39: Equipamentos e informatica
A40: Outros
A41: TOTAL | B41: 10000 | C41: 10000 | D41: 10000 | E41: 10000 | F41: 10000 | G41: 10000 | H41: 10000 | I41: 10000 | J41: 10000 | K41: 10000 | L41: 10000 | M41: 10000
A43: DESPESAS COM PESSOAL | B43: JANEIRO | C43: FEVEREIRO | D43: MARÇO | E43: ABRIL | F43: MAIO | G43: JUNHO | H43: JULHO | I43: AGOSTO | J43: SETEMBRO | K43: OUTUBRO | L43: NOVEMBRO | M43: DEZEMBRO
...

Sheet PRECIFICAÇÃO - SUGESTÃO
A1: CATEGORIA | B1: PROCEDIMENTOS | C1: OBS E SUGESTAO | D1: DURAÇÃO | E1: UNIDADES | F1: PRODUTOS | G1: TAXA DE SALA | H1: TOTAL - CUSTO OPERACIONAL | I1: PREÇO- TABELA | J1: CARTÃO DE CRÉDITO | K1: IMPOSTOS | L1: COMISSÃO | M1: LUCRO | O1: Quantidade | P1: Tempo | Q1: Faturamento | R1: Produto/ Material | S1: Taxa de Sala | T1: Imposto + Cartão | U1: Bonificação | V1: Lucro
A2: 30101077 | B2: BIÓPSIA DE PELE(TBM CARE PLUS) | D2: 30 | E2: 1 | G2: =D2*12.5 -> 375 | H2: =F2+G2 -> 375 | I2: 0 | J2: =I2*5% -> 0 | K2: =I2*16.5% -> 0 | L2: =H2*3% -> 11.25 | M2: =I2-H2-J2-K2-L2 -> -386.25 | N2: =M2/I2 -> #DIV/0! | P2: =O2*(D2/60) -> 0 | Q2: =O2*I2 -> 0 | R2: =O2*F2 -> 0 | S2: =O2*G2 -> 0 | T2: =O2*(J2+K2) -> 0 | U2: =O2*L2 -> 0 | V2: =Q2-R2-S2-T2-U2 -> 0
A3: 30101018 | B3: ABRASÃO CIRURGICA(TBM CARE PLUS) | D3: 30 | E3: 1 | G3: =D3*12.5 -> 375 | H3: =F3+G3 -> 375 | I3: 0 | J3: =I3*5% -> 0 | K3: =I3*16.5% -> 0 | L3: =H3*3% -> 11.25 | M3: =I3-H3-J3-K3-L3 -> -386.25 | N3: =M3/I3 -> #DIV/0! | P3: =O3*(D3/60) -> 0 | Q3: =O3*I3 -> 0 | R3: =O3*(F3+G3) -> 0 | S3: =O3*H3 -> 0 | T3: =O3*(J3+K3) -> 0 | U3: =O3*L3 -> 0 | V3: =Q3-R3-S3-T3-U3 -> 0
B4: AVALIAÇÃO | D4: 30 | E4: 1 | G4: =D4*12.5 -> 375 | H4: =F4+G4 -> 375 | I4: 360 | J4: =I4*5% -> 18 | K4: =I4*16.5% -> 59.4 | L4: =H4*3% -> 11.25 | M4: =I4-H4-J4-K4-L4 -> -103.65 | N4: =M4/I4 -> -0.28791667 | P4: =O4*(D4/60) -> 0 | Q4: =O4*I4 -> 0 | R4: =O4*(F4+G4) -> 0 | S4: =O4*H4 -> 0 | T4: =O4*(J4+K4) -> 0 | U4: =O4*L4 -> 0 | V4: =Q4-R4-S4-T4-U4 -> 0
B5: AVALIAÇÃO ONLINE | D5: 15 | E5: 1 | G5: =D5*12.5 -> 187.5 | H5: =F5+G5 -> 187.5 | I5: 0 | J5: =I5*5% -> 0 | K5: =I5*16.5% -> 0 | L5: =H5*3% -> 5.625 | M5: =I5-H5-J5-K5-L5 -> -193.125 | N5: =M5/I5 -> #DIV/0! | P5: =O5*(D5/60) -> 0 | Q5: =O5*I5 -> 0 | R5: =O5*(F5+G5) -> 0 | S5: =O5*H5 -> 0 | T5: =O5*(J5+K5) -> 0 | U5: =O5*L5 -> 0 | V5: =Q5-R5-S5-T5-U5 -> 0
B6: BIOESTIMULADOR DIAMOND - 1 AMPOLA | D6: 30 | E6: 1 | F6: 509.9 | G6: =D6*12.5 -> 375 | H6: =F6+G6 -> 884.9 | I6: 2300 | J6: =I6*5% -> 115 | K6: =I6*16.5% -> 379.5 | L6: =H6*3% -> 26.547 | M6: =I6-H6-J6-K6-L6 -> 894.053 | N6: =M6/I6 -> 0.3887187 | P6: =O6*(D6/60) -> 0 | Q6: =O6*I6 -> 0 | R6: =O6*(F6+G6) -> 0 | S6: =O6*H6 -> 0 | T6: =O6*(J6+K6) -> 0 | U6: =O6*L6 -> 0 | V6: =Q6-R6-S6-T6-U6 -> 0
B7: BIOESTIMULADOR RADIESSE - 1 AMPOLA | D7: 30 | E7: 1 | F7: 848 | G7: =D7*12.5 -> 375 | H7: =F7+G7 -> 1223 | I7: 2700 | J7: =I7*5% -> 135 | K7: =I7*16.5% -> 445.5 | L7: =H7*3% -> 36.69 | M7: =I7-H7-J7-K7-L7 -> 859.81 | N7: =M7/I7 -> 0.31844815 | P7: =O7*(D7/60) -> 0 | Q7: =O7*I7 -> 0 | R7: =O7*(F7+G7) -> 0 | S7: =O7*H7 -> 0 | T7: =O7*(J7+K7) -> 0 | U7: =O7*L7 -> 0 | V7: =Q7-R7-S7-T7-U7 -> 0
B8: BIOESTIMULADOR SCULPTRA - 1 AMPOLA | D8: 30 | E8: 1 | F8: 1106.7 | G8: =D8*12.5 -> 375 | H8: =F8+G8 -> 1481.7 | I8: 3300 | J8: =I8*5% -> 165 | K8: =I8*16.5% -> 544.5 | L8: =H8*3% -> 44.451 | M8: =I8-H8-J8-K8-L8 -> 1064.349 | N8: =M8/I8 -> 0.32253 | P8: =O8*(D8/60) -> 0 | Q8: =O8*I8 -> 0 | R8: =O8*(F8+G8) -> 0 | S8: =O8*H8 -> 0 | T8: =O8*(J8+K8) -> 0 | U8: =O8*L8 -> 0 | V8: =Q8-R8-S8-T8-U8 -> 0
B9: BIOESTIMULADOR ELLEVA - 1 AMPOLA | D9: 30 | E9: 1 | F9: 964.9 | G9: =D9*12.5 -> 375 | H9: =F9+G9 -> 1339.9 | I9: 3300 | J9: =I9*5% -> 165 | K9: =I9*16.5% -> 544.5 | L9: =H9*3% -> 40.197 | M9: =I9-H9-J9-K9-L9 -> 1210.403 | N9: =M9/I9 -> 0.36678879 | P9: =O9*(D9/60) -> 0 | Q9: =O9*I9 -> 0 | R9: =O9*(F9+G9) -> 0 | S9: =O9*H9 -> 0 | T9: =O9*(J9+K9) -> 0 | U9: =O9*L9 -> 0 | V9: =Q9-R9-S9-T9-U9 -> 0
B10: BIOIMPEDANCIA | D10: 15 | E10: 1 | G10: =D10*12.5 -> 187.5 | H10: =F10+G10 -> 187.5 | I10: 55 | J10: =I10*5% -> 2.75 | K10: =I10*16.5% -> 9.075 | L10: =H10*3% -> 5.625 | M10: =I10-H10-J10-K10-L10 -> -149.95 | N10: =M10/I10 -> -2.7263636 | P10: =O10*(D10/60) -> 0 | Q10: =O10*I10 -> 0 | R10: =O10*(F10+G10) -> 0 | S10: =O10*H10 -> 0 | T10: =O10*(J10+K10) -> 0 | U10: =O10*L10 -> 0 | V10: =Q10-R10-S10-T10-U10 -> 0
B11: BLEFAROPLASTIA - SUPERIOR OU INFERIOR | D11: 120 | E11: 1 | G11: =D11*12.5 -> 1500 | H11: =F11+G11 -> 1500 | I11: 7000 | J11: =I11*5% -> 350 | K11: =I11*16.5% -> 1155 | L11: =H11*3% -> 45 | M11: =I11-H11-J11-K11-L11 -> 3950 | N11: =M11/I11 -> 0.56428571 | P11: =O11*(D11/60) -> 0 | Q11: =O11*I11 -> 0 | R11: =O11*(F11+G11) -> 0 | S11: =O11*H11 -> 0 | T11: =O11*(J11+K11) -> 0 | U11: =O11*L11 -> 0 | V11: =Q11-R11-S11-T11-U11 -> 0
B12: BLEFAROPLASTIA - TOTAL | D12: 60 | E12: 1 | G12: =D12*12.5 -> 750 | H12: =F12+G12 -> 750 | I12: 7000 | J12: =I12*5% -> 350 | K12: =I12*16.5% -> 1155 | L12: =H12*3% -> 22.5 | M12: =I12-H12-J12-K12-L12 -> 4722.5 | N12: =M12/I12 -> 0.67464286 | P12: =O12*(D12/60) -> 0 | Q12: =O12*I12 -> 0 | R12: =O12*(F12+G12) -> 0 | S12: =O12*H12 -> 0 | T12: =O12*(J12+K12) -> 0 | U12: =O12*L12 -> 0 | V12: =Q12-R12-S12-T12-U12 -> 0
A13: 30101107 | B13: CAUTERIZAÇÃO QUÍMICA - ATÉ 5 LESÕES(TBM CARE PLUS) | D13: 30 | E13: 1 | G13: =D13*12.5 -> 375 | H13: =F13+G13 -> 375 | I13: 850 | J13: =I13*5% -> 42.5 | K13: =I13*16.5% -> 140.25 | L13: =H13*3% -> 11.25 | M13: =I13-H13-J13-K13-L13 -> 281 | N13: =M13/I13 -> 0.33058824 | P13: =O13*(D13/60) -> 0 | Q13: =O13*I13 -> 0 | R13: =O13*(F13+G13) -> 0 | S13: =O13*H13 -> 0 | T13: =O13*(J13+K13) -> 0 | U13: =O13*L13 -> 0 | V13: =Q13-R13-S13-T13-U13 -> 0
B14: CONSULTA DERMATOLOGICA - RJ | D14: 60 | E14: 1 | G14: =D14*12.5 -> 750 | H14: =F14+G14 -> 750 | I14: 680 | J14: =I14*5% -> 34 | K14: =I14*16.5% -> 112.2 | L14: =H14*3% -> 22.5 | M14: =I14-H14-J14-K14-L14 -> -238.7 | N14: =M14/I14 -> -0.35102941 | P14: =O14*(D14/60) -> 0 | Q14: =O14*I14 -> 0 | R14: =O14*(F14+G14) -> 0 | S14: =O14*H14 -> 0 | T14: =O14*(J14+K14) -> 0 | U14: =O14*L14 -> 0 | V14: =Q14-R14-S14-T14-U14 -> 0
B15: CONSULTA DERMATOLÓGICA - SP | D15: 60 | E15: 1 | G15: =D15*12.5 -> 750 | H15: =F15+G15 -> 750 | I15: 720 | J15: =I15*5% -> 36 | K15: =I15*16.5% -> 118.8 | L15: =H15*3% -> 22.5 | M15: =I15-H15-J15-K15-L15 -> -207.3 | N15: =M15/I15 -> -0.28791667 | P15: =O15*(D15/60) -> 0 | Q15: =O15*I15 -> 0 | R15: =O15*(F15+G15) -> 0 | S15: =O15*H15 -> 0 | T15: =O15*(J15+K15) -> 0 | U15: =O15*L15 -> 0 | V15: =Q15-R15-S15-T15-U15 -> 0
B16: CONSULTA DR. VICTOR ROMERO - TRICOLOGISTA | D16: 60 | E16: 1 | G16: =D16*12.5 -> 750 | H16: =F16+G16 -> 750 | I16: 720 | J16: =I16*5% -> 36 | K16: =I16*16.5% -> 118.8 | L16: =H16*3% -> 22.5 | M16: =I16-H16-J16-K16-L16 -> -207.3 | N16: =M16/I16 -> -0.28791667 | P16: =O16*(D16/60) -> 0 | Q16: =O16*I16 -> 0 | R16: =O16*(F16+G16) -> 0 | S16: =O16*H16 -> 0 | T16: =O16*(J16+K16) -> 0 | U16: =O16*L16 -> 0 | V16: =Q16-R16-S16-T16-U16 -> 0
B17: CONSULTA ENDOCRINOLOGIA | D17: 30 | E17: 1 | G17: =D17*12.5 -> 375 | H17: =F17+G17 -> 375 | I17: 650 | J17: =I17*5% -> 32.5 | K17: =I17*16.5% -> 107.25 | L17: =H17*3% -> 11.25 | M17: =I17-H17-J17-K17-L17 -> 124 | N17: =M17/I17 -> 0.19076923 | P17: =O17*(D17/60) -> 0 | Q17: =O17*I17 -> 0 | R17: =O17*(F17+G17) -> 0 | S17: =O17*H17 -> 0 | T17: =O17*(J17+K17) -> 0 | U17: =O17*L17 -> 0 | V17: =Q17-R17-S17-T17-U17 -> 0
B18: CONSULTA NUTRIÇÃO | D18: 60 | E18: 1 | G18: =D18*12.5 -> 750 | H18: =F18+G18 -> 750 | I18: 450 | J18: =I18*5% -> 22.5 | K18: =I18*16.5% -> 74.25 | L18: =H18*3% -> 22.5 | M18: =I18-H18-J18-K18-L18 -> -419.25 | N18: =M18/I18 -> -0.93166667 | P18: =O18*(D18/60) -> 0 | Q18: =O18*I18 -> 0 | R18: =O18*(F18+G18) -> 0 | S18: =O18*H18 -> 0 | T18: =O18*(J18+K18) -> 0 | U18: =O18*L18 -> 0 | V18: =Q18-R18-S18-T18-U18 -> 0
B19: COOLSCULPTING CORPORAL ADVANTAGE - 1 CICLO | D19: 35 | E19: 1 | F19: 506.29 | G19: =D19*12.5 -> 437.5 | H19: =F19+G19 -> 943.79 | I19: 2500 | J19: =I19*5% -> 125 | K19: =I19*16.5% -> 412.5 | L19: =H19*3% -> 28.3137 | M19: =I19-H19-J19-K19-L19 -> 990.3963 | N19: =M19/I19 -> 0.39615852 | P19: =O19*(D19/60) -> 0 | Q19: =O19*I19 -> 0 | R19: =O19*(F19+G19) -> 0 | S19: =O19*H19 -> 0 | T19: =O19*(J19+K19) -> 0 | U19: =O19*L19 -> 0 | V19: =Q19-R19-S19-T19-U19 -> 0
B20: COOLSCULPTING FACIAL MINI - 1 CICLO | D20: 45 | E20: 1 | F20: 1222.29 | G20: =D20*12.5 -> 562.5 | H20: =F20+G20 -> 1784.79 | I20: 2700 | J20: =I20*5% -> 135 | K20: =I20*16.5% -> 445.5 | L20: =H20*3% -> 53.5437 | M20: =I20-H20-J20-K20-L20 -> 281.1663 | N20: =M20/I20 -> 0.10413567 | P20: =O20*(D20/60) -> 0 | Q20: =O20*I20 -> 0 | R20: =O20*(F20+G20) -> 0 | S20: =O20*H20 -> 0 | T20: =O20*(J20+K20) -> 0 | U20: =O20*L20 -> 0 | V20: =Q20-R20-S20-T20-U20 -> 0
B21: COOLSCUPTING CORPORAL PLUS - 1 CICLO | D21: 45 | E21: 1 | F21: 559.79 | G21: =D21*12.5 -> 562.5 | H21: =F21+G21 -> 1122.29 | I21: 2500 | J21: =I21*5% -> 125 | K21: =I21*16.5% -> 412.5 | L21: =H21*3% -> 33.6687 | M21: =I21-H21-J21-K21-L21 -> 806.5413 | N21: =M21/I21 -> 0.32261652 | P21: =O21*(D21/60) -> 0 | Q21: =O21*I21 -> 0 | R21: =O21*(F21+G21) -> 0 | S21: =O21*H21 -> 0 | T21: =O21*(J21+K21) -> 0 | U21: =O21*L21 -> 0 | V21: =Q21-R21-S21-T21-U21 -> 0
B22: COOLSCUPTING CORPORAL SMOOTH - 1 CICLO | D22: 75 | E22: 1 | F22: 284.77 | G22: =D22*12.5 -> 937.5 | H22: =F22+G22 -> 1222.27 | I22: 2500 | J22: =I22*5% -> 125 | K22: =I22*16.5% -> 412.5 | L22: =H22*3% -> 36.6681 | M22: =I22-H22-J22-K22-L22 -> 703.5619 | N22: =M22/I22 -> 0.28142476 | P22: =O22*(D22/60) -> 0 | Q22: =O22*I22 -> 0 | R22: =O22*(F22+G22) -> 0 | S22: =O22*H22 -> 0 | T22: =O22*(J22+K22) -> 0 | U22: =O22*L22 -> 0 | V22: =Q22-R22-S22-T22-U22 -> 0
B23: CORREÇÃO CIRURGICA CICATRIZ ACNE | D23: 40 | E23: 1 | G23: =D23*12.5 -> 500 | H23: =F23+G23 -> 500 | I23: 1200 | J23: =I23*5% -> 60 | K23: =I23*16.5% -> 198 | L23: =H23*3% -> 15 | M23: =I23-H23-J23-K23-L23 -> 427 | N23: =M23/I23 -> 0.35583333 | P23: =O23*(D23/60) -> 0 | Q23: =O23*I23 -> 0 | R23: =O23*(F23+G23) -> 0 | S23: =O23*H23 -> 0 | T23: =O23*(J23+K23) -> 0 | U23: =O23*L23 -> 0 | V23: =Q23-R23-S23-T23-U23 -> 0
B24: CORREÇÃO DE RINOFIMA | D24: 90 | E24: 1 | G24: =D24*12.5 -> 1125 | H24: =F24+G24 -> 1125 | I24: 3500 | J24: =I24*5% -> 175 | K24: =I24*16.5% -> 577.5 | L24: =H24*3% -> 33.75 | M24: =I24-H24-J24-K24-L24 -> 1588.75 | N24: =M24/I24 -> 0.45392857 | P24: =O24*(D24/60) -> 0 | Q24: =O24*I24 -> 0 | R24: =O24*(F24+G24) -> 0 | S24: =O24*H24 -> 0 | T24: =O24*(J24+K24) -> 0 | U24: =O24*L24 -> 0 | V24: =Q24-R24-S24-T24-U24 -> 0
B25: CRIOCIRURGIA DE NEOPLASIAS CUTANEAS - NITROGENIO LIQUIDO(TBM CARE PLUS) | D25: 20 | E25: 1 | G25: =D25*12.5 -> 250 | H25: =F25+G25 -> 250 | I25: 750 | J25: =I25*5% -> 37.5 | K25: =I25*16.5% -> 123.75 | L25: =H25*3% -> 7.5 | M25: =I25-H25-J25-K25-L25 -> 331.25 | N25: =M25/I25 -> 0.44166667 | P25: =O25*(D25/60) -> 0 | Q25: =O25*I25 -> 0 | R25: =O25*(F25+G25) -> 0 | S25: =O25*H25 -> 0 | T25: =O25*(J25+K25) -> 0 | U25: =O25*L25 -> 0 | V25: =Q25-R25-S25-T25-U25 -> 0
B26: CRIOPEELING | D26: 30 | E26: 1 | G26: =D26*12.5 -> 375 | H26: =F26+G26 -> 375 | I26: 850 | J26: =I26*5% -> 42.5 | K26: =I26*16.5% -> 140.25 | L26: =H26*3% -> 11.25 | M26: =I26-H26-J26-K26-L26 -> 281 | N26: =M26/I26 -> 0.33058824 | P26: =O26*(D26/60) -> 0 | Q26: =O26*I26 -> 0 | R26: =O26*(F26+G26) -> 0 | S26: =O26*H26 -> 0 | T26: =O26*(J26+K26) -> 0 | U26: =O26*L26 -> 0 | V26: =Q26-R26-S26-T26-U26 -> 0
B27: CRIOTERAPIA DE NEOPLASIA CUTÂNEA | D27: 30 | E27: 1 | G27: =D27*12.5 -> 375 | H27: =F27+G27 -> 375 | I27: 800 | J27: =I27*5% -> 40 | K27: =I27*16.5% -> 132 | L27: =H27*3% -> 11.25 | M27: =I27-H27-J27-K27-L27 -> 241.75 | N27: =M27/I27 -> 0.3021875 | P27: =O27*(D27/60) -> 0 | Q27: =O27*I27 -> 0 | R27: =O27*(F27+G27) -> 0 | S27: =O27*H27 -> 0 | T27: =O27*(J27+K27) -> 0 | U27: =O27*L27 -> 0 | V27: =Q27-R27-S27-T27-U27 -> 0
A28: 20104103 | B28: CURATIVOS EM GERAL SEM ANESTESIA, EXCETO QUEIMADOS | D28: 30 | E28: 1 | G28: =D28*12.5 -> 375 | H28: =F28+G28 -> 375 | I28: 19 | J28: =I28*5% -> 0.95 | K28: =I28*16.5% -> 3.135 | L28: =H28*3% -> 11.25 | M28: =I28-H28-J28-K28-L28 -> -371.335 | N28: =M28/I28 -> -19.543947 | P28: =O28*(D28/60) -> 0 | Q28: =O28*I28 -> 0 | R28: =O28*(F28+G28) -> 0 | S28: =O28*H28 -> 0 | T28: =O28*(J28+K28) -> 0 | U28: =O28*L28 -> 0 | V28: =Q28-R28-S28-T28-U28 -> 0
B29: CURETAGEM DE MOLUSCO | D29: 30 | E29: 1 | G29: =D29*12.5 -> 375 | H29: =F29+G29 -> 375 | I29: 1150 | J29: =I29*5% -> 57.5 | K29: =I29*16.5% -> 189.75 | L29: =H29*3% -> 11.25 | M29: =I29-H29-J29-K29-L29 -> 516.5 | N29: =M29/I29 -> 0.44913043 | P29: =O29*(D29/60) -> 0 | Q29: =O29*I29 -> 0 | R29: =O29*(F29+G29) -> 0 | S29: =O29*H29 -> 0 | T29: =O29*(J29+K29) -> 0 | U29: =O29*L29 -> 0 | V29: =Q29-R29-S29-T29-U29 -> 0
B30: CURETAGEM SIMPLES - ATÉ 15 LESÕES | D30: 30 | E30: 1 | G30: =D30*12.5 -> 375 | H30: =F30+G30 -> 375 | I30: 850 | J30: =I30*5% -> 42.5 | K30: =I30*16.5% -> 140.25 | L30: =H30*3% -> 11.25 | M30: =I30-H30-J30-K30-L30 -> 281 | N30: =M30/I30 -> 0.33058824 | P30: =O30*(D30/60) -> 0 | Q30: =O30*I30 -> 0 | R30: =O30*(F30+G30) -> 0 | S30: =O30*H30 -> 0 | T30: =O30*(J30+K30) -> 0 | U30: =O30*L30 -> 0 | V30: =Q30-R30-S30-T30-U30 -> 0
B31: CURSO CIRURGIA DERMATOLÓGICA | D31: 360 | E31: 1 | G31: =D31*12.5 -> 4500 | H31: =F31+G31 -> 4500 | I31: 2300 | J31: =I31*5% -> 115 | K31: =I31*16.5% -> 379.5 | L31: =H31*3% -> 135 | M31: =I31-H31-J31-K31-L31 -> -2829.5 | N31: =M31/I31 -> -1.2302174 | P31: =O31*(D31/60) -> 0 | Q31: =O31*I31 -> 0 | R31: =O31*(F31+G31) -> 0 | S31: =O31*H31 -> 0 | T31: =O31*(J31+K31) -> 0 | U31: =O31*L31 -> 0 | V31: =Q31-R31-S31-T31-U31 -> 0
B32: DEPILAÇÃO A LASER ANTEBRAÇO - 1 SESSÃO | D32: 20 | E32: 1 | G32: =D32*12.5 -> 250 | H32: =F32+G32 -> 250 | I32: 350 | J32: =I32*5% -> 17.5 | K32: =I32*16.5% -> 57.75 | L32: =H32*3% -> 7.5 | M32: =I32-H32-J32-K32-L32 -> 17.25 | N32: =M32/I32 -> 0.049285714 | P32: =O32*(D32/60) -> 0 | Q32: =O32*I32 -> 0 | R32: =O32*(F32+G32) -> 0 | S32: =O32*H32 -> 0 | T32: =O32*(J32+K32) -> 0 | U32: =O32*L32 -> 0 | V32: =Q32-R32-S32-T32-U32 -> 0
B33: DEPILAÇÃO A LASER AXILAS - 1 SESSÃO | D33: 20 | E33: 1 | G33: =D33*12.5 -> 250 | H33: =F33+G33 -> 250 | I33: 250 | J33: =I33*5% -> 12.5 | K33: =I33*16.5% -> 41.25 | L33: =H33*3% -> 7.5 | M33: =I33-H33-J33-K33-L33 -> -61.25 | N33: =M33/I33 -> -0.245 | P33: =O33*(D33/60) -> 0 | Q33: =O33*I33 -> 0 | R33: =O33*(F33+G33) -> 0 | S33: =O33*H33 -> 0 | T33: =O33*(J33+K33) -> 0 | U33: =O33*L33 -> 0 | V33: =Q33-R33-S33-T33-U33 -> 0
B34: DEPILAÇÃO A LASER BARBA - 1 SESSÃO | D34: 20 | G34: =D34*12.5 -> 250 | I34: 350 | J34: =I34*5% -> 17.5 | K34: =I34*16.5% -> 57.75 | L34: =H34*3% -> 0 | M34: =I34-H34-J34-K34-L34 -> 274.75 | N34: =M34/I34 -> 0.785 | P34: =O34*(D34/60) -> 0 | Q34: =O34*I34 -> 0 | R34: =O34*(F34+G34) -> 0 | S34: =O34*H34 -> 0 | T34: =O34*(J34+K34) -> 0 | U34: =O34*L34 -> 0 | V34: =Q34-R34-S34-T34-U34 -> 0
B35: DEPILAÇÃO A LASER BARBA INFERIOR - 1 SESSÃO | D35: 20 | G35: =D35*12.5 -> 250 | I35: 250 | J35: =I35*5% -> 12.5 | K35: =I35*16.5% -> 41.25 | L35: =H35*3% -> 0 | M35: =I35-H35-J35-K35-L35 -> 196.25 | N35: =M35/I35 -> 0.785 | P35: =O35*(D35/60) -> 0 | Q35: =O35*I35 -> 0 | R35: =O35*(F35+G35) -> 0 | S35: =O35*H35 -> 0 | T35: =O35*(J35+K35) -> 0 | U35: =O35*L35 -> 0 | V35: =Q35-R35-S35-T35-U35 -> 0
B36: DEPILAÇÃO A LASER BARRIGA (LINHA) - 1 SESSÃO | D36: 30 | G36: =D36*12.5 -> 375 | I36: 250 | J36: =I36*5% -> 12.5 | K36: =I36*16.5% -> 41.25 | L36: =H36*3% -> 0 | M36: =I36-H36-J36-K36-L36 -> 196.25 | N36: =M36/I36 -> 0.785 | P36: =O36*(D36/60) -> 0 | Q36: =O36*I36 -> 0 | R36: =O36*(F36+G36) -> 0 | S36: =O36*H36 -> 0 | T36: =O36*(J36+K36) -> 0 | U36: =O36*L36 -> 0 | V36: =Q36-R36-S36-T36-U36 -> 0
B37: DEPILAÇÃO A LASER BARRIGA COMPLETA - 1 SESSÃO | D37: 30 | G37: =D37*12.5 -> 375 | I37: 400 | J37: =I37*5% -> 20 | K37: =I37*16.5% -> 66 | L37: =H37*3% -> 0 | M37: =I37-H37-J37-K37-L37 -> 314 | N37: =M37/I37 -> 0.785 | P37: =O37*(D37/60) -> 0 | Q37: =O37*I37 -> 0 | R37: =O37*(F37+G37) -> 0 | S37: =O37*H37 -> 0 | T37: =O37*(J37+K37) -> 0 | U37: =O37*L37 -> 0 | V37: =Q37-R37-S37-T37-U37 -> 0
B38: DEPILAÇÃO A LASER BOCHECHAS - 1 SESSÃO | D38: 20 | G38: =D38*12.5 -> 250 | I38: 250 | J38: =I38*5% -> 12.5 | K38: =I38*16.5% -> 41.25 | L38: =H38*3% -> 0 | M38: =I38-H38-J38-K38-L38 -> 196.25 | N38: =M38/I38 -> 0.785 | P38: =O38*(D38/60) -> 0 | Q38: =O38*I38 -> 0 | R38: =O38*(F38+G38) -> 0 | S38: =O38*H38 -> 0 | T38: =O38*(J38+K38) -> 0 | U38: =O38*L38 -> 0 | V38: =Q38-R38-S38-T38-U38 -> 0
B39: DEPILAÇÃO A LASER BRAÇOS - 1 SESSÃO | D39: 30 | G39: =D39*12.5 -> 375 | I39: 400 | J39: =I39*5% -> 20 | K39: =I39*16.5% -> 66 | L39: =H39*3% -> 0 | M39: =I39-H39-J39-K39-L39 -> 314 | N39: =M39/I39 -> 0.785 | P39: =O39*(D39/60) -> 0 | Q39: =O39*I39 -> 0 | R39: =O39*(F39+G39) -> 0 | S39: =O39*H39 -> 0 | T39: =O39*(J39+K39) -> 0 | U39: =O39*L39 -> 0 | V39: =Q39-R39-S39-T39-U39 -> 0
B40: DEPILAÇÃO A LASER BUÇO - 1 SESSÃO | D40: 20 | G40: =D40*12.5 -> 250 | I40: 250 | J40: =I40*5% -> 12.5 | K40: =I40*16.5% -> 41.25 | L40: =H40*3% -> 0 | M40: =I40-H40-J40-K40-L40 -> 196.25 | N40: =M40/I40 -> 0.785 | P40: =O40*(D40/60) -> 0 | Q40: =O40*I40 -> 0 | R40: =O40*(F40+G40) -> 0 | S40: =O40*H40 -> 0 | T40: =O40*(J40+K40) -> 0 | U40: =O40*L40 -> 0 | V40: =Q40-R40-S40-T40-U40 -> 0
...

Sheet PRECIFICAÇÃO 
A1: DATA DA VENDA | B1: MEDICO SOLICITANTE | C1: PACIENTE | D1: QUANTIDADE | E1: PROCEDIMENTO | F1: TIPO | G1: DURAÇÃO | H1: PREÇO DE VENDA | I1: VENDEDOR | J1: FORMA DE PAGAMENTO | K1: BANDEIRA | L1: TAXA ADM | M1: VALOR TAXA ADM | N1: TAXA ANTECIPAÇÃO | O1: VALOR ANTECIPAÇÃO | P1: VALOR LIQUIDO | Q1: PRODUTOS | R1: TAXA DE SALA 3,12 | S1: IMPOSTOS | T1: MÉDICO EXECUTOR | U1: COMISSÃO | V1: CUSTO TOTAL | W1: % | X1: LUCRO LÍQUIDO | Y1: %2 | Z1: MÉDICO | AA1: CLINICA
A2: 45967 | B2: Yasmin | C2: Estela | D2: 1 | E2: MMP Região - Avulso | F2: {=IFERROR(INDEX(PROCEDIMENTOS!$A$2:$A$48,MATCH('PRECIFICAÇÃO '!$E2,PROCEDIMENTOS!$B$2:$B$48,0)),"")} -> PROCEDIMENTO | G2: {=IFERROR(INDEX(PROCEDIMENTOS!$C$2:$C$48,MATCH('PRECIFICAÇÃO '!$E2,PROCEDIMENTOS!$B$2:$B$48,0)),"")} -> 45 | H2: 500 | J2: PIX | L2: =IFERROR(VLOOKUP('PRECIFICAÇÃO '!$J2,TAXA!$A$2:$C$18,2,FALSE),"") -> 0 | M2: =IFERROR(L2*H2,0) -> 0 | N2: =IFERROR(VLOOKUP('PRECIFICAÇÃO '!$J2,TAXA!$A$2:$C$18,3,FALSE),"") -> 0 | O2: =IFERROR(N2*H2,0) -> 0 | P2: =IFERROR('PRECIFICAÇÃO '!$H2-'PRECIFICAÇÃO '!$M2-'PRECIFICAÇÃO '!$O2,0) -> 500 | Q2: {=IFERROR(INDEX(PROCEDIMENTOS!$D$2:$D$48,MATCH('PRECIFICAÇÃO '!$E2,PROCEDIMENTOS!$B$2:$B$48,0)),"")} -> 7.8 | R2: =G2*3.12 -> 140.4 | S2: =IFERROR(H2*16.5%,0) -> 82.5 | U2: =IFERROR(H2*3%,0) -> 15 | V2: ='PRECIFICAÇÃO '!$Q2+'PRECIFICAÇÃO '!$R2+'PRECIFICAÇÃO '!$S2+'PRECIFICAÇÃO '!$T2+'PRECIFICAÇÃO '!$U2 -> 245.7 | W2: =IFERROR(V2/H2,0) -> 0.4914 | X2: =IFERROR(P2-V2,0) -> 254.3 | Y2: =IFERROR(X2/H2,0) -> 0.5086 | Z2: =IFERROR(X2*20%,0) -> 50.86 | AA2: =IFERROR(X2*80%,0) -> 203.44
A3: 45973 | B3: Yasmin | C3: Marlon Henrique Souza de Barros | D3: 1 | E3: Toxina Botulinica - Terço Superior | F3: {=IFERROR(INDEX(PROCEDIMENTOS!$A$2:$A$48,MATCH('PRECIFICAÇÃO '!$E3,PROCEDIMENTOS!$B$2:$B$48,0)),"")} -> PROCEDIMENTO | G3: {=IFERROR(INDEX(PROCEDIMENTOS!$C$2:$C$48,MATCH('PRECIFICAÇÃO '!$E3,PROCEDIMENTOS!$B$2:$B$48,0)),"")} -> 30 | H3: 1250 | J3: PIX | L3: =IFERROR(VLOOKUP('PRECIFICAÇÃO '!$J3,TAXA!$A$2:$C$18,2,FALSE),"") -> 0 | M3: =IFERROR(L3*H3,0) -> 0 | N3: =IFERROR(VLOOKUP('PRECIFICAÇÃO '!$J3,TAXA!$A$2:$C$18,3,FALSE),"") -> 0 | O3: =IFERROR(N3*H3,0) -> 0 | P3: =IFERROR('PRECIFICAÇÃO '!$H3-'PRECIFICAÇÃO '!$M3-'PRECIFICAÇÃO '!$O3,0) -> 1250 | Q3: {=IFERROR(INDEX(PROCEDIMENTOS!$D$2:$D$48,MATCH('PRECIFICAÇÃO '!$E3,PROCEDIMENTOS!$B$2:$B$48,0)),"")} -> 566.4 | R3: =G3*3.12 -> 93.6 | S3: =IFERROR(H3*16.5%,0) -> 206.25 | U3: =IFERROR(H3*3%,0) -> 37.5 | V3: ='PRECIFICAÇÃO '!$Q3+'PRECIFICAÇÃO '!$R3+'PRECIFICAÇÃO '!$S3+'PRECIFICAÇÃO '!$T3+'PRECIFICAÇÃO '!$U3 -> 903.75 | W3: =IFERROR(V3/H3,0) -> 0.723 | X3: =IFERROR(P3-V3,0) -> 346.25 | Y3: =IFERROR(X3/H3,0) -> 0.277 | Z3: =IFERROR(X3*20%,0) -> 69.25 | AA3: =IFERROR(X3*80%,0) -> 277
A4: 45974 | B4: Yasmin | C4: Claudia Estela | D4: 1 | E4: Tirzepatida | F4: {=IFERROR(INDEX(PROCEDIMENTOS!$A$2:$A$48,MATCH('PRECIFICAÇÃO '!$E4,PROCEDIMENTOS!$B$2:$B$48,0)),"")} -> PROCEDIMENTO | G4: 0 | H4: 1700 | J4: PIX | L4: =IFERROR(VLOOKUP('PRECIFICAÇÃO '!$J4,TAXA!$A$2:$C$18,2,FALSE),"") -> 0 | M4: =IFERROR(L4*H4,0) -> 0 | N4: =IFERROR(VLOOKUP('PRECIFICAÇÃO '!$J4,TAXA!$A$2:$C$18,3,FALSE),"") -> 0 | O4: =IFERROR(N4*H4,0) -> 0 | P4: =IFERROR('PRECIFICAÇÃO '!$H4-'PRECIFICAÇÃO '!$M4-'PRECIFICAÇÃO '!$O4,0) -> 1700 | Q4: {=IFERROR(INDEX(PROCEDIMENTOS!$D$2:$D$48,MATCH('PRECIFICAÇÃO '!$E4,PROCEDIMENTOS!$B$2:$B$48,0)),"")} -> 1575 | R4: =G4*3.12 -> 0 | S4: =IFERROR(H4*16.5%,0) -> 280.5 | U4: =IFERROR(H4*3%,0) -> 51 | V4: ='PRECIFICAÇÃO '!$Q4+'PRECIFICAÇÃO '!$R4+'PRECIFICAÇÃO '!$S4+'PRECIFICAÇÃO '!$T4+'PRECIFICAÇÃO '!$U4 -> 1906.5 | W4: =IFERROR(V4/H4,0) -> 1.1214706 | X4: =IFERROR(P4-V4,0) -> -206.5 | Y4: =IFERROR(X4/H4,0) -> -0.12147059 | Z4: =IFERROR(X4*20%,0) -> -41.3 | AA4: =IFERROR(X4*80%,0) -> -165.2
A5: 45975 | B5: Yasmin | C5: Karina Lopes | D5: 1 | E5: 1º consulta médica | F5: {=IFERROR(INDEX(PROCEDIMENTOS!$A$2:$A$48,MATCH('PRECIFICAÇÃO '!$E5,PROCEDIMENTOS!$B$2:$B$48,0)),"")} -> CONSULTA | G5: {=IFERROR(INDEX(PROCEDIMENTOS!$C$2:$C$48,MATCH('PRECIFICAÇÃO '!$E5,PROCEDIMENTOS!$B$2:$B$48,0)),"")} -> 90 | H5: 800 | J5: PIX | L5: =IFERROR(VLOOKUP('PRECIFICAÇÃO '!$J5,TAXA!$A$2:$C$18,2,FALSE),"") -> 0 | M5: =IFERROR(L5*H5,0) -> 0 | N5: =IFERROR(VLOOKUP('PRECIFICAÇÃO '!$J5,TAXA!$A$2:$C$18,3,FALSE),"") -> 0 | O5: =IFERROR(N5*H5,0) -> 0 | P5: =IFERROR('PRECIFICAÇÃO '!$H5-'PRECIFICAÇÃO '!$M5-'PRECIFICAÇÃO '!$O5,0) -> 800 | Q5: {=IFERROR(INDEX(PROCEDIMENTOS!$D$2:$D$48,MATCH('PRECIFICAÇÃO '!$E5,PROCEDIMENTOS!$B$2:$B$48,0)),"")} -> 0 | R5: =G5*3.12 -> 280.8 | S5: =IFERROR(H5*16.5%,0) -> 132 | U5: =IFERROR(H5*3%,0) -> 24 | V5: ='PRECIFICAÇÃO '!$Q5+'PRECIFICAÇÃO '!$R5+'PRECIFICAÇÃO '!$S5+'PRECIFICAÇÃO '!$T5+'PRECIFICAÇÃO '!$U5 -> 436.8 | W5: =IFERROR(V5/H5,0) -> 0.546 | X5: =IFERROR(P5-V5,0) -> 363.2 | Y5: =IFERROR(X5/H5,0) -> 0.454 | Z5: =IFERROR(X5*20%,0) -> 72.64 | AA5: =IFERROR(X5*80%,0) -> 290.56
A6: 45979 | B6: Yasmin | C6: Débora Vicentini | D6: 1 | E6: Toxina Botulinica - Terço Superior | F6: {=IFERROR(INDEX(PROCEDIMENTOS!$A$2:$A$48,MATCH('PRECIFICAÇÃO '!$E6,PROCEDIMENTOS!$B$2:$B$48,0)),"")} -> PROCEDIMENTO | G6: {=IFERROR(INDEX(PROCEDIMENTOS!$C$2:$C$48,MATCH('PRECIFICAÇÃO '!$E6,PROCEDIMENTOS!$B$2:$B$48,0)),"")} -> 30 | H6: 1425 | J6: PIX | L6: =IFERROR(VLOOKUP('PRECIFICAÇÃO '!$J6,TAXA!$A$2:$C$18,2,FALSE),"") -> 0 | M6: =IFERROR(L6*H6,0) -> 0 | N6: =IFERROR(VLOOKUP('PRECIFICAÇÃO '!$J6,TAXA!$A$2:$C$18,3,FALSE),"") -> 0 | O6: =IFERROR(N6*H6,0) -> 0 | P6: =IFERROR('PRECIFICAÇÃO '!$H6-'PRECIFICAÇÃO '!$M6-'PRECIFICAÇÃO '!$O6,0) -> 1425 | Q6: {=IFERROR(INDEX(PROCEDIMENTOS!$D$2:$D$48,MATCH('PRECIFICAÇÃO '!$E6,PROCEDIMENTOS!$B$2:$B$48,0)),"")} -> 566.4 | R6: =G6*3.12 -> 93.6 | S6: =IFERROR(H6*16.5%,0) -> 235.125 | U6: =IFERROR(H6*3%,0) -> 42.75 | V6: ='PRECIFICAÇÃO '!$Q6+'PRECIFICAÇÃO '!$R6+'PRECIFICAÇÃO '!$S6+'PRECIFICAÇÃO '!$T6+'PRECIFICAÇÃO '!$U6 -> 937.875 | W6: =IFERROR(V6/H6,0) -> 0.65815789 | X6: =IFERROR(P6-V6,0) -> 487.125 | Y6: =IFERROR(X6/H6,0) -> 0.34184211 | Z6: =IFERROR(X6*20%,0) -> 97.425 | AA6: =IFERROR(X6*80%,0) -> 389.7
A7: 45985 | B7: Yasmin | C7: Leia Carvalho | D7: 1 | E7: MMP Alopécia Padrão Feminino (6) | F7: {=IFERROR(INDEX(PROCEDIMENTOS!$A$2:$A$48,MATCH('PRECIFICAÇÃO '!$E7,PROCEDIMENTOS!$B$2:$B$48,0)),"")} -> PROCEDIMENTO | G7: {=IFERROR(INDEX(PROCEDIMENTOS!$C$2:$C$48,MATCH('PRECIFICAÇÃO '!$E7,PROCEDIMENTOS!$B$2:$B$48,0)),"")} -> 270 | H7: 4500 | J7: CREDITO 6X | L7: =IFERROR(VLOOKUP('PRECIFICAÇÃO '!$J7,TAXA!$A$2:$C$18,2,FALSE),"") -> 0.0313 | M7: =IFERROR(L7*H7,0) -> 140.85 | N7: =IFERROR(VLOOKUP('PRECIFICAÇÃO '!$J7,TAXA!$A$2:$C$18,3,FALSE),"") -> 0 | O7: =IFERROR(N7*H7,0) -> 0 | P7: =IFERROR('PRECIFICAÇÃO '!$H7-'PRECIFICAÇÃO '!$M7-'PRECIFICAÇÃO '!$O7,0) -> 4359.15 | Q7: {=IFERROR(INDEX(PROCEDIMENTOS!$D$2:$D$48,MATCH('PRECIFICAÇÃO '!$E7,PROCEDIMENTOS!$B$2:$B$48,0)),"")} -> 46.8 | R7: =G7*3.12 -> 842.4 | S7: =IFERROR(H7*16.5%,0) -> 742.5 | U7: =IFERROR(H7*3%,0) -> 135 | V7: ='PRECIFICAÇÃO '!$Q7+'PRECIFICAÇÃO '!$R7+'PRECIFICAÇÃO '!$S7+'PRECIFICAÇÃO '!$T7+'PRECIFICAÇÃO '!$U7 -> 1766.7 | W7: =IFERROR(V7/H7,0) -> 0.3926 | X7: =IFERROR(P7-V7,0) -> 2592.45 | Y7: =IFERROR(X7/H7,0) -> 0.5761 | Z7: =IFERROR(X7*20%,0) -> 518.49 | AA7: =IFERROR(X7*80%,0) -> 2073.96
A8: 45992 | B8: YASMIN | C8: Livia Zugno | D8: 1 | E8: 1º consulta médica | F8: {=IFERROR(INDEX(PROCEDIMENTOS!$A$2:$A$48,MATCH('PRECIFICAÇÃO '!$E8,PROCEDIMENTOS!$B$2:$B$48,0)),"")} -> CONSULTA | G8: {=IFERROR(INDEX(PROCEDIMENTOS!$C$2:$C$48,MATCH('PRECIFICAÇÃO '!$E8,PROCEDIMENTOS!$B$2:$B$48,0)),"")} -> 90 | H8: 800 | J8: CREDITO A VISTA | L8: =IFERROR(VLOOKUP('PRECIFICAÇÃO '!$J8,TAXA!$A$2:$C$18,2,FALSE),"") -> 0.0283 | M8: =IFERROR(L8*H8,0) -> 22.64 | N8: =IFERROR(VLOOKUP('PRECIFICAÇÃO '!$J8,TAXA!$A$2:$C$18,3,FALSE),"") -> 0 | O8: =IFERROR(N8*H8,0) -> 0 | P8: =IFERROR('PRECIFICAÇÃO '!$H8-'PRECIFICAÇÃO '!$M8-'PRECIFICAÇÃO '!$O8,0) -> 777.36 | Q8: {=IFERROR(INDEX(PROCEDIMENTOS!$D$2:$D$48,MATCH('PRECIFICAÇÃO '!$E8,PROCEDIMENTOS!$B$2:$B$48,0)),"")} -> 0 | R8: =G8*3.12 -> 280.8 | S8: =IFERROR(H8*16.5%,0) -> 132 | U8: =IFERROR(H8*3%,0) -> 24 | V8: ='PRECIFICAÇÃO '!$Q8+'PRECIFICAÇÃO '!$R8+'PRECIFICAÇÃO '!$S8+'PRECIFICAÇÃO '!$T8+'PRECIFICAÇÃO '!$U8 -> 436.8 | W8: =IFERROR(V8/H8,0) -> 0.546 | X8: =IFERROR(P8-V8,0) -> 340.56 | Y8: =IFERROR(X8/H8,0) -> 0.4257 | Z8: =IFERROR(X8*20%,0) -> 68.112 | AA8: =IFERROR(X8*80%,0) -> 272.448
A9: 46000 | B9: YAS E STE | C9: Clélia Troleis | D9: 1 | E9: CO2 | F9: PROCEDIMENTO | G9: 30 | H9: 2800 | J9: CREDITO 6X | L9: =IFERROR(VLOOKUP('PRECIFICAÇÃO '!$J9,TAXA!$A$2:$C$18,2,FALSE),"") -> 0.0313 | M9: =IFERROR(L9*H9,0) -> 87.64 | N9: =IFERROR(VLOOKUP('PRECIFICAÇÃO '!$J9,TAXA!$A$2:$C$18,3,FALSE),"") -> 0 | O9: =IFERROR(N9*H9,0) -> 0 | P9: =IFERROR('PRECIFICAÇÃO '!$H9-'PRECIFICAÇÃO '!$M9-'PRECIFICAÇÃO '!$O9,0) -> 2712.36 | Q9: {=IFERROR(INDEX(PROCEDIMENTOS!$D$2:$D$48,MATCH('PRECIFICAÇÃO '!$E9,PROCEDIMENTOS!$B$2:$B$48,0)),"")} -> 566.67 | R9: =G9*3.12 -> 93.6 | S9: =IFERROR(H9*14.33%,0) -> 401.24 | V9: ='PRECIFICAÇÃO '!$Q9+'PRECIFICAÇÃO '!$R9+'PRECIFICAÇÃO '!$S9+'PRECIFICAÇÃO '!$T9+'PRECIFICAÇÃO '!$U9 -> 1061.51 | W9: =IFERROR(V9/H9,0) -> 0.37911071 | X9: =IFERROR(P9-V9,0) -> 1650.85 | Y9: =IFERROR(X9/H9,0) -> 0.58958929 | Z9: =IFERROR(X9*20%,0) -> 330.17 | AA9: =IFERROR(X9*80%,0) -> 1320.68
A10: 46000 | B10: YAS E STE | C10: Estela | D10: 1 | E10: CO2 | F10: PROCEDIMENTO | G10: 30 | H10: 2800 | J10: CREDITO 6X | L10: =IFERROR(VLOOKUP('PRECIFICAÇÃO '!$J10,TAXA!$A$2:$C$18,2,FALSE),"") -> 0.0313 | M10: =IFERROR(L10*H10,0) -> 87.64 | N10: =IFERROR(VLOOKUP('PRECIFICAÇÃO '!$J10,TAXA!$A$2:$C$18,3,FALSE),"") -> 0 | O10: =IFERROR(N10*H10,0) -> 0 | P10: =IFERROR('PRECIFICAÇÃO '!$H10-'PRECIFICAÇÃO '!$M10-'PRECIFICAÇÃO '!$O10,0) -> 2712.36 | Q10: {=IFERROR(INDEX(PROCEDIMENTOS!$D$2:$D$48,MATCH('PRECIFICAÇÃO '!$E10,PROCEDIMENTOS!$B$2:$B$48,0)),"")} -> 566.67 | R10: =G10*3.12 -> 93.6 | S10: =IFERROR(H10*14.33%,0) -> 401.24 | V10: ='PRECIFICAÇÃO '!$Q10+'PRECIFICAÇÃO '!$R10+'PRECIFICAÇÃO '!$S10+'PRECIFICAÇÃO '!$T10+'PRECIFICAÇÃO '!$U10 -> 1061.51 | W10: =IFERROR(V10/H10,0) -> 0.37911071 | X10: =IFERROR(P10-V10,0) -> 1650.85 | Y10: =IFERROR(X10/H10,0) -> 0.58958929 | Z10: =IFERROR(X10*20%,0) -> 330.17 | AA10: =IFERROR(X10*80%,0) -> 1320.68
A11: 46000 | B11: YAS E STE | C11: Nathália | D11: 1 | E11: CO2 | F11: PROCEDIMENTO | G11: 30 | H11: 3000 | J11: CREDITO 6X | L11: =IFERROR(VLOOKUP('PRECIFICAÇÃO '!$J11,TAXA!$A$2:$C$18,2,FALSE),"") -> 0.0313 | M11: =IFERROR(L11*H11,0) -> 93.9 | N11: =IFERROR(VLOOKUP('PRECIFICAÇÃO '!$J11,TAXA!$A$2:$C$18,3,FALSE),"") -> 0 | O11: =IFERROR(N11*H11,0) -> 0 | P11: =IFERROR('PRECIFICAÇÃO '!$H11-'PRECIFICAÇÃO '!$M11-'PRECIFICAÇÃO '!$O11,0) -> 2906.1 | Q11: {=IFERROR(INDEX(PROCEDIMENTOS!$D$2:$D$48,MATCH('PRECIFICAÇÃO '!$E11,PROCEDIMENTOS!$B$2:$B$48,0)),"")} -> 566.67 | R11: =G11*3.12 -> 93.6 | S11: =IFERROR(H11*14.33%,0) -> 429.9 | V11: ='PRECIFICAÇÃO '!$Q11+'PRECIFICAÇÃO '!$R11+'PRECIFICAÇÃO '!$S11+'PRECIFICAÇÃO '!$T11+'PRECIFICAÇÃO '!$U11 -> 1090.17 | W11: =IFERROR(V11/H11,0) -> 0.36339 | X11: =IFERROR(P11-V11,0) -> 1815.93 | Y11: =IFERROR(X11/H11,0) -> 0.60531 | Z11: =IFERROR(X11*20%,0) -> 363.186 | AA11: =IFERROR(X11*80%,0) -> 1452.744
A12: 46001 | B12: YASMIN | C12: Beatriz | D12: 1 | E12: Toxina Botulinica - Terço Superior | F12: {=IFERROR(INDEX(PROCEDIMENTOS!$A$2:$A$48,MATCH('PRECIFICAÇÃO '!$E12,PROCEDIMENTOS!$B$2:$B$48,0)),"")} -> PROCEDIMENTO | G12: {=IFERROR(INDEX(PROCEDIMENTOS!$C$2:$C$48,MATCH('PRECIFICAÇÃO '!$E12,PROCEDIMENTOS!$B$2:$B$48,0)),"")} -> 30 | H12: 1280 | J12: PIX | L12: =IFERROR(VLOOKUP('PRECIFICAÇÃO '!$J12,TAXA!$A$2:$C$18,2,FALSE),"") -> 0 | M12: =IFERROR(L12*H12,0) -> 0 | N12: =IFERROR(VLOOKUP('PRECIFICAÇÃO '!$J12,TAXA!$A$2:$C$18,3,FALSE),"") -> 0 | O12: =IFERROR(N12*H12,0) -> 0 | P12: =IFERROR('PRECIFICAÇÃO '!$H12-'PRECIFICAÇÃO '!$M12-'PRECIFICAÇÃO '!$O12,0) -> 1280 | Q12: {=IFERROR(INDEX(PROCEDIMENTOS!$D$2:$D$48,MATCH('PRECIFICAÇÃO '!$E12,PROCEDIMENTOS!$B$2:$B$48,0)),"")} -> 566.4 | R12: =G12*3.12 -> 93.6 | S12: =IFERROR(H12*16.5%,0) -> 211.2 | U12: =IFERROR(H12*3%,0) -> 38.4 | V12: ='PRECIFICAÇÃO '!$Q12+'PRECIFICAÇÃO '!$R12+'PRECIFICAÇÃO '!$S12+'PRECIFICAÇÃO '!$T12+'PRECIFICAÇÃO '!$U12 -> 909.6 | W12: =IFERROR(V12/H12,0) -> 0.710625 | X12: =IFERROR(P12-V12,0) -> 370.4 | Y12: =IFERROR(X12/H12,0) -> 0.289375 | Z12: =IFERROR(X12*20%,0) -> 74.08 | AA12: =IFERROR(X12*80%,0) -> 296.32
A13: 46001 | B13: YASMIN | C13: Karina Lopes | D13: 1 | E13: Toxina Botulinica - Terço Superior | F13: {=IFERROR(INDEX(PROCEDIMENTOS!$A$2:$A$48,MATCH('PRECIFICAÇÃO '!$E13,PROCEDIMENTOS!$B$2:$B$48,0)),"")} -> PROCEDIMENTO | G13: {=IFERROR(INDEX(PROCEDIMENTOS!$C$2:$C$48,MATCH('PRECIFICAÇÃO '!$E13,PROCEDIMENTOS!$B$2:$B$48,0)),"")} -> 30 | H13: 1280 | J13: CREDITO 6X | L13: =IFERROR(VLOOKUP('PRECIFICAÇÃO '!$J13,TAXA!$A$2:$C$18,2,FALSE),"") -> 0.0313 | M13: =IFERROR(L13*H13,0) -> 40.064 | N13: =IFERROR(VLOOKUP('PRECIFICAÇÃO '!$J13,TAXA!$A$2:$C$18,3,FALSE),"") -> 0 | O13: =IFERROR(N13*H13,0) -> 0 | P13: =IFERROR('PRECIFICAÇÃO '!$H13-'PRECIFICAÇÃO '!$M13-'PRECIFICAÇÃO '!$O13,0) -> 1239.936 | Q13: {=IFERROR(INDEX(PROCEDIMENTOS!$D$2:$D$48,MATCH('PRECIFICAÇÃO '!$E13,PROCEDIMENTOS!$B$2:$B$48,0)),"")} -> 566.4 | R13: =G13*3.12 -> 93.6 | S13: =IFERROR(H13*16.5%,0) -> 211.2 | U13: =IFERROR(H13*3%,0) -> 38.4 | V13: ='PRECIFICAÇÃO '!$Q13+'PRECIFICAÇÃO '!$R13+'PRECIFICAÇÃO '!$S13+'PRECIFICAÇÃO '!$T13+'PRECIFICAÇÃO '!$U13 -> 909.6 | W13: =IFERROR(V13/H13,0) -> 0.710625 | X13: =IFERROR(P13-V13,0) -> 330.336 | Y13: =IFERROR(X13/H13,0) -> 0.258075 | Z13: =IFERROR(X13*20%,0) -> 66.0672 | AA13: =IFERROR(X13*80%,0) -> 264.2688
A14: 46001 | B14: YASMIN | C14: Karina Lopes | D14: 1 | E14: Ácido Hialurônico - Volift Juvederm | F14: {=IFERROR(INDEX(PROCEDIMENTOS!$A$2:$A$48,MATCH('PRECIFICAÇÃO '!$E14,PROCEDIMENTOS!$B$2:$B$48,0)),"")} -> PROCEDIMENTO | G14: {=IFERROR(INDEX(PROCEDIMENTOS!$C$2:$C$48,MATCH('PRECIFICAÇÃO '!$E14,PROCEDIMENTOS!$B$2:$B$48,0)),"")} -> 60 | H14: 1800 | J14: CREDITO 6X | L14: =IFERROR(VLOOKUP('PRECIFICAÇÃO '!$J14,TAXA!$A$2:$C$18,2,FALSE),"") -> 0.0313 | M14: =IFERROR(L14*H14,0) -> 56.34 | N14: =IFERROR(VLOOKUP('PRECIFICAÇÃO '!$J14,TAXA!$A$2:$C$18,3,FALSE),"") -> 0 | O14: =IFERROR(N14*H14,0) -> 0 | P14: =IFERROR('PRECIFICAÇÃO '!$H14-'PRECIFICAÇÃO '!$M14-'PRECIFICAÇÃO '!$O14,0) -> 1743.66 | Q14: {=IFERROR(INDEX(PROCEDIMENTOS!$D$2:$D$48,MATCH('PRECIFICAÇÃO '!$E14,PROCEDIMENTOS!$B$2:$B$48,0)),"")} -> 411.54 | R14: =G14*3.12 -> 187.2 | S14: =IFERROR(H14*16.5%,0) -> 297 | U14: =IFERROR(H14*3%,0) -> 54 | V14: ='PRECIFICAÇÃO '!$Q14+'PRECIFICAÇÃO '!$R14+'PRECIFICAÇÃO '!$S14+'PRECIFICAÇÃO '!$T14+'PRECIFICAÇÃO '!$U14 -> 949.74 | W14: =IFERROR(V14/H14,0) -> 0.52763333 | X14: =IFERROR(P14-V14,0) -> 793.92 | Y14: =IFERROR(X14/H14,0) -> 0.44106667 | Z14: =IFERROR(X14*20%,0) -> 158.784 | AA14: =IFERROR(X14*80%,0) -> 635.136
A15: 46001 | B15: YASMIN | C15: Karina Lopes | D15: 1 | E15: Ácido Hialurônico - Volux Juvederm | F15: {=IFERROR(INDEX(PROCEDIMENTOS!$A$2:$A$48,MATCH('PRECIFICAÇÃO '!$E15,PROCEDIMENTOS!$B$2:$B$48,0)),"")} -> PROCEDIMENTO | G15: {=IFERROR(INDEX(PROCEDIMENTOS!$C$2:$C$48,MATCH('PRECIFICAÇÃO '!$E15,PROCEDIMENTOS!$B$2:$B$48,0)),"")} -> 60 | H15: 1800 | J15: CREDITO 6X | L15: =IFERROR(VLOOKUP('PRECIFICAÇÃO '!$J15,TAXA!$A$2:$C$18,2,FALSE),"") -> 0.0313 | M15: =IFERROR(L15*H15,0) -> 56.34 | N15: =IFERROR(VLOOKUP('PRECIFICAÇÃO '!$J15,TAXA!$A$2:$C$18,3,FALSE),"") -> 0 | O15: =IFERROR(N15*H15,0) -> 0 | P15: =IFERROR('PRECIFICAÇÃO '!$H15-'PRECIFICAÇÃO '!$M15-'PRECIFICAÇÃO '!$O15,0) -> 1743.66 | Q15: {=IFERROR(INDEX(PROCEDIMENTOS!$D$2:$D$48,MATCH('PRECIFICAÇÃO '!$E15,PROCEDIMENTOS!$B$2:$B$48,0)),"")} -> 240.64 | R15: =G15*3.12 -> 187.2 | S15: =IFERROR(H15*16.5%,0) -> 297 | U15: =IFERROR(H15*3%,0) -> 54 | V15: ='PRECIFICAÇÃO '!$Q15+'PRECIFICAÇÃO '!$R15+'PRECIFICAÇÃO '!$S15+'PRECIFICAÇÃO '!$T15+'PRECIFICAÇÃO '!$U15 -> 778.84 | W15: =IFERROR(V15/H15,0) -> 0.43268889 | X15: =IFERROR(P15-V15,0) -> 964.82 | Y15: =IFERROR(X15/H15,0) -> 0.53601111 | Z15: =IFERROR(X15*20%,0) -> 192.964 | AA15: =IFERROR(X15*80%,0) -> 771.856
A16: 46006 | B16: YASMIN | C16: Lucimara | D16: 1 | E16: MMP Alopécia Padrão Feminino (6) | F16: {=IFERROR(INDEX(PROCEDIMENTOS!$A$2:$A$48,MATCH('PRECIFICAÇÃO '!$E16,PROCEDIMENTOS!$B$2:$B$48,0)),"")} -> PROCEDIMENTO | G16: {=IFERROR(INDEX(PROCEDIMENTOS!$C$2:$C$48,MATCH('PRECIFICAÇÃO '!$E16,PROCEDIMENTOS!$B$2:$B$48,0)),"")} -> 270 | H16: 4000 | J16: PIX | L16: =IFERROR(VLOOKUP('PRECIFICAÇÃO '!$J16,TAXA!$A$2:$C$18,2,FALSE),"") -> 0 | M16: =IFERROR(L16*H16,0) -> 0 | N16: =IFERROR(VLOOKUP('PRECIFICAÇÃO '!$J16,TAXA!$A$2:$C$18,3,FALSE),"") -> 0 | O16: =IFERROR(N16*H16,0) -> 0 | P16: =IFERROR('PRECIFICAÇÃO '!$H16-'PRECIFICAÇÃO '!$M16-'PRECIFICAÇÃO '!$O16,0) -> 4000 | Q16: {=IFERROR(INDEX(PROCEDIMENTOS!$D$2:$D$48,MATCH('PRECIFICAÇÃO '!$E16,PROCEDIMENTOS!$B$2:$B$48,0)),"")} -> 46.8 | R16: =G16*3.12 -> 842.4 | S16: =IFERROR(H16*16.5%,0) -> 660 | U16: =IFERROR(H16*3%,0) -> 120 | V16: ='PRECIFICAÇÃO '!$Q16+'PRECIFICAÇÃO '!$R16+'PRECIFICAÇÃO '!$S16+'PRECIFICAÇÃO '!$T16+'PRECIFICAÇÃO '!$U16 -> 1669.2 | W16: =IFERROR(V16/H16,0) -> 0.4173 | X16: =IFERROR(P16-V16,0) -> 2330.8 | Y16: =IFERROR(X16/H16,0) -> 0.5827 | Z16: =IFERROR(X16*20%,0) -> 466.16 | AA16: =IFERROR(X16*80%,0) -> 1864.64
A17: 46006 | B17: YASMIN | C17: Edimisom | D17: 1 | E17: MMP Alopécia Androgenética (6) | F17: {=IFERROR(INDEX(PROCEDIMENTOS!$A$2:$A$48,MATCH('PRECIFICAÇÃO '!$E17,PROCEDIMENTOS!$B$2:$B$48,0)),"")} -> PROCEDIMENTO | G17: {=IFERROR(INDEX(PROCEDIMENTOS!$C$2:$C$48,MATCH('PRECIFICAÇÃO '!$E17,PROCEDIMENTOS!$B$2:$B$48,0)),"")} -> 270 | H17: 4000 | J17: PIX | L17: =IFERROR(VLOOKUP('PRECIFICAÇÃO '!$J17,TAXA!$A$2:$C$18,2,FALSE),"") -> 0 | M17: =IFERROR(L17*H17,0) -> 0 | N17: =IFERROR(VLOOKUP('PRECIFICAÇÃO '!$J17,TAXA!$A$2:$C$18,3,FALSE),"") -> 0 | O17: =IFERROR(N17*H17,0) -> 0 | P17: =IFERROR('PRECIFICAÇÃO '!$H17-'PRECIFICAÇÃO '!$M17-'PRECIFICAÇÃO '!$O17,0) -> 4000 | Q17: {=IFERROR(INDEX(PROCEDIMENTOS!$D$2:$D$48,MATCH('PRECIFICAÇÃO '!$E17,PROCEDIMENTOS!$B$2:$B$48,0)),"")} -> 46.8 | R17: =G17*3.12 -> 842.4 | S17: =IFERROR(H17*16.5%,0) -> 660 | U17: =IFERROR(H17*3%,0) -> 120 | V17: ='PRECIFICAÇÃO '!$Q17+'PRECIFICAÇÃO '!$R17+'PRECIFICAÇÃO '!$S17+'PRECIFICAÇÃO '!$T17+'PRECIFICAÇÃO '!$U17 -> 1669.2 | W17: =IFERROR(V17/H17,0) -> 0.4173 | X17: =IFERROR(P17-V17,0) -> 2330.8 | Y17: =IFERROR(X17/H17,0) -> 0.5827 | Z17: =IFERROR(X17*20%,0) -> 466.16 | AA17: =IFERROR(X17*80%,0) -> 1864.64
A18: 46008 | B18: YASMIN | C18: Nathália | D18: 1 | E18: Clube do Botox | F18: {=IFERROR(INDEX(PROCEDIMENTOS!$A$2:$A$48,MATCH('PRECIFICAÇÃO '!$E18,PROCEDIMENTOS!$B$2:$B$48,0)),"")} -> PROCEDIMENTO | G18: 90 | H18: 3360 | J18: CREDITO 5X | L18: =IFERROR(VLOOKUP('PRECIFICAÇÃO '!$J18,TAXA!$A$2:$C$18,2,FALSE),"") -> 0.0313 | M18: =IFERROR(L18*H18,0) -> 105.168 | N18: =IFERROR(VLOOKUP('PRECIFICAÇÃO '!$J18,TAXA!$A$2:$C$18,3,FALSE),"") -> 0 | O18: =IFERROR(N18*H18,0) -> 0 | P18: =IFERROR('PRECIFICAÇÃO '!$H18-'PRECIFICAÇÃO '!$M18-'PRECIFICAÇÃO '!$O18,0) -> 3254.832 | Q18: {=IFERROR(INDEX(PROCEDIMENTOS!$D$2:$D$48,MATCH('PRECIFICAÇÃO '!$E18,PROCEDIMENTOS!$B$2:$B$48,0)),"")} -> 1699.2 | R18: =G18*3.12 -> 280.8 | S18: =IFERROR(H18*16.5%,0) -> 554.4 | U18: =IFERROR(H18*3%,0) -> 100.8 | V18: ='PRECIFICAÇÃO '!$Q18+'PRECIFICAÇÃO '!$R18+'PRECIFICAÇÃO '!$S18+'PRECIFICAÇÃO '!$T18+'PRECIFICAÇÃO '!$U18 -> 2635.2 | W18: =IFERROR(V18/H18,0) -> 0.78428571 | X18: =IFERROR(P18-V18,0) -> 619.632 | Y18: =IFERROR(X18/H18,0) -> 0.18441429 | Z18: =IFERROR(X18*20%,0) -> 123.9264 | AA18: =IFERROR(X18*80%,0) -> 495.7056
A19: 46017 | B19: YASMIN | C19: João Vitor | D19: 1 | E19: Tirzepatida | F19: {=IFERROR(INDEX(PROCEDIMENTOS!$A$2:$A$48,MATCH('PRECIFICAÇÃO '!$E19,PROCEDIMENTOS!$B$2:$B$48,0)),"")} -> PROCEDIMENTO | G19: 0 | H19: 1700 | J19: PIX | L19: =IFERROR(VLOOKUP('PRECIFICAÇÃO '!$J19,TAXA!$A$2:$C$18,2,FALSE),"") -> 0 | M19: =IFERROR(L19*H19,0) -> 0 | N19: =IFERROR(VLOOKUP('PRECIFICAÇÃO '!$J19,TAXA!$A$2:$C$18,3,FALSE),"") -> 0 | O19: =IFERROR(N19*H19,0) -> 0 | P19: =IFERROR('PRECIFICAÇÃO '!$H19-'PRECIFICAÇÃO '!$M19-'PRECIFICAÇÃO '!$O19,0) -> 1700 | Q19: {=IFERROR(INDEX(PROCEDIMENTOS!$D$2:$D$48,MATCH('PRECIFICAÇÃO '!$E19,PROCEDIMENTOS!$B$2:$B$48,0)),"")} -> 1575 | R19: =G19*3.12 -> 0 | S19: =IFERROR(H19*16.5%,0) -> 280.5 | U19: =IFERROR(H19*3%,0) -> 51 | V19: ='PRECIFICAÇÃO '!$Q19+'PRECIFICAÇÃO '!$R19+'PRECIFICAÇÃO '!$S19+'PRECIFICAÇÃO '!$T19+'PRECIFICAÇÃO '!$U19 -> 1906.5 | W19: =IFERROR(V19/H19,0) -> 1.1214706 | X19: =IFERROR(P19-V19,0) -> -206.5 | Y19: =IFERROR(X19/H19,0) -> -0.12147059 | Z19: =IFERROR(X19*20%,0) -> -41.3 | AA19: =IFERROR(X19*80%,0) -> -165.2
A20: 46019 | B20: YASMIN | C20: Stéphany | D20: 1 | E20: Toxina Botulinica - Terço Superior | F20: {=IFERROR(INDEX(PROCEDIMENTOS!$A$2:$A$48,MATCH('PRECIFICAÇÃO '!$E20,PROCEDIMENTOS!$B$2:$B$48,0)),"")} -> PROCEDIMENTO | G20: {=IFERROR(INDEX(PROCEDIMENTOS!$C$2:$C$48,MATCH('PRECIFICAÇÃO '!$E20,PROCEDIMENTOS!$B$2:$B$48,0)),"")} -> 30 | H20: 999 | J20: PIX | L20: =IFERROR(VLOOKUP('PRECIFICAÇÃO '!$J20,TAXA!$A$2:$C$18,2,FALSE),"") -> 0 | M20: =IFERROR(L20*H20,0) -> 0 | N20: =IFERROR(VLOOKUP('PRECIFICAÇÃO '!$J20,TAXA!$A$2:$C$18,3,FALSE),"") -> 0 | O20: =IFERROR(N20*H20,0) -> 0 | P20: =IFERROR('PRECIFICAÇÃO '!$H20-'PRECIFICAÇÃO '!$M20-'PRECIFICAÇÃO '!$O20,0) -> 999 | Q20: {=IFERROR(INDEX(PROCEDIMENTOS!$D$2:$D$48,MATCH('PRECIFICAÇÃO '!$E20,PROCEDIMENTOS!$B$2:$B$48,0)),"")} -> 566.4 | R20: =G20*3.12 -> 93.6 | S20: =IFERROR(H20*16.5%,0) -> 164.835 | U20: =IFERROR(H20*3%,0) -> 29.97 | V20: ='PRECIFICAÇÃO '!$Q20+'PRECIFICAÇÃO '!$R20+'PRECIFICAÇÃO '!$S20+'PRECIFICAÇÃO '!$T20+'PRECIFICAÇÃO '!$U20 -> 854.805 | W20: =IFERROR(V20/H20,0) -> 0.85566066 | X20: =IFERROR(P20-V20,0) -> 144.195 | Y20: =IFERROR(X20/H20,0) -> 0.14433934 | Z20: =IFERROR(X20*20%,0) -> 28.839 | AA20: =IFERROR(X20*80%,0) -> 115.356
A21: 46021 | B21: YASMIN | C21: Victor Omatti | D21: 1 | E21: MMP Alopécia Androgenética (6) | F21: {=IFERROR(INDEX(PROCEDIMENTOS!$A$2:$A$48,MATCH('PRECIFICAÇÃO '!$E21,PROCEDIMENTOS!$B$2:$B$48,0)),"")} -> PROCEDIMENTO | G21: {=IFERROR(INDEX(PROCEDIMENTOS!$C$2:$C$48,MATCH('PRECIFICAÇÃO '!$E21,PROCEDIMENTOS!$B$2:$B$48,0)),"")} -> 270 | H21: 1900 | J21: DINHEIRO | L21: =IFERROR(VLOOKUP('PRECIFICAÇÃO '!$J21,TAXA!$A$2:$C$18,2,FALSE),"") -> 0 | M21: =IFERROR(L21*H21,0) -> 0 | N21: =IFERROR(VLOOKUP('PRECIFICAÇÃO '!$J21,TAXA!$A$2:$C$18,3,FALSE),"") -> 0 | O21: =IFERROR(N21*H21,0) -> 0 | P21: =IFERROR('PRECIFICAÇÃO '!$H21-'PRECIFICAÇÃO '!$M21-'PRECIFICAÇÃO '!$O21,0) -> 1900 | Q21: {=IFERROR(INDEX(PROCEDIMENTOS!$D$2:$D$48,MATCH('PRECIFICAÇÃO '!$E21,PROCEDIMENTOS!$B$2:$B$48,0)),"")} -> 46.8 | R21: =G21*3.12 -> 842.4 | S21: =IFERROR(H21*16.5%,0) -> 313.5 | U21: =IFERROR(H21*3%,0) -> 57 | V21: ='PRECIFICAÇÃO '!$Q21+'PRECIFICAÇÃO '!$R21+'PRECIFICAÇÃO '!$S21+'PRECIFICAÇÃO '!$T21+'PRECIFICAÇÃO '!$U21 -> 1259.7 | W21: =IFERROR(V21/H21,0) -> 0.663 | X21: =IFERROR(P21-V21,0) -> 640.3 | Y21: =IFERROR(X21/H21,0) -> 0.337 | Z21: =IFERROR(X21*20%,0) -> 128.06 | AA21: =IFERROR(X21*80%,0) -> 512.24
A22: 46021 | B22: YASMIN | C22: Amanda Bárbara | D22: 1 | E22: MMP Alopécia Padrão Feminino (6) | F22: {=IFERROR(INDEX(PROCEDIMENTOS!$A$2:$A$48,MATCH('PRECIFICAÇÃO '!$E22,PROCEDIMENTOS!$B$2:$B$48,0)),"")} -> PROCEDIMENTO | G22: {=IFERROR(INDEX(PROCEDIMENTOS!$C$2:$C$48,MATCH('PRECIFICAÇÃO '!$E22,PROCEDIMENTOS!$B$2:$B$48,0)),"")} -> 270 | H22: 2250 | J22: CREDITO 6X | L22: =IFERROR(VLOOKUP('PRECIFICAÇÃO '!$J22,TAXA!$A$2:$C$18,2,FALSE),"") -> 0.0313 | M22: =IFERROR(L22*H22,0) -> 70.425 | N22: =IFERROR(VLOOKUP('PRECIFICAÇÃO '!$J22,TAXA!$A$2:$C$18,3,FALSE),"") -> 0 | O22: =IFERROR(N22*H22,0) -> 0 | P22: =IFERROR('PRECIFICAÇÃO '!$H22-'PRECIFICAÇÃO '!$M22-'PRECIFICAÇÃO '!$O22,0) -> 2179.575 | Q22: {=IFERROR(INDEX(PROCEDIMENTOS!$D$2:$D$48,MATCH('PRECIFICAÇÃO '!$E22,PROCEDIMENTOS!$B$2:$B$48,0)),"")} -> 46.8 | R22: =G22*3.12 -> 842.4 | S22: =IFERROR(H22*16.5%,0) -> 371.25 | U22: =IFERROR(H22*3%,0) -> 67.5 | V22: ='PRECIFICAÇÃO '!$Q22+'PRECIFICAÇÃO '!$R22+'PRECIFICAÇÃO '!$S22+'PRECIFICAÇÃO '!$T22+'PRECIFICAÇÃO '!$U22 -> 1327.95 | W22: =IFERROR(V22/H22,0) -> 0.5902 | X22: =IFERROR(P22-V22,0) -> 851.625 | Y22: =IFERROR(X22/H22,0) -> 0.3785 | Z22: =IFERROR(X22*20%,0) -> 170.325 | AA22: =IFERROR(X22*80%,0) -> 681.3
A23: 46021 | B23: YASMIN | C23: Amanda Bárbara | D23: 1 | E23: Clube do Botox | F23: {=IFERROR(INDEX(PROCEDIMENTOS!$A$2:$A$48,MATCH('PRECIFICAÇÃO '!$E23,PROCEDIMENTOS!$B$2:$B$48,0)),"")} -> PROCEDIMENTO | G23: {=IFERROR(INDEX(PROCEDIMENTOS!$C$2:$C$48,MATCH('PRECIFICAÇÃO '!$E23,PROCEDIMENTOS!$B$2:$B$48,0)),"")} -> 90 | H23: 3600 | J23: CREDITO 6X | L23: =IFERROR(VLOOKUP('PRECIFICAÇÃO '!$J23,TAXA!$A$2:$C$18,2,FALSE),"") -> 0.0313 | M23: =IFERROR(L23*H23,0) -> 112.68 | N23: =IFERROR(VLOOKUP('PRECIFICAÇÃO '!$J23,TAXA!$A$2:$C$18,3,FALSE),"") -> 0 | O23: =IFERROR(N23*H23,0) -> 0 | P23: =IFERROR('PRECIFICAÇÃO '!$H23-'PRECIFICAÇÃO '!$M23-'PRECIFICAÇÃO '!$O23,0) -> 3487.32 | R23: =G23*3.12 -> 280.8 | S23: =IFERROR(H23*16.5%,0) -> 594 | U23: =IFERROR(H23*3%,0) -> 108 | V23: ='PRECIFICAÇÃO '!$Q23+'PRECIFICAÇÃO '!$R23+'PRECIFICAÇÃO '!$S23+'PRECIFICAÇÃO '!$T23+'PRECIFICAÇÃO '!$U23 -> 982.8 | W23: =IFERROR(V23/H23,0) -> 0.273 | X23: =IFERROR(P23-V23,0) -> 2504.52 | Y23: =IFERROR(X23/H23,0) -> 0.6957 | Z23: =IFERROR(X23*20%,0) -> 500.904 | AA23: =IFERROR(X23*80%,0) -> 2003.616
A24: 46028 | B24: YASMIN | C24: Meire Laura | D24: 1 | E24: Toxina Botulinica - Terço Superior | F24: {=IFERROR(INDEX(PROCEDIMENTOS!$A$2:$A$48,MATCH('PRECIFICAÇÃO '!$E24,PROCEDIMENTOS!$B$2:$B$48,0)),"")} -> PROCEDIMENTO | G24: {=IFERROR(INDEX(PROCEDIMENTOS!$C$2:$C$48,MATCH('PRECIFICAÇÃO '!$E24,PROCEDIMENTOS!$B$2:$B$48,0)),"")} -> 30 | H24: 1600 | J24: CREDITO 3X | L24: =IFERROR(VLOOKUP('PRECIFICAÇÃO '!$J24,TAXA!$A$2:$C$18,2,FALSE),"") -> 0.0313 | M24: =IFERROR(L24*H24,0) -> 50.08 | N24: =IFERROR(VLOOKUP('PRECIFICAÇÃO '!$J24,TAXA!$A$2:$C$18,3,FALSE),"") -> 0 | O24: =IFERROR(N24*H24,0) -> 0 | P24: =IFERROR('PRECIFICAÇÃO '!$H24-'PRECIFICAÇÃO '!$M24-'PRECIFICAÇÃO '!$O24,0) -> 1549.92 | R24: =G24*3.12 -> 93.6 | S24: =IFERROR(H24*16.5%,0) -> 264 | U24: =IFERROR(H24*3%,0) -> 48 | V24: ='PRECIFICAÇÃO '!$Q24+'PRECIFICAÇÃO '!$R24+'PRECIFICAÇÃO '!$S24+'PRECIFICAÇÃO '!$T24+'PRECIFICAÇÃO '!$U24 -> 405.6 | W24: =IFERROR(V24/H24,0) -> 0.2535 | X24: =IFERROR(P24-V24,0) -> 1144.32 | Y24: =IFERROR(X24/H24,0) -> 0.7152 | Z24: =IFERROR(X24*20%,0) -> 228.864 | AA24: =IFERROR(X24*80%,0) -> 915.456
A25: 46034 | B25: YASMIN | C25: Nelson | D25: 1 | E25: 1º consulta médica | F25: {=IFERROR(INDEX(PROCEDIMENTOS!$A$2:$A$48,MATCH('PRECIFICAÇÃO '!$E25,PROCEDIMENTOS!$B$2:$B$48,0)),"")} -> CONSULTA | G25: {=IFERROR(INDEX(PROCEDIMENTOS!$C$2:$C$48,MATCH('PRECIFICAÇÃO '!$E25,PROCEDIMENTOS!$B$2:$B$48,0)),"")} -> 90 | H25: 800 | J25: PIX | L25: =IFERROR(VLOOKUP('PRECIFICAÇÃO '!$J25,TAXA!$A$2:$C$18,2,FALSE),"") -> 0 | M25: =IFERROR(L25*H25,0) -> 0 | N25: =IFERROR(VLOOKUP('PRECIFICAÇÃO '!$J25,TAXA!$A$2:$C$18,3,FALSE),"") -> 0 | O25: =IFERROR(N25*H25,0) -> 0 | P25: =IFERROR('PRECIFICAÇÃO '!$H25-'PRECIFICAÇÃO '!$M25-'PRECIFICAÇÃO '!$O25,0) -> 800 | R25: =G25*3.12 -> 280.8 | S25: =IFERROR(H25*16.5%,0) -> 132 | U25: =IFERROR(H25*3%,0) -> 24 | V25: ='PRECIFICAÇÃO '!$Q25+'PRECIFICAÇÃO '!$R25+'PRECIFICAÇÃO '!$S25+'PRECIFICAÇÃO '!$T25+'PRECIFICAÇÃO '!$U25 -> 436.8 | W25: =IFERROR(V25/H25,0) -> 0.546 | X25: =IFERROR(P25-V25,0) -> 363.2 | Y25: =IFERROR(X25/H25,0) -> 0.454 | Z25: =IFERROR(X25*20%,0) -> 72.64 | AA25: =IFERROR(X25*80%,0) -> 290.56
A26: 46059 | B26: YASMIN | C26: Juliana | D26: 1 | E26: Clube do Botox | F26: {=IFERROR(INDEX(PROCEDIMENTOS!$A$2:$A$48,MATCH('PRECIFICAÇÃO '!$E26,PROCEDIMENTOS!$B$2:$B$48,0)),"")} -> PROCEDIMENTO | G26: {=IFERROR(INDEX(PROCEDIMENTOS!$C$2:$C$48,MATCH('PRECIFICAÇÃO '!$E26,PROCEDIMENTOS!$B$2:$B$48,0)),"")} -> 90 | H26: 3360 | J26: CREDITO 5X | L26: =IFERROR(VLOOKUP('PRECIFICAÇÃO '!$J26,TAXA!$A$2:$C$18,2,FALSE),"") -> 0.0313 | M26: =IFERROR(L26*H26,0) -> 105.168 | N26: =IFERROR(VLOOKUP('PRECIFICAÇÃO '!$J26,TAXA!$A$2:$C$18,3,FALSE),"") -> 0 | O26: =IFERROR(N26*H26,0) -> 0 | P26: =IFERROR('PRECIFICAÇÃO '!$H26-'PRECIFICAÇÃO '!$M26-'PRECIFICAÇÃO '!$O26,0) -> 3254.832 | Q26: {=IFERROR(INDEX(PROCEDIMENTOS!$D$2:$D$48,MATCH('PRECIFICAÇÃO '!$E26,PROCEDIMENTOS!$B$2:$B$48,0)),"")} -> 1699.2 | R26: =G26*3.12 -> 280.8 | S26: =IFERROR(H26*16.5%,0) -> 554.4 | U26: =IFERROR(H26*3%,0) -> 100.8 | V26: ='PRECIFICAÇÃO '!$Q26+'PRECIFICAÇÃO '!$R26+'PRECIFICAÇÃO '!$S26+'PRECIFICAÇÃO '!$T26+'PRECIFICAÇÃO '!$U26 -> 2635.2 | W26: =IFERROR(V26/H26,0) -> 0.78428571 | X26: =IFERROR(P26-V26,0) -> 619.632 | Y26: =IFERROR(X26/H26,0) -> 0.18441429 | Z26: =IFERROR(X26*20%,0) -> 123.9264 | AA26: =IFERROR(X26*80%,0) -> 495.7056
A27: 46065 | B27: YASMIN | C27: Pedro Augusto | D27: 1 | E27: 1º consulta médica | F27: {=IFERROR(INDEX(PROCEDIMENTOS!$A$2:$A$48,MATCH('PRECIFICAÇÃO '!$E27,PROCEDIMENTOS!$B$2:$B$48,0)),"")} -> CONSULTA | G27: {=IFERROR(INDEX(PROCEDIMENTOS!$C$2:$C$48,MATCH('PRECIFICAÇÃO '!$E27,PROCEDIMENTOS!$B$2:$B$48,0)),"")} -> 90 | H27: 800 | J27: CREDITO 2X | L27: =IFERROR(VLOOKUP('PRECIFICAÇÃO '!$J27,TAXA!$A$2:$C$18,2,FALSE),"") -> 0.0313 | M27: =IFERROR(L27*H27,0) -> 25.04 | N27: =IFERROR(VLOOKUP('PRECIFICAÇÃO '!$J27,TAXA!$A$2:$C$18,3,FALSE),"") -> 0 | O27: =IFERROR(N27*H27,0) -> 0 | P27: =IFERROR('PRECIFICAÇÃO '!$H27-'PRECIFICAÇÃO '!$M27-'PRECIFICAÇÃO '!$O27,0) -> 774.96 | Q27: {=IFERROR(INDEX(PROCEDIMENTOS!$D$2:$D$48,MATCH('PRECIFICAÇÃO '!$E27,PROCEDIMENTOS!$B$2:$B$48,0)),"")} -> 0 | R27: =G27*3.12 -> 280.8 | S27: =IFERROR(H27*16.5%,0) -> 132 | U27: =IFERROR(H27*3%,0) -> 24 | V27: ='PRECIFICAÇÃO '!$Q27+'PRECIFICAÇÃO '!$R27+'PRECIFICAÇÃO '!$S27+'PRECIFICAÇÃO '!$T27+'PRECIFICAÇÃO '!$U27 -> 436.8 | W27: =IFERROR(V27/H27,0) -> 0.546 | X27: =IFERROR(P27-V27,0) -> 338.16 | Y27: =IFERROR(X27/H27,0) -> 0.4227 | Z27: =IFERROR(X27*20%,0) -> 67.632 | AA27: =IFERROR(X27*80%,0) -> 270.528
A28: 46071 | B28: YASMIN | C28: Jamille | D28: 1 | E28: Toxina Botulinica - Terço Superior | F28: {=IFERROR(INDEX(PROCEDIMENTOS!$A$2:$A$48,MATCH('PRECIFICAÇÃO '!$E28,PROCEDIMENTOS!$B$2:$B$48,0)),"")} -> PROCEDIMENTO | G28: {=IFERROR(INDEX(PROCEDIMENTOS!$C$2:$C$48,MATCH('PRECIFICAÇÃO '!$E28,PROCEDIMENTOS!$B$2:$B$48,0)),"")} -> 30 | H28: 1600 | J28: CREDITO 4X | L28: =IFERROR(VLOOKUP('PRECIFICAÇÃO '!$J28,TAXA!$A$2:$C$18,2,FALSE),"") -> 0.0313 | M28: =IFERROR(L28*H28,0) -> 50.08 | N28: =IFERROR(VLOOKUP('PRECIFICAÇÃO '!$J28,TAXA!$A$2:$C$18,3,FALSE),"") -> 0 | O28: =IFERROR(N28*H28,0) -> 0 | P28: =IFERROR('PRECIFICAÇÃO '!$H28-'PRECIFICAÇÃO '!$M28-'PRECIFICAÇÃO '!$O28,0) -> 1549.92 | Q28: {=IFERROR(INDEX(PROCEDIMENTOS!$D$2:$D$48,MATCH('PRECIFICAÇÃO '!$E28,PROCEDIMENTOS!$B$2:$B$48,0)),"")} -> 566.4 | R28: =G28*3.12 -> 93.6 | S28: =IFERROR(H28*16.5%,0) -> 264 | U28: =IFERROR(H28*3%,0) -> 48 | V28: ='PRECIFICAÇÃO '!$Q28+'PRECIFICAÇÃO '!$R28+'PRECIFICAÇÃO '!$S28+'PRECIFICAÇÃO '!$T28+'PRECIFICAÇÃO '!$U28 -> 972 | W28: =IFERROR(V28/H28,0) -> 0.6075 | X28: =IFERROR(P28-V28,0) -> 577.92 | Y28: =IFERROR(X28/H28,0) -> 0.3612 | Z28: =IFERROR(X28*20%,0) -> 115.584 | AA28: =IFERROR(X28*80%,0) -> 462.336
A29: 46072 | B29: YASMIN | C29: Sandro | D29: 1 | E29: MMP Alopécia Androgenética (6) | F29: {=IFERROR(INDEX(PROCEDIMENTOS!$A$2:$A$48,MATCH('PRECIFICAÇÃO '!$E29,PROCEDIMENTOS!$B$2:$B$48,0)),"")} -> PROCEDIMENTO | G29: {=IFERROR(INDEX(PROCEDIMENTOS!$C$2:$C$48,MATCH('PRECIFICAÇÃO '!$E29,PROCEDIMENTOS!$B$2:$B$48,0)),"")} -> 270 | H29: 2800 | J29: PIX | L29: =IFERROR(VLOOKUP('PRECIFICAÇÃO '!$J29,TAXA!$A$2:$C$18,2,FALSE),"") -> 0 | M29: =IFERROR(L29*H29,0) -> 0 | N29: =IFERROR(VLOOKUP('PRECIFICAÇÃO '!$J29,TAXA!$A$2:$C$18,3,FALSE),"") -> 0 | O29: =IFERROR(N29*H29,0) -> 0 | P29: =IFERROR('PRECIFICAÇÃO '!$H29-'PRECIFICAÇÃO '!$M29-'PRECIFICAÇÃO '!$O29,0) -> 2800 | Q29: {=IFERROR(INDEX(PROCEDIMENTOS!$D$2:$D$48,MATCH('PRECIFICAÇÃO '!$E29,PROCEDIMENTOS!$B$2:$B$48,0)),"")} -> 46.8 | R29: =G29*3.12 -> 842.4 | S29: =IFERROR(H29*16.5%,0) -> 462 | U29: =IFERROR(H29*3%,0) -> 84 | V29: ='PRECIFICAÇÃO '!$Q29+'PRECIFICAÇÃO '!$R29+'PRECIFICAÇÃO '!$S29+'PRECIFICAÇÃO '!$T29+'PRECIFICAÇÃO '!$U29 -> 1435.2 | W29: =IFERROR(V29/H29,0) -> 0.51257143 | X29: =IFERROR(P29-V29,0) -> 1364.8 | Y29: =IFERROR(X29/H29,0) -> 0.48742857 | Z29: =IFERROR(X29*20%,0) -> 272.96 | AA29: =IFERROR(X29*80%,0) -> 1091.84
A30: 46072 | B30: YASMIN | C30: Sandro | D30: 1 | E30: MMP Alopécia Androgenética (6) | F30: {=IFERROR(INDEX(PROCEDIMENTOS!$A$2:$A$48,MATCH('PRECIFICAÇÃO '!$E30,PROCEDIMENTOS!$B$2:$B$48,0)),"")} -> PROCEDIMENTO | G30: {=IFERROR(INDEX(PROCEDIMENTOS!$C$2:$C$48,MATCH('PRECIFICAÇÃO '!$E30,PROCEDIMENTOS!$B$2:$B$48,0)),"")} -> 270 | H30: 1700 | J30: CREDITO 6X | L30: =IFERROR(VLOOKUP('PRECIFICAÇÃO '!$J30,TAXA!$A$2:$C$18,2,FALSE),"") -> 0.0313 | M30: =IFERROR(L30*H30,0) -> 53.21 | N30: =IFERROR(VLOOKUP('PRECIFICAÇÃO '!$J30,TAXA!$A$2:$C$18,3,FALSE),"") -> 0 | O30: =IFERROR(N30*H30,0) -> 0 | P30: =IFERROR('PRECIFICAÇÃO '!$H30-'PRECIFICAÇÃO '!$M30-'PRECIFICAÇÃO '!$O30,0) -> 1646.79 | Q30: {=IFERROR(INDEX(PROCEDIMENTOS!$D$2:$D$48,MATCH('PRECIFICAÇÃO '!$E30,PROCEDIMENTOS!$B$2:$B$48,0)),"")} -> 46.8 | R30: =G30*3.12 -> 842.4 | S30: =IFERROR(H30*16.5%,0) -> 280.5 | U30: =IFERROR(H30*3%,0) -> 51 | V30: ='PRECIFICAÇÃO '!$Q30+'PRECIFICAÇÃO '!$R30+'PRECIFICAÇÃO '!$S30+'PRECIFICAÇÃO '!$T30+'PRECIFICAÇÃO '!$U30 -> 1220.7 | W30: =IFERROR(V30/H30,0) -> 0.71805882 | X30: =IFERROR(P30-V30,0) -> 426.09 | Y30: =IFERROR(X30/H30,0) -> 0.25064118 | Z30: =IFERROR(X30*20%,0) -> 85.218 | AA30: =IFERROR(X30*80%,0) -> 340.872
A31: 46077 | B31: YASMIN | C31: José Ricardo | D31: 1 | E31: Toxina Botulinica - Terço Superior | F31: {=IFERROR(INDEX(PROCEDIMENTOS!$A$2:$A$48,MATCH('PRECIFICAÇÃO '!$E31,PROCEDIMENTOS!$B$2:$B$48,0)),"")} -> PROCEDIMENTO | G31: {=IFERROR(INDEX(PROCEDIMENTOS!$C$2:$C$48,MATCH('PRECIFICAÇÃO '!$E31,PROCEDIMENTOS!$B$2:$B$48,0)),"")} -> 30 | H31: 1440 | J31: PIX | L31: =IFERROR(VLOOKUP('PRECIFICAÇÃO '!$J31,TAXA!$A$2:$C$18,2,FALSE),"") -> 0 | M31: =IFERROR(L31*H31,0) -> 0 | N31: =IFERROR(VLOOKUP('PRECIFICAÇÃO '!$J31,TAXA!$A$2:$C$18,3,FALSE),"") -> 0 | O31: =IFERROR(N31*H31,0) -> 0 | P31: =IFERROR('PRECIFICAÇÃO '!$H31-'PRECIFICAÇÃO '!$M31-'PRECIFICAÇÃO '!$O31,0) -> 1440 | R31: =G31*3.12 -> 93.6 | S31: =IFERROR(H31*16.5%,0) -> 237.6 | U31: =IFERROR(H31*3%,0) -> 43.2 | V31: ='PRECIFICAÇÃO '!$Q31+'PRECIFICAÇÃO '!$R31+'PRECIFICAÇÃO '!$S31+'PRECIFICAÇÃO '!$T31+'PRECIFICAÇÃO '!$U31 -> 374.4 | W31: =IFERROR(V31/H31,0) -> 0.26 | X31: =IFERROR(P31-V31,0) -> 1065.6 | Y31: =IFERROR(X31/H31,0) -> 0.74 | Z31: =IFERROR(X31*20%,0) -> 213.12 | AA31: =IFERROR(X31*80%,0) -> 852.48
A32: 46079 | B32: YASMIN | C32: Edimsom | D32: 1 | E32: Biópsia de Pele (1 lesão) | F32: {=IFERROR(INDEX(PROCEDIMENTOS!$A$2:$A$48,MATCH('PRECIFICAÇÃO '!$E32,PROCEDIMENTOS!$B$2:$B$48,0)),"")} -> PROCEDIMENTO | G32: {=IFERROR(INDEX(PROCEDIMENTOS!$C$2:$C$48,MATCH('PRECIFICAÇÃO '!$E32,PROCEDIMENTOS!$B$2:$B$48,0)),"")} -> 30 | H32: 1400 | J32: PIX | L32: =IFERROR(VLOOKUP('PRECIFICAÇÃO '!$J32,TAXA!$A$2:$C$18,2,FALSE),"") -> 0 | M32: =IFERROR(L32*H32,0) -> 0 | N32: =IFERROR(VLOOKUP('PRECIFICAÇÃO '!$J32,TAXA!$A$2:$C$18,3,FALSE),"") -> 0 | O32: =IFERROR(N32*H32,0) -> 0 | P32: =IFERROR('PRECIFICAÇÃO '!$H32-'PRECIFICAÇÃO '!$M32-'PRECIFICAÇÃO '!$O32,0) -> 1400 | R32: =G32*3.12 -> 93.6 | S32: =IFERROR(H32*16.5%,0) -> 231 | U32: =IFERROR(H32*3%,0) -> 42 | V32: ='PRECIFICAÇÃO '!$Q32+'PRECIFICAÇÃO '!$R32+'PRECIFICAÇÃO '!$S32+'PRECIFICAÇÃO '!$T32+'PRECIFICAÇÃO '!$U32 -> 366.6 | W32: =IFERROR(V32/H32,0) -> 0.26185714 | X32: =IFERROR(P32-V32,0) -> 1033.4 | Y32: =IFERROR(X32/H32,0) -> 0.73814286 | Z32: =IFERROR(X32*20%,0) -> 206.68 | AA32: =IFERROR(X32*80%,0) -> 826.72
A33: 46056 | B33: YASMIN | C33: Luiza Rodrigues | D33: 1 | E33: MMP Eflúvio Telógeno (geral) 6 | F33: {=IFERROR(INDEX(PROCEDIMENTOS!$A$2:$A$48,MATCH('PRECIFICAÇÃO '!$E33,PROCEDIMENTOS!$B$2:$B$48,0)),"")} -> PROCEDIMENTO | G33: {=IFERROR(INDEX(PROCEDIMENTOS!$C$2:$C$48,MATCH('PRECIFICAÇÃO '!$E33,PROCEDIMENTOS!$B$2:$B$48,0)),"")} -> 270 | H33: 4500 | J33: CREDITO 6X | L33: =IFERROR(VLOOKUP('PRECIFICAÇÃO '!$J33,TAXA!$A$2:$C$18,2,FALSE),"") -> 0.0313 | M33: =IFERROR(L33*H33,0) -> 140.85 | N33: =IFERROR(VLOOKUP('PRECIFICAÇÃO '!$J33,TAXA!$A$2:$C$18,3,FALSE),"") -> 0 | O33: =IFERROR(N33*H33,0) -> 0 | P33: =IFERROR('PRECIFICAÇÃO '!$H33-'PRECIFICAÇÃO '!$M33-'PRECIFICAÇÃO '!$O33,0) -> 4359.15 | R33: =G33*3.12 -> 842.4 | S33: =IFERROR(H33*16.5%,0) -> 742.5 | U33: =IFERROR(H33*3%,0) -> 135 | V33: ='PRECIFICAÇÃO '!$Q33+'PRECIFICAÇÃO '!$R33+'PRECIFICAÇÃO '!$S33+'PRECIFICAÇÃO '!$T33+'PRECIFICAÇÃO '!$U33 -> 1719.9 | W33: =IFERROR(V33/H33,0) -> 0.3822 | X33: =IFERROR(P33-V33,0) -> 2639.25 | Y33: =IFERROR(X33/H33,0) -> 0.5865 | Z33: =IFERROR(X33*20%,0) -> 527.85 | AA33: =IFERROR(X33*80%,0) -> 2111.4
A34: 46087 | B34: YASMIN | C34: Jamille Uez | D34: 2 | E34: Ácido Hialurônico - Volbella Juvederm | F34: {=IFERROR(INDEX(PROCEDIMENTOS!$A$2:$A$48,MATCH('PRECIFICAÇÃO '!$E34,PROCEDIMENTOS!$B$2:$B$48,0)),"")} -> PROCEDIMENTO | G34: {=IFERROR(INDEX(PROCEDIMENTOS!$C$2:$C$48,MATCH('PRECIFICAÇÃO '!$E34,PROCEDIMENTOS!$B$2:$B$48,0)),"")} -> 60 | H34: 3600 | J34: CREDITO 6X | L34: =IFERROR(VLOOKUP('PRECIFICAÇÃO '!$J34,TAXA!$A$2:$C$18,2,FALSE),"") -> 0.0313 | M34: =IFERROR(L34*H34,0) -> 112.68 | N34: =IFERROR(VLOOKUP('PRECIFICAÇÃO '!$J34,TAXA!$A$2:$C$18,3,FALSE),"") -> 0 | O34: =IFERROR(N34*H34,0) -> 0 | P34: =IFERROR('PRECIFICAÇÃO '!$H34-'PRECIFICAÇÃO '!$M34-'PRECIFICAÇÃO '!$O34,0) -> 3487.32 | Q34: {=IFERROR(INDEX(PROCEDIMENTOS!$D$2:$D$48,MATCH('PRECIFICAÇÃO '!$E34,PROCEDIMENTOS!$B$2:$B$48,0)),"")} -> 360.35 | R34: =G34*3.12 -> 187.2 | S34: =IFERROR(H34*16.5%,0) -> 594 | U34: =IFERROR(H34*3%,0) -> 108 | V34: ='PRECIFICAÇÃO '!$Q34+'PRECIFICAÇÃO '!$R34+'PRECIFICAÇÃO '!$S34+'PRECIFICAÇÃO '!$T34+'PRECIFICAÇÃO '!$U34 -> 1249.55 | W34: =IFERROR(V34/H34,0) -> 0.34709722 | X34: =IFERROR(P34-V34,0) -> 2237.77 | Y34: =IFERROR(X34/H34,0) -> 0.62160278 | Z34: =IFERROR(X34*20%,0) -> 447.554 | AA34: =IFERROR(X34*80%,0) -> 1790.216
F35: {=IFERROR(INDEX(PROCEDIMENTOS!$A$2:$A$48,MATCH('PRECIFICAÇÃO '!$E35,PROCEDIMENTOS!$B$2:$B$48,0)),"")} | G35: {=IFERROR(INDEX(PROCEDIMENTOS!$C$2:$C$48,MATCH('PRECIFICAÇÃO '!$E35,PROCEDIMENTOS!$B$2:$B$48,0)),"")} | L35: =IFERROR(VLOOKUP('PRECIFICAÇÃO '!$J35,TAXA!$A$2:$C$18,2,FALSE),"") | M35: =IFERROR(L35*H35,0) -> 0 | N35: =IFERROR(VLOOKUP('PRECIFICAÇÃO '!$J35,TAXA!$A$2:$C$18,3,FALSE),"") | O35: =IFERROR(N35*H35,0) -> 0 | P35: =IFERROR('PRECIFICAÇÃO '!$H35-'PRECIFICAÇÃO '!$M35-'PRECIFICAÇÃO '!$O35,0) -> 0 | Q35: {=IFERROR(INDEX(PROCEDIMENTOS!$D$2:$D$48,MATCH('PRECIFICAÇÃO '!$E35,PROCEDIMENTOS!$B$2:$B$48,0)),"")} | R35: =G35*3.12 -> 0 | S35: =IFERROR(H35*16.5%,0) -> 0 | U35: =IFERROR(H35*3%,0) -> 0 | V35: ='PRECIFICAÇÃO '!$Q35+'PRECIFICAÇÃO '!$R35+'PRECIFICAÇÃO '!$S35+'PRECIFICAÇÃO '!$T35+'PRECIFICAÇÃO '!$U35 -> 0 | W35: =IFERROR(V35/H35,0) -> 0 | X35: =IFERROR(P35-V35,0) -> 0 | Y35: =IFERROR(X35/H35,0) -> 0 | Z35: =IFERROR(X35*20%,0) -> 0 | AA35: =IFERROR(X35*80%,0) -> 0
F36: {=IFERROR(INDEX(PROCEDIMENTOS!$A$2:$A$48,MATCH('PRECIFICAÇÃO '!$E36,PROCEDIMENTOS!$B$2:$B$48,0)),"")} | G36: {=IFERROR(INDEX(PROCEDIMENTOS!$C$2:$C$48,MATCH('PRECIFICAÇÃO '!$E36,PROCEDIMENTOS!$B$2:$B$48,0)),"")} | L36: =IFERROR(VLOOKUP('PRECIFICAÇÃO '!$J36,TAXA!$A$2:$C$18,2,FALSE),"") | M36: =IFERROR(L36*H36,0) -> 0 | N36: =IFERROR(VLOOKUP('PRECIFICAÇÃO '!$J36,TAXA!$A$2:$C$18,3,FALSE),"") | O36: =IFERROR(N36*H36,0) -> 0 | P36: =IFERROR('PRECIFICAÇÃO '!$H36-'PRECIFICAÇÃO '!$M36-'PRECIFICAÇÃO '!$O36,0) -> 0 | Q36: {=IFERROR(INDEX(PROCEDIMENTOS!$D$2:$D$48,MATCH('PRECIFICAÇÃO '!$E36,PROCEDIMENTOS!$B$2:$B$48,0)),"")} | R36: =G36*3.12 -> 0 | S36: =IFERROR(H36*16.5%,0) -> 0 | U36: =IFERROR(H36*3%,0) -> 0 | V36: ='PRECIFICAÇÃO '!$Q36+'PRECIFICAÇÃO '!$R36+'PRECIFICAÇÃO '!$S36+'PRECIFICAÇÃO '!$T36+'PRECIFICAÇÃO '!$U36 -> 0 | W36: =IFERROR(V36/H36,0) -> 0 | X36: =IFERROR(P36-V36,0) -> 0 | Y36: =IFERROR(X36/H36,0) -> 0 | Z36: =IFERROR(X36*20%,0) -> 0 | AA36: =IFERROR(X36*80%,0) -> 0
