Workbook

Sheet SALDO ATUAL
A1: -
A2: CÓD | B2: STATUS | C2: NOME DO PRODUTO | D2: CATEGORIA | E2: UNIDADE | F2: FABRICANTE | G2: VALOR UNITÁRIO | H2: QTD EM ESTOQUE INICIAL | I2: QTD MÍNIMA | J2: TOTAL ENTRADA | K2: TOTAL SAÍDA | L2: QTD ESTOQUE ATUAL | M2: VALOR ESTIMADO | N2: VALOR TOTAL | O2: SITUAÇÃO | P2: QTD MÍNIMA A COMPRAR
A3: 1 | C3: AC. ALFA LIPOICO OPTMUS | D3: ATIVOS | E3: 001 - Ampola | F3: OPTIMUS | H3: 2 | I3: 4 | J3: =SUMIF(ENTRADAS!B:B,A:A,ENTRADAS!F:F) -> 6 | K3: =SUMIF(SAÍDAS!B:B,A:A,SAÍDAS!F:F) -> 5 | L3: =H3+J3-K3 -> 3 | M3: ='SALDO ATUAL'!$G277*'SALDO ATUAL'!$I277 -> 0 | N3: ='SALDO ATUAL'!$G277*'SALDO ATUAL'!$L277 -> 0 | O3: =IF(L3>=I3,"OK","COMPRAR") -> COMPRAR | P3: =IF(O3="COMPRAR",I3-L3,0) -> 1
A4: 2 | C4: ACNE FORMULA NEAUVIA | D4: ATIVOS | J4: =SUMIF(ENTRADAS!B:B,A:A,ENTRADAS!F:F) -> 0 | K4: =SUMIF(SAÍDAS!B:B,A:A,SAÍDAS!F:F) -> 0 | L4: =H4+J4-K4 -> 0 | M4: ='SALDO ATUAL'!$G169*'SALDO ATUAL'!$I169 -> 0 | N4: ='SALDO ATUAL'!$G169*'SALDO ATUAL'!$L169 -> 0 | O4: =IF(L4>=I4,"OK","COMPRAR") -> OK | P4: =IF(O4="COMPRAR",I4-L4,0) -> 0
A5: 5 | C5: AGUA DESTILADA 5L | D5: SOLUÇÕES | E5: 015- Galão | H5: 1
A6: 6 | C6: AGUA MICELAR BIODERMA | D6: DERMOCOSMÉTICO E COSMÉTICO | E6: 036 - Unidade | F6: BIODERMA | H6: 4 | I6: 4 | J6: =SUMIF(ENTRADAS!B:B,A:A,ENTRADAS!F:F) -> 0 | K6: =SUMIF(SAÍDAS!B:B,A:A,SAÍDAS!F:F) -> 5 | L6: =H6+J6-K6 -> -1 | M6: ='SALDO ATUAL'!$G11*'SALDO ATUAL'!$I11 -> 521 | N6: ='SALDO ATUAL'!$G11*'SALDO ATUAL'!$L11 -> 1042 | O6: =IF(L6>=I6,"OK","COMPRAR") -> COMPRAR | P6: =IF(O6="COMPRAR",I6-L6,0) -> 5
A7: 8 | C7: ÁGUA PARA INJEÇÃO EQUIPLEX | D7: MATERIAIS DESCARTÁVEIS E APOIO | E7: 012 - Flaconete | F7: EQUIPLEX | G7: 4.75 | H7: 20 | I7: 5 | J7: =SUMIF(ENTRADAS!B:B,A:A,ENTRADAS!F:F) -> 0 | K7: =SUMIF(SAÍDAS!B:B,A:A,SAÍDAS!F:F) -> 0 | L7: =H7+J7-K7 -> 20 | M7: =#REF!*#REF! -> #REF! | N7: =#REF!*#REF! -> #REF! | O7: =IF(L7>=I7,"OK","COMPRAR") -> OK | P7: =IF(O7="COMPRAR",I7-L7,0) -> 0
A8: 11 | C8: ÁGUA TERMAL MINERAUX | D8: DERMOCOSMÉTICO E COSMÉTICO | E8: 013 - Frasco | F8: MINERAUX | G8: 72.64 | H8: 72 | I8: 20 | J8: =SUMIF(ENTRADAS!B:B,A:A,ENTRADAS!F:F) -> 1 | K8: =SUMIF(SAÍDAS!B:B,A:A,SAÍDAS!F:F) -> 7 | L8: =H8+J8-K8 -> 66 | M8: ='SALDO ATUAL'!$G63*'SALDO ATUAL'!$I63 -> 32.5 | N8: ='SALDO ATUAL'!$G63*'SALDO ATUAL'!$L63 -> 26 | O8: =IF(L8>=I8,"OK","COMPRAR") -> OK | P8: =IF(O8="COMPRAR",I8-L8,0) -> 0
A9: 12 | C9: AGULHA 32G 4MM SMART GR | D9: AGULHAS | E9: 036 - Unidade | F9: SMART GR | G9: 302.9 | H9: 2 | I9: 1 | J9: =SUMIF(ENTRADAS!B:B,A:A,ENTRADAS!F:F) -> 0 | K9: =SUMIF(SAÍDAS!B:B,A:A,SAÍDAS!F:F) -> 0 | L9: =H9+J9-K9 -> 2 | M9: ='SALDO ATUAL'!$G298*'SALDO ATUAL'!$I298 -> 17 | N9: ='SALDO ATUAL'!$G298*'SALDO ATUAL'!$L298 -> 34 | O9: =IF(L9>=I9,"OK","COMPRAR") -> OK | P9: =IF(O9="COMPRAR",I9-L9,0) -> 0
A10: 13 | C10: AGULHA AMARELA 30G - 13X3 BD | D10: AGULHAS | E10: 036 - Unidade | F10: BD | G10: 24.12 | H10: 2 | I10: 1 | J10: =SUMIF(ENTRADAS!B:B,A:A,ENTRADAS!F:F) -> 0 | K10: =SUMIF(SAÍDAS!B:B,A:A,SAÍDAS!F:F) -> 0 | L10: =H10+J10-K10 -> 2 | M10: ='SALDO ATUAL'!$G297*'SALDO ATUAL'!$I297 -> 0 | N10: ='SALDO ATUAL'!$G297*'SALDO ATUAL'!$L297 -> 0 | O10: =IF(L10>=I10,"OK","COMPRAR") -> OK | P10: =IF(O10="COMPRAR",I10-L10,0) -> 0
A11: 15 | C11: AGULHA CHEYENNE 27 MAGNUM | D11: AGULHAS | E11: 036 - Unidade | F11: CHEYENNE | G11: 521 | H11: 2 | I11: 1 | J11: =SUMIF(ENTRADAS!B:B,A:A,ENTRADAS!F:F) -> 0 | K11: =SUMIF(SAÍDAS!B:B,A:A,SAÍDAS!F:F) -> 0 | L11: =H11+J11-K11 -> 2 | M11: ='SALDO ATUAL'!$G295*'SALDO ATUAL'!$I295 -> 27.18 | N11: ='SALDO ATUAL'!$G295*'SALDO ATUAL'!$L295 -> 27.18 | O11: =IF(L11>=I11,"OK","COMPRAR") -> OK | P11: =IF(O11="COMPRAR",I11-L11,0) -> 0
A12: 19 | C12: AH SOFIDERM 10ML | D12: PREENCHEDOR | E12: 023 - Mililitro | F12: AESKINS | H12: 4 | I12: 2 | J12: =SUMIF(ENTRADAS!B:B,A:A,ENTRADAS!F:F) -> 0 | K12: =SUMIF(SAÍDAS!B:B,A:A,SAÍDAS!F:F) -> 0 | L12: =H12+J12-K12 -> 4 | M12: ='SALDO ATUAL'!$G212*'SALDO ATUAL'!$I212 -> 18110.1 | N12: ='SALDO ATUAL'!$G212*'SALDO ATUAL'!$L212 -> 18110.1 | O12: =IF(L12>=I12,"OK","COMPRAR") -> OK | P12: =IF(O12="COMPRAR",I12-L12,0) -> 0
A13: 20 | C13: AGULHA ROSA 18G - 40X12 UNIQMED | D13: AGULHAS | E13: 036 - Unidade | F13: UNIQMED | G13: 10.87 | H13: 3 | I13: 2 | J13: =SUMIF(ENTRADAS!B:B,A:A,ENTRADAS!F:F) -> 0 | K13: =SUMIF(SAÍDAS!B:B,A:A,SAÍDAS!F:F) -> 2 | L13: =H13+J13-K13 -> 1 | M13: ='SALDO ATUAL'!$G296*'SALDO ATUAL'!$I296 -> 0 | N13: ='SALDO ATUAL'!$G296*'SALDO ATUAL'!$L296 -> 0 | O13: =IF(L13>=I13,"OK","COMPRAR") -> COMPRAR | P13: =IF(O13="COMPRAR",I13-L13,0) -> 1
A14: 24 | C14: AH BELOTERO BALANCE | D14: PREENCHEDOR | E14: 023 - Mililitro | F14: MERZ | G14: 193.1 | H14: 51 | I14: 30 | J14: =SUMIF(ENTRADAS!B:B,A:A,ENTRADAS!F:F) -> 0 | K14: =SUMIF(SAÍDAS!B:B,A:A,SAÍDAS!F:F) -> 22 | L14: =H14+J14-K14 -> 29 | M14: ='SALDO ATUAL'!$G269*'SALDO ATUAL'!$I269 -> 180.84 | N14: ='SALDO ATUAL'!$G269*'SALDO ATUAL'!$L269 -> 813.78 | O14: =IF(L14>=I14,"OK","COMPRAR") -> COMPRAR | P14: =IF(O14="COMPRAR",I14-L14,0) -> 1
A15: 25 | C15: AH BELOTERO INTENSE | D15: PREENCHEDOR | E15: 023 - Mililitro | F15: MERZ | G15: 210 | H15: 99 | I15: 30 | J15: =SUMIF(ENTRADAS!B:B,A:A,ENTRADAS!F:F) -> 2 | K15: =SUMIF(SAÍDAS!B:B,A:A,SAÍDAS!F:F) -> 34 | L15: =H15+J15-K15 -> 67 | M15: ='SALDO ATUAL'!$G90*'SALDO ATUAL'!$I90 -> 0 | N15: ='SALDO ATUAL'!$G90*'SALDO ATUAL'!$L90 -> 0 | O15: =IF(L15>=I15,"OK","COMPRAR") -> OK | P15: =IF(O15="COMPRAR",I15-L15,0) -> 0
A16: 26 | C16: AH BELOTERO VOLUME | D16: PREENCHEDOR | E16: 023 - Mililitro | F16: MERZ | G16: 437 | H16: 18 | I16: 30
A17: 31 | C17: AH RESTYLANE LYFT LIDO | D17: PREENCHEDOR | H17: 0 | J17: =SUMIF(ENTRADAS!B:B,A:A,ENTRADAS!F:F) -> 0 | K17: =SUMIF(SAÍDAS!B:B,A:A,SAÍDAS!F:F) -> 0 | L17: =H17+J17-K17 -> 0 | M17: ='SALDO ATUAL'!$G49*'SALDO ATUAL'!$I49 -> 0 | N17: ='SALDO ATUAL'!$G49*'SALDO ATUAL'!$L49 -> 0 | O17: =IF(L17>=I17,"OK","COMPRAR") -> OK | P17: =IF(O17="COMPRAR",I17-L17,0) -> 0
A18: 32 | C18: AH RESTYLANE REFYNE | D18: PREENCHEDOR | H18: 0 | J18: =SUMIF(ENTRADAS!B:B,A:A,ENTRADAS!F:F) -> 0 | K18: =SUMIF(SAÍDAS!B:B,A:A,SAÍDAS!F:F) -> 0 | L18: =H18+J18-K18 -> 0 | M18: ='SALDO ATUAL'!$G130*'SALDO ATUAL'!$I130 -> 0 | N18: ='SALDO ATUAL'!$G130*'SALDO ATUAL'!$L130 -> 0 | O18: =IF(L18>=I18,"OK","COMPRAR") -> OK | P18: =IF(O18="COMPRAR",I18-L18,0) -> 0
A19: 33 | C19: AH RESTYLANE SHAYPE | D19: PREENCHEDOR | H19: 0 | J19: =SUMIF(ENTRADAS!B:B,A:A,ENTRADAS!F:F) -> 0 | K19: =SUMIF(SAÍDAS!B:B,A:A,SAÍDAS!F:F) -> 0 | L19: =H19+J19-K19 -> 0 | M19: ='SALDO ATUAL'!$G270*'SALDO ATUAL'!$I270 -> 0 | N19: ='SALDO ATUAL'!$G270*'SALDO ATUAL'!$L270 -> 0 | O19: =IF(L19>=I19,"OK","COMPRAR") -> OK | P19: =IF(O19="COMPRAR",I19-L19,0) -> 0
A20: 34 | C20: AH RESTYLANE SKINBOOSTER VITAL LIGHT LIDOCAINE | D20: PREENCHEDOR | H20: 0 | J20: =SUMIF(ENTRADAS!B:B,A:A,ENTRADAS!F:F) -> 0 | K20: =SUMIF(SAÍDAS!B:B,A:A,SAÍDAS!F:F) -> 0 | L20: =H20+J20-K20 -> 0 | M20: ='SALDO ATUAL'!$G27*'SALDO ATUAL'!$I27 -> 53.54 | N20: ='SALDO ATUAL'!$G27*'SALDO ATUAL'!$L27 -> 53.54 | O20: =IF(L20>=I20,"OK","COMPRAR") -> OK | P20: =IF(O20="COMPRAR",I20-L20,0) -> 0
A21: 35 | C21: AH SOFIDERM SUB-SKIN 20ML | D21: PREENCHEDOR | E21: 023 - Mililitro | F21: AESKINS | G21: 1315.82 | H21: 11 | I21: 20 | J21: =SUMIF(ENTRADAS!B:B,A:A,ENTRADAS!F:F) -> 0 | K21: =SUMIF(SAÍDAS!B:B,A:A,SAÍDAS!F:F) -> 0 | L21: =H21+J21-K21 -> 11 | M21: ='SALDO ATUAL'!$G157*'SALDO ATUAL'!$I157 -> 0 | N21: ='SALDO ATUAL'!$G157*'SALDO ATUAL'!$L157 -> 0 | O21: =IF(L21>=I21,"OK","COMPRAR") -> COMPRAR | P21: =IF(O21="COMPRAR",I21-L21,0) -> 9
A22: 36 | C22: ALCOOL 70% 100ML CINORD | D22: SOLUÇÕES | H22: 0 | J22: =SUMIF(ENTRADAS!B:B,A:A,ENTRADAS!F:F) -> 0 | K22: =SUMIF(SAÍDAS!B:B,A:A,SAÍDAS!F:F) -> 0 | L22: =H22+J22-K22 -> 0 | M22: ='SALDO ATUAL'!$G153*'SALDO ATUAL'!$I153 -> 0 | N22: ='SALDO ATUAL'!$G153*'SALDO ATUAL'!$L153 -> 0 | O22: =IF(L22>=I22,"OK","COMPRAR") -> OK | P22: =IF(O22="COMPRAR",I22-L22,0) -> 0
A23: 37 | C23: ALCOOL 70% 100ML RIALCOOL | D23: SOLUÇÕES | H23: 0 | J23: =SUMIF(ENTRADAS!B:B,A:A,ENTRADAS!F:F) -> 0 | K23: =SUMIF(SAÍDAS!B:B,A:A,SAÍDAS!F:F) -> 0 | L23: =H23+J23-K23 -> 0 | M23: ='SALDO ATUAL'!$G263*'SALDO ATUAL'!$I263 -> 0 | N23: ='SALDO ATUAL'!$G263*'SALDO ATUAL'!$L263 -> 0 | O23: =IF(L23>=I23,"OK","COMPRAR") -> OK | P23: =IF(O23="COMPRAR",I23-L23,0) -> 0
A24: 38 | C24: ALCOOL 70% SEPTPRO 70 | D24: INSUMOS | E24: 023 - Mililitro | F24: SEPTPRO | H24: 5 | I24: 5 | J24: =SUMIF(ENTRADAS!B:B,A:A,ENTRADAS!F:F) -> 15 | K24: =SUMIF(SAÍDAS!B:B,A:A,SAÍDAS!F:F) -> 7 | L24: =H24+J24-K24 -> 13 | M24: ='SALDO ATUAL'!$G100*'SALDO ATUAL'!$I100 -> 0 | N24: ='SALDO ATUAL'!$G100*'SALDO ATUAL'!$L100 -> 0 | O24: =IF(L24>=I24,"OK","COMPRAR") -> OK | P24: =IF(O24="COMPRAR",I24-L24,0) -> 0
A25: 39 | C25: ALCOOL ISOPROPÍLICO 1 LITRO CINORD | D25: SOLUÇÕES | E25: 013 - Frasco | F25: CINORD | G25: 45.5 | H25: 1 | I25: 1 | J25: =SUMIF(ENTRADAS!B:B,A:A,ENTRADAS!F:F) -> 0 | K25: =SUMIF(SAÍDAS!B:B,A:A,SAÍDAS!F:F) -> 0 | L25: =H25+J25-K25 -> 1 | M25: ='SALDO ATUAL'!$G264*'SALDO ATUAL'!$I264 -> 0 | N25: ='SALDO ATUAL'!$G264*'SALDO ATUAL'!$L264 -> 0 | O25: =IF(L25>=I25,"OK","COMPRAR") -> OK | P25: =IF(O25="COMPRAR",I25-L25,0) -> 0
A26: 40 | C26: ALGODÃO QUADRADINHO SUSSEX | D26: MATERIAIS DESCARTÁVEIS E APOIO | E26: 043 - Pacote | F26: SUSSEX | G26: 8.65 | H26: 1 | I26: 2 | J26: =SUMIF(ENTRADAS!B:B,A:A,ENTRADAS!F:F) -> 5 | K26: =SUMIF(SAÍDAS!B:B,A:A,SAÍDAS!F:F) -> 3 | L26: =H26+J26-K26 -> 3 | M26: ='SALDO ATUAL'!$G152*'SALDO ATUAL'!$I152 -> 0 | N26: ='SALDO ATUAL'!$G152*'SALDO ATUAL'!$L152 -> 0 | O26: =IF(L26>=I26,"OK","COMPRAR") -> OK | P26: =IF(O26="COMPRAR",I26-L26,0) -> 0
A27: 41 | C27: ALLEGRA | D27: MEDICAMENTOS | E27: 008 - Comprimido | F27: SANOFI | G27: 53.54 | H27: 1 | I27: 1 | J27: =SUMIF(ENTRADAS!B:B,A:A,ENTRADAS!F:F) -> 0 | K27: =SUMIF(SAÍDAS!B:B,A:A,SAÍDAS!F:F) -> 0 | L27: =H27+J27-K27 -> 1 | M27: ='SALDO ATUAL'!$G148*'SALDO ATUAL'!$I148 -> 0 | N27: ='SALDO ATUAL'!$G148*'SALDO ATUAL'!$L148 -> 0 | O27: =IF(L27>=I27,"OK","COMPRAR") -> OK | P27: =IF(O27="COMPRAR",I27-L27,0) -> 0
A28: 42 | C28: ANESTÉSICO MANIPULADO TETRA E LIDO DERMOFIT | D28: ANESTÉSICO | H28: 0 | J28: =SUMIF(ENTRADAS!B:B,A:A,ENTRADAS!F:F) -> 0 | K28: =SUMIF(SAÍDAS!B:B,A:A,SAÍDAS!F:F) -> 0 | L28: =H28+J28-K28 -> 0 | M28: ='SALDO ATUAL'!$G291*'SALDO ATUAL'!$I291 -> 41.4 | N28: ='SALDO ATUAL'!$G291*'SALDO ATUAL'!$L291 -> 41.4 | O28: =IF(L28>=I28,"OK","COMPRAR") -> OK | P28: =IF(O28="COMPRAR",I28-L28,0) -> 0
A29: 43 | C29: ANESTÉSICO MANIPULADO TETRA E LIDO FARMA ASSIST | D29: ANESTÉSICO | E29: 018 - Grama | F29: FARMA ASSIST | G29: 90.37 | H29: 4 | I29: 2 | J29: =SUMIF(ENTRADAS!B:B,A:A,ENTRADAS!F:F) -> 0 | K29: =SUMIF(SAÍDAS!B:B,A:A,SAÍDAS!F:F) -> 2 | L29: =H29+J29-K29 -> 2 | M29: ='SALDO ATUAL'!$G293*'SALDO ATUAL'!$I293 -> 0 | N29: ='SALDO ATUAL'!$G293*'SALDO ATUAL'!$L293 -> 0 | O29: =IF(L29>=I29,"OK","COMPRAR") -> OK | P29: =IF(O29="COMPRAR",I29-L29,0) -> 0
A30: 44 | C30: APARELHO DE BARBEAR BIC | D30: MATERIAIS DESCARTÁVEIS E APOIO | H30: 0 | J30: =SUMIF(ENTRADAS!B:B,A:A,ENTRADAS!F:F) -> 0 | K30: =SUMIF(SAÍDAS!B:B,A:A,SAÍDAS!F:F) -> 0 | L30: =H30+J30-K30 -> 0 | M30: ='SALDO ATUAL'!$G186*'SALDO ATUAL'!$I186 -> 3425 | N30: ='SALDO ATUAL'!$G186*'SALDO ATUAL'!$L186 -> 7398 | O30: =IF(L30>=I30,"OK","COMPRAR") -> OK | P30: =IF(O30="COMPRAR",I30-L30,0) -> 0
A31: 46 | C31: ATIVO HAIR COCKTAIL | D31: ATIVOS | J31: =SUMIF(ENTRADAS!B:B,A:A,ENTRADAS!F:F) -> 0 | K31: =SUMIF(SAÍDAS!B:B,A:A,SAÍDAS!F:F) -> 0 | L31: =H31+J31-K31 -> 0 | M31: ='SALDO ATUAL'!$G165*'SALDO ATUAL'!$I165 -> 0 | N31: ='SALDO ATUAL'!$G165*'SALDO ATUAL'!$L165 -> 0 | O31: =IF(L31>=I31,"OK","COMPRAR") -> OK | P31: =IF(O31="COMPRAR",I31-L31,0) -> 0
A32: 48 | C32: AVENTAL DESCARTÁVEL PRETO | D32: MATERIAIS DESCARTÁVEIS E APOIO | H32: 1 | J32: =SUMIF(ENTRADAS!B:B,A:A,ENTRADAS!F:F) -> 0 | K32: =SUMIF(SAÍDAS!B:B,A:A,SAÍDAS!F:F) -> 0 | L32: =H32+J32-K32 -> 1 | M32: ='SALDO ATUAL'!$G221*'SALDO ATUAL'!$I221 -> 0 | N32: ='SALDO ATUAL'!$G221*'SALDO ATUAL'!$L221 -> 0 | O32: =IF(L32>=I32,"OK","COMPRAR") -> OK | P32: =IF(O32="COMPRAR",I32-L32,0) -> 0
A33: 49 | C33: BABADOR | D33: MATERIAIS DESCARTÁVEIS E APOIO | E33: 036 - Unidade | F33: SSPLUS | G33: 21.05 | H33: 4 | I33: 2 | J33: =SUMIF(ENTRADAS!B:B,A:A,ENTRADAS!F:F) -> 0 | K33: =SUMIF(SAÍDAS!B:B,A:A,SAÍDAS!F:F) -> 1 | L33: =H33+J33-K33 -> 3 | M33: ='SALDO ATUAL'!$G155*'SALDO ATUAL'!$I155 -> 0 | N33: ='SALDO ATUAL'!$G155*'SALDO ATUAL'!$L155 -> 0 | O33: =IF(L33>=I33,"OK","COMPRAR") -> OK | P33: =IF(O33="COMPRAR",I33-L33,0) -> 0
A34: 50 | C34: BÁLSAMO DE LIMPEZA FACIAL OLERA | D34: DERMOCOSMÉTICO E COSMÉTICO | E34: 013 - Frasco | F34: OLERA | G34: 127 | H34: 35 | I34: 10 | J34: =SUMIF(ENTRADAS!B:B,A:A,ENTRADAS!F:F) -> 0 | K34: =SUMIF(SAÍDAS!B:B,A:A,SAÍDAS!F:F) -> 22 | L34: =H34+J34-K34 -> 13 | M34: ='SALDO ATUAL'!$G47*'SALDO ATUAL'!$I47 -> 15.65 | N34: ='SALDO ATUAL'!$G47*'SALDO ATUAL'!$L47 -> 25.04 | O34: =IF(L34>=I34,"OK","COMPRAR") -> OK | P34: =IF(O34="COMPRAR",I34-L34,0) -> 0
A35: 51 | C35: BETA CALM MÁSCARA PÓS PROCEDIMENTO ADCOS | D35: DERMOCOSMÉTICO E COSMÉTICO | E35: 018 - Grama | F35: ADCOS | G35: 117.18 | H35: 1 | I35: 1 | J35: =SUMIF(ENTRADAS!B:B,A:A,ENTRADAS!F:F) -> 0 | K35: =SUMIF(SAÍDAS!B:B,A:A,SAÍDAS!F:F) -> 1 | L35: =H35+J35-K35 -> 0 | M35: ='SALDO ATUAL'!$G46*'SALDO ATUAL'!$I46 -> 15.65 | N35: ='SALDO ATUAL'!$G46*'SALDO ATUAL'!$L46 -> 21.91 | O35: =IF(L35>=I35,"OK","COMPRAR") -> COMPRAR | P35: =IF(O35="COMPRAR",I35-L35,0) -> 1
A36: 52 | C36: BICARBONATO DE SÓDIO EM PÓ NEEDS | D36: INSUMOS | E36: 0 | F36: 0 | G36: 0 | H36: 0 | I36: 0 | J36: =SUMIF(ENTRADAS!B:B,A:A,ENTRADAS!F:F) -> 0 | K36: =SUMIF(SAÍDAS!B:B,A:A,SAÍDAS!F:F) -> 0 | L36: =H36+J36-K36 -> 0 | M36: ='SALDO ATUAL'!$G95*'SALDO ATUAL'!$I95 -> 0 | N36: ='SALDO ATUAL'!$G95*'SALDO ATUAL'!$L95 -> 0 | O36: =IF(L36>=I36,"OK","COMPRAR") -> OK | P36: =IF(O36="COMPRAR",I36-L36,0) -> 0
A37: 53 | C37: BICARBONATO DE SÓDIO SAMTEC | D37: SOLUÇÕES | E37: 0 | F37: 0 | G37: 0 | H37: 0 | I37: 0 | J37: =SUMIF(ENTRADAS!B:B,A:A,ENTRADAS!F:F) -> 0 | K37: =SUMIF(SAÍDAS!B:B,A:A,SAÍDAS!F:F) -> 0 | L37: =H37+J37-K37 -> 0 | M37: ='SALDO ATUAL'!$G267*'SALDO ATUAL'!$I267 -> 0 | N37: ='SALDO ATUAL'!$G267*'SALDO ATUAL'!$L267 -> 0 | O37: =IF(L37>=I37,"OK","COMPRAR") -> OK | P37: =IF(O37="COMPRAR",I37-L37,0) -> 0
A38: 54 | C38: BIOESTIMULADOR DIAMOND | D38: BIOESTIMULADORES | E38: 0 | F38: 0 | G38: 0 | H38: 0 | I38: 0 | J38: =SUMIF(ENTRADAS!B:B,A:A,ENTRADAS!F:F) -> 0 | K38: =SUMIF(SAÍDAS!B:B,A:A,SAÍDAS!F:F) -> 0 | L38: =H38+J38-K38 -> 0 | M38: ='SALDO ATUAL'!$G199*'SALDO ATUAL'!$I199 -> 0 | N38: ='SALDO ATUAL'!$G199*'SALDO ATUAL'!$L199 -> 0 | O38: =IF(L38>=I38,"OK","COMPRAR") -> OK | P38: =IF(O38="COMPRAR",I38-L38,0) -> 0
A39: 55 | C39: BIOESTIMULADOR ELLEVA 210MG RENNOVA | D39: BIOESTIMULADORES | E39: 0 | F39: 0 | G39: 0 | H39: 0 | I39: 0 | J39: =SUMIF(ENTRADAS!B:B,A:A,ENTRADAS!F:F) -> 0 | K39: =SUMIF(SAÍDAS!B:B,A:A,SAÍDAS!F:F) -> 0 | L39: =H39+J39-K39 -> 0 | M39: ='SALDO ATUAL'!$G145*'SALDO ATUAL'!$I145 -> 0 | N39: ='SALDO ATUAL'!$G145*'SALDO ATUAL'!$L145 -> 0 | O39: =IF(L39>=I39,"OK","COMPRAR") -> OK | P39: =IF(O39="COMPRAR",I39-L39,0) -> 0
A40: 56 | C40: BIOESTIMULADOR ELLEVA X RENNOVA | D40: BIOESTIMULADORES | E40: 0 | F40: 0 | G40: 0 | H40: 0 | I40: 0 | J40: =SUMIF(ENTRADAS!B:B,A:A,ENTRADAS!F:F) -> 0 | K40: =SUMIF(SAÍDAS!B:B,A:A,SAÍDAS!F:F) -> 0 | L40: =H40+J40-K40 -> 0 | M40: ='SALDO ATUAL'!$G146*'SALDO ATUAL'!$I146 -> 0 | N40: ='SALDO ATUAL'!$G146*'SALDO ATUAL'!$L146 -> 0 | O40: =IF(L40>=I40,"OK","COMPRAR") -> OK | P40: =IF(O40="COMPRAR",I40-L40,0) -> 0
...

Sheet ENTRADAS
A1: ENTRADA
A2: DATA | B2: CÓDIGO | C2: NOME DO PRODUTO | D2: CATEGORIA | E2: UNIDADE | F2: QTD COMPRADA
A3: 46076 | B3: 237 | C3: =IFERROR(VLOOKUP(B:B,'SALDO ATUAL'!$A$3:$E$505,3,0),"") -> EXO OX HAIR SKYMEDIC | D3: =IFERROR(VLOOKUP(B:B,'SALDO ATUAL'!$A$3:$E$505,4,0),"") -> ATIVOS | F3: 1
A4: 46076 | B4: 123 | C4: =IFERROR(VLOOKUP(B:B,'SALDO ATUAL'!$A$3:$E$505,3,0),"") -> EXO OX REGENERATIVE/POWER SKYMEDIC | D4: =IFERROR(VLOOKUP(B:B,'SALDO ATUAL'!$A$3:$E$505,4,0),"") -> ATIVOS | F4: 1
A5: 46076 | B5: 236 | C5: =IFERROR(VLOOKUP(B:B,'SALDO ATUAL'!$A$3:$E$505,3,0),"") -> MESO OX ENZYMES COLAGENASE SKYMEDIC | D5: =IFERROR(VLOOKUP(B:B,'SALDO ATUAL'!$A$3:$E$505,4,0),"") -> ATIVOS | F5: 1
A6: 46076 | B6: 238 | C6: =IFERROR(VLOOKUP(B:B,'SALDO ATUAL'!$A$3:$E$505,3,0),"") -> MESO OX HYBRID SKYMEDIC | D6: =IFERROR(VLOOKUP(B:B,'SALDO ATUAL'!$A$3:$E$505,4,0),"") -> ATIVOS | F6: 1
A7: 46076 | B7: 241 | C7: =IFERROR(VLOOKUP(B:B,'SALDO ATUAL'!$A$3:$E$505,3,0),"") -> MESO OX PPC SKYMEDIC | D7: =IFERROR(VLOOKUP(B:B,'SALDO ATUAL'!$A$3:$E$505,4,0),"") -> ATIVOS | F7: 1
A8: 46083 | B8: 359 | C8: =IFERROR(VLOOKUP(B:B,'SALDO ATUAL'!$A$3:$E$505,3,0),"") -> NADH (PÓ LIOFILIZADO) OPTIMUS | D8: =IFERROR(VLOOKUP(B:B,'SALDO ATUAL'!$A$3:$E$505,4,0),"") -> ATIVOS | E8: =IFERROR(VLOOKUP(B:B,'SALDO ATUAL'!$A$3:$E$505,5,0),"") -> 001- Ampola | F8: 3
A9: 46083 | B9: 379 | C9: =IFERROR(VLOOKUP(B:B,'SALDO ATUAL'!$A$3:$E$505,3,0),"") -> COENZIMA Q10 OPTIMUS | D9: =IFERROR(VLOOKUP(B:B,'SALDO ATUAL'!$A$3:$E$505,4,0),"") -> MANIPULADOS | E9: =IFERROR(VLOOKUP(B:B,'SALDO ATUAL'!$A$3:$E$505,5,0),"") -> 036- Unidade | F9: 3
A10: 46083 | B10: 80 | C10: =IFERROR(VLOOKUP(B:B,'SALDO ATUAL'!$A$3:$E$505,3,0),"") -> CLORETO DE MAGNESIO OPTMUS | D10: =IFERROR(VLOOKUP(B:B,'SALDO ATUAL'!$A$3:$E$505,4,0),"") -> ATIVOS | E10: =IFERROR(VLOOKUP(B:B,'SALDO ATUAL'!$A$3:$E$505,5,0),"") -> 001- Ampola | F10: 6
A11: 46083 | B11: 1 | C11: =IFERROR(VLOOKUP(B:B,'SALDO ATUAL'!$A$3:$E$505,3,0),"") -> AC. ALFA LIPOICO OPTMUS | D11: =IFERROR(VLOOKUP(B:B,'SALDO ATUAL'!$A$3:$E$505,4,0),"") -> ATIVOS | E11: =IFERROR(VLOOKUP(B:B,'SALDO ATUAL'!$A$3:$E$505,5,0),"") -> 001 - Ampola | F11: 6
A12: 46083 | B12: 336 | C12: =IFERROR(VLOOKUP(B:B,'SALDO ATUAL'!$A$3:$E$505,3,0),"") -> VITAMINA C OPTIMUS | D12: =IFERROR(VLOOKUP(B:B,'SALDO ATUAL'!$A$3:$E$505,4,0),"") -> ATIVOS | E12: =IFERROR(VLOOKUP(B:B,'SALDO ATUAL'!$A$3:$E$505,5,0),"") -> 001- Ampola | F12: 6
A13: 46083 | B13: 284 | C13: =IFERROR(VLOOKUP(B:B,'SALDO ATUAL'!$A$3:$E$505,3,0),"") -> RESVERASROL OPTIMUS | D13: =IFERROR(VLOOKUP(B:B,'SALDO ATUAL'!$A$3:$E$505,4,0),"") -> ATIVOS | E13: =IFERROR(VLOOKUP(B:B,'SALDO ATUAL'!$A$3:$E$505,5,0),"") -> 001- Ampola | F13: 6
A14: 46083 | B14: 203 | C14: =IFERROR(VLOOKUP(B:B,'SALDO ATUAL'!$A$3:$E$505,3,0),"") -> L GLUTATIONA OPTMUS | D14: =IFERROR(VLOOKUP(B:B,'SALDO ATUAL'!$A$3:$E$505,4,0),"") -> ATIVOS | E14: =IFERROR(VLOOKUP(B:B,'SALDO ATUAL'!$A$3:$E$505,5,0),"") -> 001- Ampola | F14: 6
A15: 46091 | B15: 285 | C15: =IFERROR(VLOOKUP(B:B,'SALDO ATUAL'!$A$3:$E$505,3,0),"") -> ROLO PARA ESTERILIZAÇÃO | D15: =IFERROR(VLOOKUP(B:B,'SALDO ATUAL'!$A$3:$E$505,4,0),"") -> MATERIAIS DESCARTÁVEIS E APOIO | E15: =IFERROR(VLOOKUP(B:B,'SALDO ATUAL'!$A$3:$E$505,5,0),"") -> 036- Unidade | F15: 2
A16: 46091 | B16: 381 | C16: =IFERROR(VLOOKUP(B:B,'SALDO ATUAL'!$A$3:$E$505,3,0),"") -> TESTE INDICADOR QUÍMICO | D16: =IFERROR(VLOOKUP(B:B,'SALDO ATUAL'!$A$3:$E$505,4,0),"") -> ESTERELIZAÇÃO | E16: =IFERROR(VLOOKUP(B:B,'SALDO ATUAL'!$A$3:$E$505,5,0),"") -> 036- Unidade | F16: 2
A17: 46091 | B17: 323 | C17: =IFERROR(VLOOKUP(B:B,'SALDO ATUAL'!$A$3:$E$505,3,0),"") -> TESTE INDICADOR BIOLÓGICO | D17: =IFERROR(VLOOKUP(B:B,'SALDO ATUAL'!$A$3:$E$505,4,0),"") -> ESTERELIZAÇÃO | E17: =IFERROR(VLOOKUP(B:B,'SALDO ATUAL'!$A$3:$E$505,5,0),"") -> 036- Unidade | F17: 6
A18: 46091 | B18: 11 | C18: =IFERROR(VLOOKUP(B:B,'SALDO ATUAL'!$A$3:$E$505,3,0),"") -> ÁGUA TERMAL MINERAUX | D18: =IFERROR(VLOOKUP(B:B,'SALDO ATUAL'!$A$3:$E$505,4,0),"") -> DERMOCOSMÉTICO E COSMÉTICO | E18: =IFERROR(VLOOKUP(B:B,'SALDO ATUAL'!$A$3:$E$505,5,0),"") -> 013 - Frasco | F18: 1
A19: 46091 | B19: 10 | C19: =IFERROR(VLOOKUP(B:B,'SALDO ATUAL'!$A$3:$E$505,3,0),"") | D19: =IFERROR(VLOOKUP(B:B,'SALDO ATUAL'!$A$3:$E$505,4,0),"") | E19: =IFERROR(VLOOKUP(B:B,'SALDO ATUAL'!$A$3:$E$505,5,0),"") | F19: 1
... A52: 46098 | B52: 96 | C52: =IFERROR(VLOOKUP(B:B,'SALDO ATUAL'!$A$3:$E$505,3,0),"") -> CREME CALMANTE NIACINAMIDA INC BEAUTY | D52: =IFERROR(VLOOKUP(B:B,'SALDO ATUAL'!$A$3:$E$505,4,0),"") -> MANIPULADOS | E52: =IFERROR(VLOOKUP(B:B,'SALDO ATUAL'!$A$3:$E$505,5,0),"") -> 018 - Grama | F52: 15
A53: 46098 | B53: 98 | C53: =IFERROR(VLOOKUP(B:B,'SALDO ATUAL'!$A$3:$E$505,3,0),"") -> CREME COM NUTRI OMEGA + ASSOCIAÇÕES INC BEAUTY | D53: =IFERROR(VLOOKUP(B:B,'SALDO ATUAL'!$A$3:$E$999,4,0),"") -> MANIPULADOS | E53: =IFERROR(VLOOKUP(B:B,'SALDO ATUAL'!$A$3:$E$505,5,0),"") -> 018 - Grama | F53: 1
A54: 46098 | B54: 328 | C54: =IFERROR(VLOOKUP(B:B,'SALDO ATUAL'!$A$3:$E$505,3,0),"") -> TOXINA BOTULÍNICA DYSPORT 300U | D54: =IFERROR(VLOOKUP(B:B,'SALDO ATUAL'!$A$3:$E$999,4,0),"") -> TOXINA | E54: =IFERROR(VLOOKUP(B:B,'SALDO ATUAL'!$A$3:$E$505,5,0),"") -> 037 - Unidade Internacional | F54: 3
A55: 46100 | B55: 399 | C55: =IFERROR(VLOOKUP(B:B,'SALDO ATUAL'!$A$3:$E$505,3,0),"") | D55: =IFERROR(VLOOKUP(B:B,'SALDO ATUAL'!$A$3:$E$999,4,0),"") | E55: =IFERROR(VLOOKUP(B:B,'SALDO ATUAL'!$A$3:$E$505,5,0),"") | F55: 1
A56: 46100 | B56: 400 | C56: =IFERROR(VLOOKUP(B:B,'SALDO ATUAL'!$A$3:$E$505,3,0),"") | D56: =IFERROR(VLOOKUP(B:B,'SALDO ATUAL'!$A$3:$E$999,4,0),"") | E56: =IFERROR(VLOOKUP(B:B,'SALDO ATUAL'!$A$3:$E$505,5,0),"") | F56: 1
A57: 46100 | B57: 401 | C57: =IFERROR(VLOOKUP(B:B,'SALDO ATUAL'!$A$3:$E$505,3,0),"") | D57: =IFERROR(VLOOKUP(B:B,'SALDO ATUAL'!$A$3:$E$999,4,0),"") | E57: =IFERROR(VLOOKUP(B:B,'SALDO ATUAL'!$A$3:$E$505,5,0),"") | F57: 1
A58: 46100 | B58: 402 | C58: =IFERROR(VLOOKUP(B:B,'SALDO ATUAL'!$A$3:$E$505,3,0),"") | D58: =IFERROR(VLOOKUP(B:B,'SALDO ATUAL'!$A$3:$E$999,4,0),"") | E58: =IFERROR(VLOOKUP(B:B,'SALDO ATUAL'!$A$3:$E$505,5,0),"") | F58: 1
A59: 46100 | B59: 404 | C59: =IFERROR(VLOOKUP(B:B,'SALDO ATUAL'!$A$3:$E$505,3,0),"") | D59: =IFERROR(VLOOKUP(B:B,'SALDO ATUAL'!$A$3:$E$999,4,0),"") | E59: =IFERROR(VLOOKUP(B:B,'SALDO ATUAL'!$A$3:$E$505,5,0),"") | F59: 1
A60: 46100 | B60: 405 | C60: =IFERROR(VLOOKUP(B:B,'SALDO ATUAL'!$A$3:$E$505,3,0),"") | D60: =IFERROR(VLOOKUP(B:B,'SALDO ATUAL'!$A$3:$E$999,4,0),"") | E60: =IFERROR(VLOOKUP(B:B,'SALDO ATUAL'!$A$3:$E$505,5,0),"") | F60: 1
A61: 46100 | B61: 406 | C61: =IFERROR(VLOOKUP(B:B,'SALDO ATUAL'!$A$3:$E$505,3,0),"") -> CANULADE GUEDEL 4 - CARRINHO DE PARADA | D61: =IFERROR(VLOOKUP(B:B,'SALDO ATUAL'!$A$3:$E$999,4,0),"") -> ITEM OPERACIONAL | E61: =IFERROR(VLOOKUP(B:B,'SALDO ATUAL'!$A$3:$E$505,5,0),"") -> 036- Unidade | F61: 1
A62: 46100 | B62: 407 | C62: =IFERROR(VLOOKUP(B:B,'SALDO ATUAL'!$A$3:$E$505,3,0),"") -> CANULA DE GUEDEL 5 - CARRINHO DE PARADA | D62: =IFERROR(VLOOKUP(B:B,'SALDO ATUAL'!$A$3:$E$999,4,0),"") -> ITEM OPERACIONAL | E62: =IFERROR(VLOOKUP(B:B,'SALDO ATUAL'!$A$3:$E$505,5,0),"") -> 036- Unidade | F62: 1
A63: 46100 | B63: 408 | C63: =IFERROR(VLOOKUP(B:B,'SALDO ATUAL'!$A$3:$E$505,3,0),"") -> MASCARA ALTA CONCENTRAÇÃO - CARRINHO DE PARADA | D63: =IFERROR(VLOOKUP(B:B,'SALDO ATUAL'!$A$3:$E$999,4,0),"") -> ITEM OPERACIONAL | E63: =IFERROR(VLOOKUP(B:B,'SALDO ATUAL'!$A$3:$E$505,5,0),"") -> 036- Unidade | F63: 1
A64: 46100 | B64: 409 | C64: =IFERROR(VLOOKUP(B:B,'SALDO ATUAL'!$A$3:$E$505,3,0),"") -> MALETA NYLON - CARRINHO DE PARADA | D64: =IFERROR(VLOOKUP(B:B,'SALDO ATUAL'!$A$3:$E$999,4,0),"") -> ITEM OPERACIONAL | E64: =IFERROR(VLOOKUP(B:B,'SALDO ATUAL'!$A$3:$E$505,5,0),"") -> 036- Unidade | F64: 1
A65: 46100 | B65: 410 | C65: =IFERROR(VLOOKUP(B:B,'SALDO ATUAL'!$A$3:$E$505,3,0),"") -> ALCOOL 70% NOVA VIDA | D65: =IFERROR(VLOOKUP(B:B,'SALDO ATUAL'!$A$3:$E$999,4,0),"") -> SOLUÇÕES | E65: =IFERROR(VLOOKUP(B:B,'SALDO ATUAL'!$A$3:$E$505,5,0),"") -> 019 - Litro | F65: 3
A66: 46100 | B66: 411 | C66: =IFERROR(VLOOKUP(B:B,'SALDO ATUAL'!$A$3:$E$505,3,0),"") -> AROMATIZADOR DE AR | D66: =IFERROR(VLOOKUP(B:B,'SALDO ATUAL'!$A$3:$E$999,4,0),"") -> ITEM OPERACIONAL | E66: =IFERROR(VLOOKUP(B:B,'SALDO ATUAL'!$A$3:$E$505,5,0),"") -> 023 - Mililitro | F66: 2
A67: 46100 | B67: 412 | C67: =IFERROR(VLOOKUP(B:B,'SALDO ATUAL'!$A$3:$E$505,3,0),"") -> AGUA OXIGENADA 30 VOL ITALLIAN | D67: =IFERROR(VLOOKUP(B:B,'SALDO ATUAL'!$A$3:$E$999,4,0),"") -> SOLUÇÕES | E67: =IFERROR(VLOOKUP(B:B,'SALDO ATUAL'!$A$3:$E$505,5,0),"") -> 019 - Litro | F67: 1
A68: 46100 | B68: 118 | C68: =IFERROR(VLOOKUP(B:B,'SALDO ATUAL'!$A$3:$E$505,3,0),"") -> ELETRODO DENSITY | D68: =IFERROR(VLOOKUP(B:B,'SALDO ATUAL'!$A$3:$E$999,4,0),"") -> MATERIAIS DESCARTÁVEIS E APOIO | E68: =IFERROR(VLOOKUP(B:B,'SALDO ATUAL'!$A$3:$E$505,5,0),"") -> 036 - Unidade | F68: 10
A69: 46100 | B69: 267 | C69: =IFERROR(VLOOKUP(B:B,'SALDO ATUAL'!$A$3:$E$505,3,0),"") -> PONTEIRA E TIP DENSITY | D69: =IFERROR(VLOOKUP(B:B,'SALDO ATUAL'!$A$3:$E$999,4,0),"") -> PONTEIRA | E69: =IFERROR(VLOOKUP(B:B,'SALDO ATUAL'!$A$3:$E$505,5,0),"") -> 036-Unidade | F69: 6
A70: 46100 | B70: 184 | C70: =IFERROR(VLOOKUP(B:B,'SALDO ATUAL'!$A$3:$E$505,3,0),"") -> FLUIDO DE ACOPLAMENTO DENSITY | D70: =IFERROR(VLOOKUP(B:B,'SALDO ATUAL'!$A$3:$E$999,4,0),"") -> MATERIAIS DESCARTÁVEIS E APOIO | E70: =IFERROR(VLOOKUP(B:B,'SALDO ATUAL'!$A$3:$E$505,5,0),"") -> 0 | F70: 6
A71: 46100 | B71: 101 | C71: =IFERROR(VLOOKUP(B:B,'SALDO ATUAL'!$A$3:$E$505,3,0),"") -> CRIOGENIO DENSITY | D71: =IFERROR(VLOOKUP(B:B,'SALDO ATUAL'!$A$3:$E$999,4,0),"") -> MATERIAIS DESCARTÁVEIS E APOIO | E71: =IFERROR(VLOOKUP(B:B,'SALDO ATUAL'!$A$3:$E$505,5,0),"") -> 018 - Grama | F71: 2
A72: 46100 | B72: 413 | C72: =IFERROR(VLOOKUP(B:B,'SALDO ATUAL'!$A$3:$E$505,3,0),"") -> SERINGA PARA INSULINA 1 ML - MEDIX | D72: =IFERROR(VLOOKUP(B:B,'SALDO ATUAL'!$A$3:$E$999,4,0),"") -> MATERIAIS DESCARTÁVEIS E APOIO | E72: =IFERROR(VLOOKUP(B:B,'SALDO ATUAL'!$A$3:$E$505,5,0),"") -> 036- Unidade | F72: 100
...

Sheet SAÍDAS
A1: 89
A2: DATA | B2: CÓD | C2: NOME DO PRODUTO | D2: CATEGORIA | E2: UNIDADE | F2: QTD UTILIZADA
A3: 46076 | B3: 268 | C3: =IFERROR(VLOOKUP(B:B,'SALDO ATUAL'!$A$3:$E$238,3,0),"") -> PONTEIRA F TIP DENSITY | D3: =IFERROR(VLOOKUP(B:B,'SALDO ATUAL'!$A$3:$E$238,4,0),"") -> PONTEIRA | E3: =IFERROR(VLOOKUP(B:B,'SALDO ATUAL'!$A$3:$E$238,5,0),"") -> 036-Unidade | F3: 1
A4: 46076 | B4: 11 | C4: =IFERROR(VLOOKUP(B:B,'SALDO ATUAL'!$A$3:$E$238,3,0),"") -> ÁGUA TERMAL MINERAUX | D4: =IFERROR(VLOOKUP(B:B,'SALDO ATUAL'!$A$3:$E$238,4,0),"") -> DERMOCOSMÉTICO E COSMÉTICO | E4: =IFERROR(VLOOKUP(B:B,'SALDO ATUAL'!$A$3:$E$238,5,0),"") -> 013 - Frasco | F4: 1
A5: 46077 | B5: 98 | C5: =IFERROR(VLOOKUP(B:B,'SALDO ATUAL'!$A$3:$E$506,3,0),"") -> CREME COM NUTRI OMEGA + ASSOCIAÇÕES INC BEAUTY | D5: =IFERROR(VLOOKUP(B:B,'SALDO ATUAL'!$A$3:$E$506,4,0),"") -> MANIPULADOS | E5: =IFERROR(VLOOKUP(B:B,'SALDO ATUAL'!$A$3:$E$506,5,0),"") -> 018 - Grama | F5: 1
A6: 46078 | B6: 83 | C6: =IFERROR(VLOOKUP(B:B,'SALDO ATUAL'!$A$3:$E$238,3,0),"") -> CLOREX AQUOSO 0,2% 100ML RIOHEX | D6: =IFERROR(VLOOKUP(B:B,'SALDO ATUAL'!$A$3:$E$238,4,0),"") -> SOLUÇÕES | E6: =IFERROR(VLOOKUP(B:B,'SALDO ATUAL'!$A$3:$E$238,5,0),"") -> 023 - Mililitro | F6: 3
A7: 46078 | B7: 306 | C7: =IFERROR(VLOOKUP(B:B,'SALDO ATUAL'!$A$3:$E$9999,3,0),"") -> SERINGA ULTRA FINE 0,3ML 0,8x0,30 BD | D7: =IFERROR(VLOOKUP(B:B,'SALDO ATUAL'!$A$3:$E999,4,0),"") -> SERINGA | E7: =IFERROR(VLOOKUP(B:B,'SALDO ATUAL'!$A$3:$E$999,5,0),"") -> 043- Pacotes | F7: 1
A8: 46078 | B8: 38 | C8: =IFERROR(VLOOKUP(B:B,'SALDO ATUAL'!$A$3:$E$9999,3,0),"") -> ALCOOL 70% SEPTPRO 70 | D8: =IFERROR(VLOOKUP(B:B,'SALDO ATUAL'!$A$3:$E1000,4,0),"") -> INSUMOS | E8: =IFERROR(VLOOKUP(B:B,'SALDO ATUAL'!$A$3:$E$999,5,0),"") -> 023 - Mililitro | F8: 3
A9: 46078 | B9: 298 | C9: =IFERROR(VLOOKUP(B:B,'SALDO ATUAL'!$A$3:$E$9999,3,0),"") -> SERINGA 5ML LOCK - ROSCA BD | D9: =IFERROR(VLOOKUP(B:B,'SALDO ATUAL'!$A$3:$E1001,4,0),"") -> SERINGA | E9: =IFERROR(VLOOKUP(B:B,'SALDO ATUAL'!$A$3:$E$999,5,0),"") -> 036- Unidade | F9: 10
A10: 46078 | B10: 201 | C10: =IFERROR(VLOOKUP(B:B,'SALDO ATUAL'!$A$3:$E$9999,3,0),"") -> KIT PONTEIRA HAIR D&D EVO | D10: =IFERROR(VLOOKUP(B:B,'SALDO ATUAL'!$A$3:$E1002,4,0),"") -> PONTEIRA | E10: =IFERROR(VLOOKUP(B:B,'SALDO ATUAL'!$A$3:$E$999,5,0),"") -> 036-Unidades | F10: 5
A11: 46078 | B11: 316 | C11: =IFERROR(VLOOKUP(B:B,'SALDO ATUAL'!$A$3:$E$9999,3,0),"") -> SORO ESTÉRIL 10 ML ISOFARMA | D11: =IFERROR(VLOOKUP(B:B,'SALDO ATUAL'!$A$3:$E1003,4,0),"") -> SOLUÇÕES | E11: =IFERROR(VLOOKUP(B:B,'SALDO ATUAL'!$A$3:$E$999,5,0),"") -> 012- Floconete | F11: 5
A12: 46078 | B12: 89 | C12: =IFERROR(VLOOKUP(B:B,'SALDO ATUAL'!$A$3:$E$9999,3,0),"") -> COMPRESSA GAZE 13 FIOS C/ 500 UNID MEDI HOUSE | D12: =IFERROR(VLOOKUP(B:B,'SALDO ATUAL'!$A$3:$E1004,4,0),"") -> MATERIAIS DESCARTÁVEIS E APOIO | E12: =IFERROR(VLOOKUP(B:B,'SALDO ATUAL'!$A$3:$E$999,5,0),"") -> 036 - Unidade | F12: 1
A13: 46078 | B13: 84 | C13: =IFERROR(VLOOKUP(B:B,'SALDO ATUAL'!$A$3:$E$9999,3,0),"") -> COLETOR PERFUROCORTANTE 3L DESCARPACK | D13: =IFERROR(VLOOKUP(B:B,'SALDO ATUAL'!$A$3:$E1005,4,0),"") -> MATERIAIS DESCARTÁVEIS E APOIO | E13: =IFERROR(VLOOKUP(B:B,'SALDO ATUAL'!$A$3:$E$999,5,0),"") -> 036 - Unidade | F13: 1
A14: 46078 | B14: 50 | C14: =IFERROR(VLOOKUP(B:B,'SALDO ATUAL'!$A$3:$E$9999,3,0),"") -> BÁLSAMO DE LIMPEZA FACIAL OLERA | D14: =IFERROR(VLOOKUP(B:B,'SALDO ATUAL'!$A$3:$E1006,4,0),"") -> DERMOCOSMÉTICO E COSMÉTICO | E14: =IFERROR(VLOOKUP(B:B,'SALDO ATUAL'!$A$3:$E$999,5,0),"") -> 013 - Frasco | F14: 1
A15: 46078 | B15: 83 | C15: =IFERROR(VLOOKUP(B:B,'SALDO ATUAL'!$A$3:$E$9999,3,0),"") -> CLOREX AQUOSO 0,2% 100ML RIOHEX | D15: =IFERROR(VLOOKUP(B:B,'SALDO ATUAL'!$A$3:$E1007,4,0),"") -> SOLUÇÕES | E15: =IFERROR(VLOOKUP(B:B,'SALDO ATUAL'!$A$3:$E$999,5,0),"") -> 023 - Mililitro | F15: 1
A16: 46078 | B16: 218 | C16: =IFERROR(VLOOKUP(B:B,'SALDO ATUAL'!$A$3:$E$9999,3,0),"") -> LUVA P SEM PÓ DESCARPACK | D16: =IFERROR(VLOOKUP(B:B,'SALDO ATUAL'!$A$3:$E1008,4,0),"") -> MATERIAIS DESCARTÁVEIS E APOIO | E16: =IFERROR(VLOOKUP(B:B,'SALDO ATUAL'!$A$3:$E$999,5,0),"") -> 005- Caixa | F16: 1
A17: 46078 | B17: 275 | C17: =IFERROR(VLOOKUP(B:B,'SALDO ATUAL'!$A$3:$E$9999,3,0),"") -> PROFHILO | D17: =IFERROR(VLOOKUP(B:B,'SALDO ATUAL'!$A$3:$E1009,4,0),"") -> BIORREMODULADOR | E17: =IFERROR(VLOOKUP(B:B,'SALDO ATUAL'!$A$3:$E$999,5,0),"") -> 031- Seringa | F17: 6
A18: 46078 | B18: 24 | C18: =IFERROR(VLOOKUP(B:B,'SALDO ATUAL'!$A$3:$E$9999,3,0),"") -> AH BELOTERO BALANCE | D18: =IFERROR(VLOOKUP(B:B,'SALDO ATUAL'!$A$3:$E1010,4,0),"") -> PREENCHEDOR | E18: =IFERROR(VLOOKUP(B:B,'SALDO ATUAL'!$A$3:$E$999,5,0),"") -> 023 - Mililitro | F18: 3
... A273: 46106 | B273: 220 | C273: =IFERROR(VLOOKUP(B:B,'SALDO ATUAL'!$A$3:$E$9999,3,0),"") -> MASCARA ARGILA INC BEAUTY | D273: =IFERROR(VLOOKUP(B:B,'SALDO ATUAL'!$A$3:$E1265,4,0),"") -> MANIPULADOS | E273: =IFERROR(VLOOKUP(B:B,'SALDO ATUAL'!$A$3:$E$999,5,0),"") -> 018 - Grama | F273: 1
A274: 46106 | B274: 25 | C274: =IFERROR(VLOOKUP(B:B,'SALDO ATUAL'!$A$3:$E$9999,3,0),"") -> AH BELOTERO INTENSE | D274: =IFERROR(VLOOKUP(B:B,'SALDO ATUAL'!$A$3:$E1267,4,0),"") -> PREENCHEDOR | E274: =IFERROR(VLOOKUP(B:B,'SALDO ATUAL'!$A$3:$E$999,5,0),"") -> 023 - Mililitro | F274: 4
A275: 46106 | B275: 329 | C275: =IFERROR(VLOOKUP(B:B,'SALDO ATUAL'!$A$3:$E$9999,3,0),"") -> TOXINA BOTULÍNICA XEOMIN 100UI | D275: =IFERROR(VLOOKUP(B:B,'SALDO ATUAL'!$A$3:$E1268,4,0),"") -> TOXINA | E275: =IFERROR(VLOOKUP(B:B,'SALDO ATUAL'!$A$3:$E$999,5,0),"") -> 037 - Unidade Internacional | F275: 1
A276: 46106 | B276: 359 | C276: =IFERROR(VLOOKUP(B:B,'SALDO ATUAL'!$A$3:$E$9999,3,0),"") -> NADH (PÓ LIOFILIZADO) OPTIMUS | D276: =IFERROR(VLOOKUP(B:B,'SALDO ATUAL'!$A$3:$E1269,4,0),"") -> ATIVOS | E276: =IFERROR(VLOOKUP(B:B,'SALDO ATUAL'!$A$3:$E$999,5,0),"") -> 001- Ampola | F276: 1
A277: 46106 | B277: 336 | C277: =IFERROR(VLOOKUP(B:B,'SALDO ATUAL'!$A$3:$E$9999,3,0),"") -> VITAMINA C OPTIMUS | D277: =IFERROR(VLOOKUP(B:B,'SALDO ATUAL'!$A$3:$E1270,4,0),"") -> ATIVOS | E277: =IFERROR(VLOOKUP(B:B,'SALDO ATUAL'!$A$3:$E$999,5,0),"") -> 001- Ampola | F277: 2
A278: 46106 | B278: 322 | C278: =IFERROR(VLOOKUP(B:B,'SALDO ATUAL'!$A$3:$E$9999,3,0),"") -> SULF . DE ZINCO OPTIMUS | D278: =IFERROR(VLOOKUP(B:B,'SALDO ATUAL'!$A$3:$E1271,4,0),"") -> INJETAVEL | E278: =IFERROR(VLOOKUP(B:B,'SALDO ATUAL'!$A$3:$E$999,5,0),"") -> 001 - Ampola | F278: 2
A279: 46106 | B279: 335 | C279: =IFERROR(VLOOKUP(B:B,'SALDO ATUAL'!$A$3:$E$9999,3,0),"") -> VITAMINA B12 OPTIMUS | D279: =IFERROR(VLOOKUP(B:B,'SALDO ATUAL'!$A$3:$E1272,4,0),"") -> ATIVOS | E279: =IFERROR(VLOOKUP(B:B,'SALDO ATUAL'!$A$3:$E$999,5,0),"") -> 001- Ampola | F279: 2
A280: 46106 | B280: 288 | C280: =IFERROR(VLOOKUP(B:B,'SALDO ATUAL'!$A$3:$E$9999,3,0),"") -> SELENIO OPTIMUS | D280: =IFERROR(VLOOKUP(B:B,'SALDO ATUAL'!$A$3:$E1273,4,0),"") -> ATIVOS | E280: =IFERROR(VLOOKUP(B:B,'SALDO ATUAL'!$A$3:$E$999,5,0),"") -> 001- Ampola | F280: 2
A281: 46106 | B281: 324 | C281: =IFERROR(VLOOKUP(B:B,'SALDO ATUAL'!$A$3:$E$9999,3,0),"") -> TIMOMODULINA OPTIMUS | D281: =IFERROR(VLOOKUP(B:B,'SALDO ATUAL'!$A$3:$E1274,4,0),"") -> ATIVOS | E281: =IFERROR(VLOOKUP(B:B,'SALDO ATUAL'!$A$3:$E$999,5,0),"") -> 001 - Ampola | F281: 2
A282: 46106 | B282: 357 | C282: =IFERROR(VLOOKUP(B:B,'SALDO ATUAL'!$A$3:$E$9999,3,0),"") -> SORO EV 250ML | D282: =IFERROR(VLOOKUP(B:B,'SALDO ATUAL'!$A$3:$E1275,4,0),"") -> MATERIAIS DESCARTÁVEIS E APOIO | E282: =IFERROR(VLOOKUP(B:B,'SALDO ATUAL'!$A$3:$E$999,5,0),"") -> 036- Unidade | F282: 2
A283: 46106 | B283: 354 | C283: =IFERROR(VLOOKUP(B:B,'SALDO ATUAL'!$A$3:$E$9999,3,0),"") -> SCALP 23G | D283: =IFERROR(VLOOKUP(B:B,'SALDO ATUAL'!$A$3:$E1276,4,0),"") -> AGULHAS | E283: =IFERROR(VLOOKUP(B:B,'SALDO ATUAL'!$A$3:$E$999,5,0),"") -> 036- Unidade | F283: 2
A284: 46106 | B284: 355 | C284: =IFERROR(VLOOKUP(B:B,'SALDO ATUAL'!$A$3:$E$9999,3,0),"") -> EQUIPO TKL | D284: =IFERROR(VLOOKUP(B:B,'SALDO ATUAL'!$A$3:$E1277,4,0),"") -> MATERIAIS DESCARTÁVEIS E APOIO | E284: =IFERROR(VLOOKUP(B:B,'SALDO ATUAL'!$A$3:$E$999,5,0),"") -> 036- Unidade | F284: 1
A285: 46107 | B285: 84 | C285: =IFERROR(VLOOKUP(B:B,'SALDO ATUAL'!$A$3:$E$9999,3,0),"") -> COLETOR PERFUROCORTANTE 3L DESCARPACK | D285: =IFERROR(VLOOKUP(B:B,'SALDO ATUAL'!$A$3:$E1278,4,0),"") -> MATERIAIS DESCARTÁVEIS E APOIO | E285: =IFERROR(VLOOKUP(B:B,'SALDO ATUAL'!$A$3:$E$999,5,0),"") -> 036 - Unidade | F285: 2
... A320: 46111 | B320: 50 | C320: =IFERROR(VLOOKUP(B:B,'SALDO ATUAL'!$A$3:$E$9999,3,0),"") -> BÁLSAMO DE LIMPEZA FACIAL OLERA | D320: =IFERROR(VLOOKUP(B:B,'SALDO ATUAL'!$A$3:$E1313,4,0),"") -> DERMOCOSMÉTICO E COSMÉTICO | E320: =IFERROR(VLOOKUP(B:B,'SALDO ATUAL'!$A$3:$E$999,5,0),"") -> 013 - Frasco | F320: 1
A321: 46111 | B321: 96 | C321: =IFERROR(VLOOKUP(B:B,'SALDO ATUAL'!$A$3:$E$9999,3,0),"") -> CREME CALMANTE NIACINAMIDA INC BEAUTY | D321: =IFERROR(VLOOKUP(B:B,'SALDO ATUAL'!$A$3:$E794,4,0),"") -> MANIPULADOS | E321: =IFERROR(VLOOKUP(B:B,'SALDO ATUAL'!$A$3:$E$999,5,0),"") -> 018 - Grama | F321: 1
A322: 46112 | B322: 58 | C322: =IFERROR(VLOOKUP(B:B,'SALDO ATUAL'!$A$3:$E$9999,3,0),"") -> BIOESTIMULADOR RADIESSE | D322: =IFERROR(VLOOKUP(B:B,'SALDO ATUAL'!$A$3:$E795,4,0),"") -> BIOESTIMULADORES | E322: =IFERROR(VLOOKUP(B:B,'SALDO ATUAL'!$A$3:$E$999,5,0),"") -> 023 - Mililitro | F322: 1
A323: 46112 | B323: 336 | C323: =IFERROR(VLOOKUP(B:B,'SALDO ATUAL'!$A$3:$E$9999,3,0),"") -> VITAMINA C OPTIMUS | D323: =IFERROR(VLOOKUP(B:B,'SALDO ATUAL'!$A$3:$E796,4,0),"") -> ATIVOS | E323: =IFERROR(VLOOKUP(B:B,'SALDO ATUAL'!$A$3:$E$999,5,0),"") -> 001- Ampola | F323: 1
A324: 46112 | B324: 324 | C324: =IFERROR(VLOOKUP(B:B,'SALDO ATUAL'!$A$3:$E$9999,3,0),"") -> TIMOMODULINA OPTIMUS | D324: =IFERROR(VLOOKUP(B:B,'SALDO ATUAL'!$A$3:$E797,4,0),"") -> ATIVOS | E324: =IFERROR(VLOOKUP(B:B,'SALDO ATUAL'!$A$3:$E$999,5,0),"") -> 001 - Ampola | F324: 1
A325: 46112 | B325: 322 | C325: =IFERROR(VLOOKUP(B:B,'SALDO ATUAL'!$A$3:$E$9999,3,0),"") -> SULF . DE ZINCO OPTIMUS | D325: =IFERROR(VLOOKUP(B:B,'SALDO ATUAL'!$A$3:$E798,4,0),"") -> INJETAVEL | E325: =IFERROR(VLOOKUP(B:B,'SALDO ATUAL'!$A$3:$E$999,5,0),"") -> 001 - Ampola | F325: 1
A326: 46112 | B326: 335 | C326: =IFERROR(VLOOKUP(B:B,'SALDO ATUAL'!$A$3:$E$9999,3,0),"") -> VITAMINA B12 OPTIMUS | D326: =IFERROR(VLOOKUP(B:B,'SALDO ATUAL'!$A$3:$E799,4,0),"") -> ATIVOS | E326: =IFERROR(VLOOKUP(B:B,'SALDO ATUAL'!$A$3:$E$999,5,0),"") -> 001- Ampola | F326: 1
A327: 46112 | B327: 288 | C327: =IFERROR(VLOOKUP(B:B,'SALDO ATUAL'!$A$3:$E$9999,3,0),"") -> SELENIO OPTIMUS | D327: =IFERROR(VLOOKUP(B:B,'SALDO ATUAL'!$A$3:$E800,4,0),"") -> ATIVOS | E327: =IFERROR(VLOOKUP(B:B,'SALDO ATUAL'!$A$3:$E$999,5,0),"") -> 001- Ampola | F327: 1
A328: 46112 | B328: 357 | C328: =IFERROR(VLOOKUP(B:B,'SALDO ATUAL'!$A$3:$E$9999,3,0),"") -> SORO EV 250ML | D328: =IFERROR(VLOOKUP(B:B,'SALDO ATUAL'!$A$3:$E801,4,0),"") -> MATERIAIS DESCARTÁVEIS E APOIO | E328: =IFERROR(VLOOKUP(B:B,'SALDO ATUAL'!$A$3:$E$999,5,0),"") -> 036- Unidade | F328: 1
...

Sheet VALIDADES
A1: CONTROLE DE VALIDADE
A2: CÓD | B2: SITUAÇÃO | C2: NOME DO PRODUTO | D2: CATEGORIA | E2: UNIDADE | F2: FORNECEDOR | G2: LOTE | H2: QTD | I2: VALIDADE | J2: DISPOBILIDADE (DIAS) | L2: =TODAY() -> 46126 | N2: DIAS | O2: LEGENDA | P2: TOTAL DE PRODUTOS
B3: =IFERROR(VLOOKUP(A:A,'SALDO ATUAL'!$A$3:$E$238,2,0),"") | C3: =IFERROR(VLOOKUP(A:A,'SALDO ATUAL'!$A$3:$E$238,3,0),"") | D3: =IFERROR(VLOOKUP(A:A,'SALDO ATUAL'!$A$3:$E$238,4,0),"") | E3: =IFERROR(VLOOKUP(A:A,'SALDO ATUAL'!$A$3:$E$238,5,0),"") | F3: =IFERROR(VLOOKUP(A:A,'SALDO ATUAL'!$A$2:$F$238,6,0),"") | J3: =VALIDADES!$I3-$L$2 -> -46126 | N3: 30 | O3: VERMELHO | P3: =COUNTIF(J:J,"<="&N3) -> 178
B4: =IFERROR(VLOOKUP(A:A,'SALDO ATUAL'!$A$3:$E$238,2,0),"") | C4: =IFERROR(VLOOKUP(A:A,'SALDO ATUAL'!$A$3:$E$238,3,0),"") | D4: =IFERROR(VLOOKUP(A:A,'SALDO ATUAL'!$A$3:$E$238,4,0),"") | E4: =IFERROR(VLOOKUP(A:A,'SALDO ATUAL'!$A$3:$E$238,5,0),"") | F4: =IFERROR(VLOOKUP(A:A,'SALDO ATUAL'!$A$2:$F$238,6,0),"") | J4: =VALIDADES!$I4-$L$2 -> -46126 | N4: 60 | O4: LARANJA | P4: =COUNTIFS(J:J,">"&N3,J:J,"<="&N4) -> 0
B5: =IFERROR(VLOOKUP(A:A,'SALDO ATUAL'!$A$3:$E$238,2,0),"") | C5: =IFERROR(VLOOKUP(A:A,'SALDO ATUAL'!$A$3:$E$238,3,0),"") | D5: =IFERROR(VLOOKUP(A:A,'SALDO ATUAL'!$A$3:$E$238,4,0),"") | E5: =IFERROR(VLOOKUP(A:A,'SALDO ATUAL'!$A$3:$E$238,5,0),"") | F5: =IFERROR(VLOOKUP(A:A,'SALDO ATUAL'!$A$2:$F$238,6,0),"") | J5: =VALIDADES!$I5-$L$2 -> -46126
B6: =IFERROR(VLOOKUP(A:A,'SALDO ATUAL'!$A$3:$E$238,2,0),"") | C6: =IFERROR(VLOOKUP(A:A,'SALDO ATUAL'!$A$3:$E$238,3,0),"") | D6: =IFERROR(VLOOKUP(A:A,'SALDO ATUAL'!$A$3:$E$238,4,0),"") | E6: =IFERROR(VLOOKUP(A:A,'SALDO ATUAL'!$A$3:$E$238,5,0),"") | F6: =IFERROR(VLOOKUP(A:A,'SALDO ATUAL'!$A$2:$F$238,6,0),"") | J6: =VALIDADES!$I6-$L$2 -> -46126
B7: =IFERROR(VLOOKUP(A:A,'SALDO ATUAL'!$A$3:$E$238,2,0),"") | C7: =IFERROR(VLOOKUP(A:A,'SALDO ATUAL'!$A$3:$E$238,3,0),"") | D7: =IFERROR(VLOOKUP(A:A,'SALDO ATUAL'!$A$3:$E$238,4,0),"") | E7: =IFERROR(VLOOKUP(A:A,'SALDO ATUAL'!$A$3:$E$238,5,0),"") | F7: =IFERROR(VLOOKUP(A:A,'SALDO ATUAL'!$A$2:$F$238,6,0),"") | J7: =VALIDADES!$I7-$L$2 -> -46126
B8: =IFERROR(VLOOKUP(A:A,'SALDO ATUAL'!$A$3:$E$238,2,0),"") | C8: =IFERROR(VLOOKUP(A:A,'SALDO ATUAL'!$A$3:$E$238,3,0),"") | D8: =IFERROR(VLOOKUP(A:A,'SALDO ATUAL'!$A$3:$E$238,4,0),"") | E8: =IFERROR(VLOOKUP(A:A,'SALDO ATUAL'!$A$3:$E$238,5,0),"") | F8: =IFERROR(VLOOKUP(A:A,'SALDO ATUAL'!$A$2:$F$238,6,0),"") | J8: =VALIDADES!$I8-$L$2 -> -46126
B9: =IFERROR(VLOOKUP(A:A,'SALDO ATUAL'!$A$3:$E$238,2,0),"") | C9: =IFERROR(VLOOKUP(A:A,'SALDO ATUAL'!$A$3:$E$238,3,0),"") | D9: =IFERROR(VLOOKUP(A:A,'SALDO ATUAL'!$A$3:$E$238,4,0),"") | E9: =IFERROR(VLOOKUP(A:A,'SALDO ATUAL'!$A$3:$E$238,5,0),"") | F9: =IFERROR(VLOOKUP(A:A,'SALDO ATUAL'!$A$2:$F$238,6,0),"") | J9: =VALIDADES!$I9-$L$2 -> -46126
B10: =IFERROR(VLOOKUP(A:A,'SALDO ATUAL'!$A$3:$E$238,2,0),"") | C10: =IFERROR(VLOOKUP(A:A,'SALDO ATUAL'!$A$3:$E$238,3,0),"") | D10: =IFERROR(VLOOKUP(A:A,'SALDO ATUAL'!$A$3:$E$238,4,0),"") | E10: =IFERROR(VLOOKUP(A:A,'SALDO ATUAL'!$A$3:$E$238,5,0),"") | F10: =IFERROR(VLOOKUP(A:A,'SALDO ATUAL'!$A$2:$F$238,6,0),"") | J10: =VALIDADES!$I10-$L$2 -> -46126
B11: =IFERROR(VLOOKUP(A:A,'SALDO ATUAL'!$A$3:$E$238,2,0),"") | C11: =IFERROR(VLOOKUP(A:A,'SALDO ATUAL'!$A$3:$E$238,3,0),"") | D11: =IFERROR(VLOOKUP(A:A,'SALDO ATUAL'!$A$3:$E$238,4,0),"") | E11: =IFERROR(VLOOKUP(A:A,'SALDO ATUAL'!$A$3:$E$238,5,0),"") | F11: =IFERROR(VLOOKUP(A:A,'SALDO ATUAL'!$A$2:$F$238,6,0),"") | J11: =VALIDADES!$I11-$L$2 -> -46126
B12: =IFERROR(VLOOKUP(A:A,'SALDO ATUAL'!$A$3:$E$238,2,0),"") | C12: =IFERROR(VLOOKUP(A:A,'SALDO ATUAL'!$A$3:$E$238,3,0),"") | D12: =IFERROR(VLOOKUP(A:A,'SALDO ATUAL'!$A$3:$E$238,4,0),"") | E12: =IFERROR(VLOOKUP(A:A,'SALDO ATUAL'!$A$3:$E$238,5,0),"") | F12: =IFERROR(VLOOKUP(A:A,'SALDO ATUAL'!$A$2:$F$238,6,0),"") | J12: =VALIDADES!$I12-$L$2 -> -46126
B13: =IFERROR(VLOOKUP(A:A,'SALDO ATUAL'!$A$3:$E$238,2,0),"") | C13: =IFERROR(VLOOKUP(A:A,'SALDO ATUAL'!$A$3:$E$238,3,0),"") | D13: =IFERROR(VLOOKUP(A:A,'SALDO ATUAL'!$A$3:$E$238,4,0),"") | E13: =IFERROR(VLOOKUP(A:A,'SALDO ATUAL'!$A$3:$E$238,5,0),"") | F13: =IFERROR(VLOOKUP(A:A,'SALDO ATUAL'!$A$2:$F$238,6,0),"") | J13: =VALIDADES!$I13-$L$2 -> -46126
B14: =IFERROR(VLOOKUP(A:A,'SALDO ATUAL'!$A$3:$E$238,2,0),"") | C14: =IFERROR(VLOOKUP(A:A,'SALDO ATUAL'!$A$3:$E$238,3,0),"") | D14: =IFERROR(VLOOKUP(A:A,'SALDO ATUAL'!$A$3:$E$238,4,0),"") | E14: =IFERROR(VLOOKUP(A:A,'SALDO ATUAL'!$A$3:$E$238,5,0),"") | F14: =IFERROR(VLOOKUP(A:A,'SALDO ATUAL'!$A$2:$F$238,6,0),"") | J14: =VALIDADES!$I14-$L$2 -> -46126
B15: =IFERROR(VLOOKUP(A:A,'SALDO ATUAL'!$A$3:$E$238,2,0),"") | C15: =IFERROR(VLOOKUP(A:A,'SALDO ATUAL'!$A$3:$E$238,3,0),"") | D15: =IFERROR(VLOOKUP(A:A,'SALDO ATUAL'!$A$3:$E$238,4,0),"") | E15: =IFERROR(VLOOKUP(A:A,'SALDO ATUAL'!$A$3:$E$238,5,0),"") | F15: =IFERROR(VLOOKUP(A:A,'SALDO ATUAL'!$A$2:$F$238,6,0),"") | J15: =VALIDADES!$I15-$L$2 -> -46126
B16: =IFERROR(VLOOKUP(A:A,'SALDO ATUAL'!$A$3:$E$238,2,0),"") | C16: =IFERROR(VLOOKUP(A:A,'SALDO ATUAL'!$A$3:$E$238,3,0),"") | D16: =IFERROR(VLOOKUP(A:A,'SALDO ATUAL'!$A$3:$E$238,4,0),"") | E16: =IFERROR(VLOOKUP(A:A,'SALDO ATUAL'!$A$3:$E$238,5,0),"") | F16: =IFERROR(VLOOKUP(A:A,'SALDO ATUAL'!$A$2:$F$238,6,0),"") | J16: =VALIDADES!$I16-$L$2 -> -46126
... B24: =IFERROR(VLOOKUP(A:A,'SALDO ATUAL'!$A$3:$E$238,2,0),"") | C24: =IFERROR(VLOOKUP(A:A,'SALDO ATUAL'!$A$3:$E$238,3,0),"") | D24: =IFERROR(VLOOKUP(A:A,'SALDO ATUAL'!$A$3:$E$238,4,0),"") | E24: =IFERROR(VLOOKUP(A:A,'SALDO ATUAL'!$A$3:$E$238,5,0),"") | F24: =IFERROR(VLOOKUP(A:A,'SALDO ATUAL'!$A$2:$F$238,6,0),"") | J24: =VALIDADES!$I24-$L$2 -> -46126
A25: 24 | B25: =IFERROR(VLOOKUP(A:A,'SALDO ATUAL'!$A$3:$E$238,2,0),"") -> 0 | C25: =IFERROR(VLOOKUP(A:A,'SALDO ATUAL'!$A$3:$E$238,3,0),"") -> AH BELOTERO BALANCE | D25: =IFERROR(VLOOKUP(A:A,'SALDO ATUAL'!$A$3:$E$238,4,0),"") -> PREENCHEDOR | E25: =IFERROR(VLOOKUP(A:A,'SALDO ATUAL'!$A$3:$E$238,5,0),"") -> 023 - Mililitro | F25: =IFERROR(VLOOKUP(A:A,'SALDO ATUAL'!$A$2:$F$238,6,0),"") -> MERZ | G25: CAM28052402S | H25: 8 | I25: 45808 | J25: =VALIDADES!$I25-$L$2 -> -318
B26: =IFERROR(VLOOKUP(A:A,'SALDO ATUAL'!$A$3:$E$238,2,0),"") | C26: =IFERROR(VLOOKUP(A:A,'SALDO ATUAL'!$A$3:$E$238,3,0),"") | D26: =IFERROR(VLOOKUP(A:A,'SALDO ATUAL'!$A$3:$E$238,4,0),"") | E26: =IFERROR(VLOOKUP(A:A,'SALDO ATUAL'!$A$3:$E$238,5,0),"") | F26: =IFERROR(VLOOKUP(A:A,'SALDO ATUAL'!$A$2:$F$238,6,0),"") | J26: =VALIDADES!$I26-$L$2 -> -46126
B27: =IFERROR(VLOOKUP(A:A,'SALDO ATUAL'!$A$3:$E$238,2,0),"") | C27: =IFERROR(VLOOKUP(A:A,'SALDO ATUAL'!$A$3:$E$238,3,0),"") | D27: =IFERROR(VLOOKUP(A:A,'SALDO ATUAL'!$A$3:$E$238,4,0),"") | E27: =IFERROR(VLOOKUP(A:A,'SALDO ATUAL'!$A$3:$E$238,5,0),"") | F27: =IFERROR(VLOOKUP(A:A,'SALDO ATUAL'!$A$2:$F$238,6,0),"") | J27: =VALIDADES!$I27-$L$2 -> -46126
B28: =IFERROR(VLOOKUP(A:A,'SALDO ATUAL'!$A$3:$E$238,2,0),"") | C28: =IFERROR(VLOOKUP(A:A,'SALDO ATUAL'!$A$3:$E$238,3,0),"") | D28: =IFERROR(VLOOKUP(A:A,'SALDO ATUAL'!$A$3:$E$238,4,0),"") | E28: =IFERROR(VLOOKUP(A:A,'SALDO ATUAL'!$A$3:$E$238,5,0),"") | F28: =IFERROR(VLOOKUP(A:A,'SALDO ATUAL'!$A$2:$F$238,6,0),"") | J28: =VALIDADES!$I28-$L$2 -> -46126
B29: =IFERROR(VLOOKUP(A:A,'SALDO ATUAL'!$A$3:$E$238,2,0),"") | C29: =IFERROR(VLOOKUP(A:A,'SALDO ATUAL'!$A$3:$E$238,3,0),"") | D29: =IFERROR(VLOOKUP(A:A,'SALDO ATUAL'!$A$3:$E$238,4,0),"") | E29: =IFERROR(VLOOKUP(A:A,'SALDO ATUAL'!$A$3:$E$238,5,0),"") | F29: =IFERROR(VLOOKUP(A:A,'SALDO ATUAL'!$A$2:$F$238,6,0),"") | J29: =VALIDADES!$I29-$L$2 -> -46126
A30: 168 | B30: =IFERROR(VLOOKUP(A:A,'SALDO ATUAL'!$A$3:$E$238,2,0),"") | C30: =IFERROR(VLOOKUP(A:A,'SALDO ATUAL'!$A$3:$E$238,3,0),"") | D30: =IFERROR(VLOOKUP(A:A,'SALDO ATUAL'!$A$3:$E$238,4,0),"") | E30: =IFERROR(VLOOKUP(A:A,'SALDO ATUAL'!$A$3:$E$238,5,0),"") | F30: =IFERROR(VLOOKUP(A:A,'SALDO ATUAL'!$A$2:$F$238,6,0),"") | G30: A79142 | H30: 4 | I30: 45961 | J30: =VALIDADES!$I30-$L$2 -> -165
B31: =IFERROR(VLOOKUP(A:A,'SALDO ATUAL'!$A$3:$E$238,2,0),"") | C31: =IFERROR(VLOOKUP(A:A,'SALDO ATUAL'!$A$3:$E$238,3,0),"") | D31: =IFERROR(VLOOKUP(A:A,'SALDO ATUAL'!$A$3:$E$238,4,0),"") | E31: =IFERROR(VLOOKUP(A:A,'SALDO ATUAL'!$A$3:$E$238,5,0),"") | F31: =IFERROR(VLOOKUP(A:A,'SALDO ATUAL'!$A$2:$F$238,6,0),"") | J31: =VALIDADES!$I31-$L$2 -> -46126
B32: =IFERROR(VLOOKUP(A:A,'SALDO ATUAL'!$A$3:$E$238,2,0),"") | C32: =IFERROR(VLOOKUP(A:A,'SALDO ATUAL'!$A$3:$E$238,3,0),"") | D32: =IFERROR(VLOOKUP(A:A,'SALDO ATUAL'!$A$3:$E$238,4,0),"") | E32: =IFERROR(VLOOKUP(A:A,'SALDO ATUAL'!$A$3:$E$238,5,0),"") | F32: =IFERROR(VLOOKUP(A:A,'SALDO ATUAL'!$A$2:$F$238,6,0),"") | J32: =VALIDADES!$I32-$L$2 -> -46126
B33: =IFERROR(VLOOKUP(A:A,'SALDO ATUAL'!$A$3:$E$238,2,0),"") | C33: =IFERROR(VLOOKUP(A:A,'SALDO ATUAL'!$A$3:$E$238,3,0),"") | D33: =IFERROR(VLOOKUP(A:A,'SALDO ATUAL'!$A$3:$E$238,4,0),"") | E33: =IFERROR(VLOOKUP(A:A,'SALDO ATUAL'!$A$3:$E$238,5,0),"") | F33: =IFERROR(VLOOKUP(A:A,'SALDO ATUAL'!$A$2:$F$238,6,0),"") | J33: =VALIDADES!$I33-$L$2 -> -46126
B34: =IFERROR(VLOOKUP(A:A,'SALDO ATUAL'!$A$3:$E$238,2,0),"") | C34: =IFERROR(VLOOKUP(A:A,'SALDO ATUAL'!$A$3:$E$238,3,0),"") | D34: =IFERROR(VLOOKUP(A:A,'SALDO ATUAL'!$A$3:$E$238,4,0),"") | E34: =IFERROR(VLOOKUP(A:A,'SALDO ATUAL'!$A$3:$E$238,5,0),"") | F34: =IFERROR(VLOOKUP(A:A,'SALDO ATUAL'!$A$2:$F$238,6,0),"") | J34: =VALIDADES!$I34-$L$2 -> -46126
B35: =IFERROR(VLOOKUP(A:A,'SALDO ATUAL'!$A$3:$E$238,2,0),"") | C35: =IFERROR(VLOOKUP(A:A,'SALDO ATUAL'!$A$3:$E$238,3,0),"") | D35: =IFERROR(VLOOKUP(A:A,'SALDO ATUAL'!$A$3:$E$238,4,0),"") | E35: =IFERROR(VLOOKUP(A:A,'SALDO ATUAL'!$A$3:$E$238,5,0),"") | F35: =IFERROR(VLOOKUP(A:A,'SALDO ATUAL'!$A$2:$F$238,6,0),"") | J35: =VALIDADES!$I35-$L$2 -> -46126
B36: =IFERROR(VLOOKUP(A:A,'SALDO ATUAL'!$A$3:$E$238,2,0),"") | C36: =IFERROR(VLOOKUP(A:A,'SALDO ATUAL'!$A$3:$E$238,3,0),"") | D36: =IFERROR(VLOOKUP(A:A,'SALDO ATUAL'!$A$3:$E$238,4,0),"") | E36: =IFERROR(VLOOKUP(A:A,'SALDO ATUAL'!$A$3:$E$238,5,0),"") | F36: =IFERROR(VLOOKUP(A:A,'SALDO ATUAL'!$A$2:$F$238,6,0),"") | J36: =VALIDADES!$I36-$L$2 -> -46126
B37: =IFERROR(VLOOKUP(A:A,'SALDO ATUAL'!$A$3:$E$238,2,0),"") | C37: =IFERROR(VLOOKUP(A:A,'SALDO ATUAL'!$A$3:$E$238,3,0),"") | D37: =IFERROR(VLOOKUP(A:A,'SALDO ATUAL'!$A$3:$E$238,4,0),"") | E37: =IFERROR(VLOOKUP(A:A,'SALDO ATUAL'!$A$3:$E$238,5,0),"") | F37: =IFERROR(VLOOKUP(A:A,'SALDO ATUAL'!$A$2:$F$238,6,0),"") | J37: =VALIDADES!$I37-$L$2 -> -46126
B38: =IFERROR(VLOOKUP(A:A,'SALDO ATUAL'!$A$3:$E$238,2,0),"") | C38: =IFERROR(VLOOKUP(A:A,'SALDO ATUAL'!$A$3:$E$238,3,0),"") | D38: =IFERROR(VLOOKUP(A:A,'SALDO ATUAL'!$A$3:$E$238,4,0),"") | E38: =IFERROR(VLOOKUP(A:A,'SALDO ATUAL'!$A$3:$E$238,5,0),"") | F38: =IFERROR(VLOOKUP(A:A,'SALDO ATUAL'!$A$2:$F$238,6,0),"") | J38: =VALIDADES!$I38-$L$2 -> -46126
A39: 243 | B39: =IFERROR(VLOOKUP(A:A,'SALDO ATUAL'!$A$3:$E$238,2,0),"") -> 0 | C39: =IFERROR(VLOOKUP(A:A,'SALDO ATUAL'!$A$3:$E$238,3,0),"") -> MINOXIDIL HEALTH TECH | D39: =IFERROR(VLOOKUP(A:A,'SALDO ATUAL'!$A$3:$E$238,4,0),"") -> ATIVOS | E39: =IFERROR(VLOOKUP(A:A,'SALDO ATUAL'!$A$3:$E$238,5,0),"") -> 0 | F39: =IFERROR(VLOOKUP(A:A,'SALDO ATUAL'!$A$2:$F$238,6,0),"") -> 0 | J39: =VALIDADES!$I39-$L$2 -> -46126
A40: 244 | B40: =IFERROR(VLOOKUP(A:A,'SALDO ATUAL'!$A$3:$E$238,2,0),"") -> 0 | C40: =IFERROR(VLOOKUP(A:A,'SALDO ATUAL'!$A$3:$E$238,3,0),"") -> MINOXIDIL VICTA | D40: =IFERROR(VLOOKUP(A:A,'SALDO ATUAL'!$A$3:$E$238,4,0),"") -> ATIVOS | E40: =IFERROR(VLOOKUP(A:A,'SALDO ATUAL'!$A$3:$E$238,5,0),"") -> 0 | F40: =IFERROR(VLOOKUP(A:A,'SALDO ATUAL'!$A$2:$F$238,6,0),"") -> 0 | J40: =VALIDADES!$I40-$L$2 -> -46126
A41: 245 | B41: =IFERROR(VLOOKUP(A:A,'SALDO ATUAL'!$A$3:$E$238,2,0),"") -> 0 | C41: =IFERROR(VLOOKUP(A:A,'SALDO ATUAL'!$A$3:$E$238,3,0),"") -> NCPR/NCTF TOSKANI | D41: =IFERROR(VLOOKUP(A:A,'SALDO ATUAL'!$A$3:$E$238,4,0),"") -> ATIVOS | E41: =IFERROR(VLOOKUP(A:A,'SALDO ATUAL'!$A$3:$E$238,5,0),"") -> 0 | F41: =IFERROR(VLOOKUP(A:A,'SALDO ATUAL'!$A$2:$F$238,6,0),"") -> 0 | J41: =VALIDADES!$I41-$L$2 -> -46126
B42: =IFERROR(VLOOKUP(A:A,'SALDO ATUAL'!$A$3:$E$238,2,0),"") | C42: =IFERROR(VLOOKUP(A:A,'SALDO ATUAL'!$A$3:$E$238,3,0),"") | D42: =IFERROR(VLOOKUP(A:A,'SALDO ATUAL'!$A$3:$E$238,4,0),"") | E42: =IFERROR(VLOOKUP(A:A,'SALDO ATUAL'!$A$3:$E$238,5,0),"") | F42: =IFERROR(VLOOKUP(A:A,'SALDO ATUAL'!$A$2:$F$238,6,0),"") | J42: =VALIDADES!$I42-$L$2 -> -46126
B43: =IFERROR(VLOOKUP(A:A,'SALDO ATUAL'!$A$3:$E$238,2,0),"") | C43: =IFERROR(VLOOKUP(A:A,'SALDO ATUAL'!$A$3:$E$238,3,0),"") | D43: =IFERROR(VLOOKUP(A:A,'SALDO ATUAL'!$A$3:$E$238,4,0),"") | E43: =IFERROR(VLOOKUP(A:A,'SALDO ATUAL'!$A$3:$E$238,5,0),"") | F43: =IFERROR(VLOOKUP(A:A,'SALDO ATUAL'!$A$2:$F$238,6,0),"") | J43: =VALIDADES!$I43-$L$2 -> -46126
B44: =IFERROR(VLOOKUP(A:A,'SALDO ATUAL'!$A$3:$E$238,2,0),"") | C44: =IFERROR(VLOOKUP(A:A,'SALDO ATUAL'!$A$3:$E$238,3,0),"") | D44: =IFERROR(VLOOKUP(A:A,'SALDO ATUAL'!$A$3:$E$238,4,0),"") | E44: =IFERROR(VLOOKUP(A:A,'SALDO ATUAL'!$A$3:$E$238,5,0),"") | F44: =IFERROR(VLOOKUP(A:A,'SALDO ATUAL'!$A$2:$F$238,6,0),"") | J44: =VALIDADES!$I44-$L$2 -> -46126
B45: =IFERROR(VLOOKUP(A:A,'SALDO ATUAL'!$A$3:$E$238,2,0),"") | C45: =IFERROR(VLOOKUP(A:A,'SALDO ATUAL'!$A$3:$E$238,3,0),"") | D45: =IFERROR(VLOOKUP(A:A,'SALDO ATUAL'!$A$3:$E$238,4,0),"") | E45: =IFERROR(VLOOKUP(A:A,'SALDO ATUAL'!$A$3:$E$238,5,0),"") | F45: =IFERROR(VLOOKUP(A:A,'SALDO ATUAL'!$A$2:$F$238,6,0),"") | J45: =VALIDADES!$I45-$L$2 -> -46126
B46: =IFERROR(VLOOKUP(A:A,'SALDO ATUAL'!$A$3:$E$238,2,0),"") | C46: =IFERROR(VLOOKUP(A:A,'SALDO ATUAL'!$A$3:$E$238,3,0),"") | D46: =IFERROR(VLOOKUP(A:A,'SALDO ATUAL'!$A$3:$E$238,4,0),"") | E46: =IFERROR(VLOOKUP(A:A,'SALDO ATUAL'!$A$3:$E$238,5,0),"") | F46: =IFERROR(VLOOKUP(A:A,'SALDO ATUAL'!$A$2:$F$238,6,0),"") | J46: =VALIDADES!$I46-$L$2 -> -46126
B47: =IFERROR(VLOOKUP(A:A,'SALDO ATUAL'!$A$3:$E$238,2,0),"") | C47: =IFERROR(VLOOKUP(A:A,'SALDO ATUAL'!$A$3:$E$238,3,0),"") | D47: =IFERROR(VLOOKUP(A:A,'SALDO ATUAL'!$A$3:$E$238,4,0),"") | E47: =IFERROR(VLOOKUP(A:A,'SALDO ATUAL'!$A$3:$E$238,5,0),"") | F47: =IFERROR(VLOOKUP(A:A,'SALDO ATUAL'!$A$2:$F$238,6,0),"") | J47: =VALIDADES!$I47-$L$2 -> -46126
...
